Workbook

Sheet 1.1.9
A1: Table 1.1.9 mean heating degree days in Great Britain, [note 1][note 2][note 3][note 4]
A2: This worksheet contains one table
A3: Some cells refer to notes which can be found on the notes worksheet
A4: Freeze panes are active on this sheet, to turn off freeze panes select 'view' then 'freeze panes' then 'unfreeze panes' or use [Alt W, F]
A5: [x] is used to indicate data not available
A6: Column1 | B6: January | C6: February | D6: March | E6: April | F6: May | G6: June | H6: July | I6: August | J6: September | K6: October | L6: November | M6: December | N6: Total heating degree days | O6: Year
A7: Long-term mean 1991-2020 | B7: 10.591253 | C7: 10.331654 | D7: 8.7443241 | E7: 6.6107303 | F7: 3.8731422 | G7: 1.7088802 | H7: 0.61067221 | I7: 0.67392994 | J7: 1.9294969 | K7: 4.6426107 | L7: 7.9338589 | M7: 10.331529 | N7: 2060.8495 | O7: 5.6422985
A8: 2002 | B8: 9.4550417 | C8: 8.2790041 | D8: 7.8466091 | E8: 6.1168275 | F8: 3.6002924 | G8: 1.3671053 | H8: 0.63602623 | I8: 0.085639505 | J8: 1.2452144 | K8: 5.2310036 | L8: 6.7108434 | M8: 9.542275 | N8: 1823.3153 | O8: 4.9953845
A9: 2003 | B9: 10.583783 | C9: 11.061627 | D9: 7.6807725 | E9: 5.619732 | F9: 3.6498821 | G9: 0.26655458 | H9: 0.039558573 | I9: 0.26349746 | J9: 1.5473197 | K9: 6.0769336 | L9: 7.1494594 | M9: 10.467832 | N9: 1948.8476 | O9: 5.3393084
A10: 2004 | B10: 10.009567 | C10: 9.9152096 | D10: 8.8604549 | E10: 5.942711 | F10: 3.4151526 | G10: 1.0315926 | H10: 0.67715053 | I10: 0.21989247 | J10: 1.2194097 | K10: 4.9349599 | L10: 7.4830386 | M10: 9.7566091 | N10: 1931.931 | O10: 5.2785
A11: 2005 | B11: 9.1392716 | C11: 10.952184 | D11: 8.2363158 | E11: 6.6824914 | F11: 4.3252553 | G11: 1.2577341 | H11: 0.26786866 | I11: 0.31190475 | J11: 1.2117619 | K11: 2.5557041 | L11: 9.061693 | M11: 10.67147 | N11: 1953.8131 | O11: 5.3529125
A12: 2006 | B12: 10.98 | C12: 11.332143 | D12: 10.506545 | E12: 7.0039035 | F12: 3.6689209 | G12: 0.64526316 | H12: 0.0045540797 | I12: 0.25625354 | J12: 0.25546784 | K12: 2.7219864 | L12: 7.4257531 | M12: 9.1236323 | N12: 1932.3303 | O12: 5.2940556
A13: 2007 | B13: 8.5841778 | C13: 9.4508459 | D13: 8.3802207 | E13: 4.3097214 | F13: 3.6543294 | G13: 0.91665147 | H13: 0.53709677 | I13: 0.51813364 | J13: 2.1388849 | K13: 4.5029954 | L13: 7.9624286 | M13: 10.463863 | N13: 1860.3196 | O13: 5.096766
A14: 2008 | B14: 9.1267281 | C14: 10.135878 | D14: 9.4043779 | E14: 7.5553175 | F14: 2.5526882 | G14: 1.5995948 | H14: 0.4502195 | I14: 0.22311828 | J14: 1.9839683 | K14: 5.7529685 | L14: 8.5224603 | M14: 11.780031 | N14: 2101.7748 | O14: 5.742554
A15: 2009 | B15: 12.200998 | C15: 11.143793 | D15: 8.5715054 | E15: 5.7938095 | F15: 3.5778034 | G15: 1.5675397 | H15: 0.24101382 | I15: 0.20721966 | J15: 1.463254 | K15: 4.0167435 | L15: 7.0784921 | M15: 12.414593 | N15: 2067.2452 | O15: 5.6636856
A16: 2010 | B16: 14.004992 | C16: 12.74983 | D16: 9.4020737 | E16: 6.6230159 | F16: 4.9456221 | G16: 0.96150794 | H16: 0.055453149 | I16: 0.65192012 | J16: 1.7657143 | K16: 5.1019969 | L16: 10.121032 | M16: 15.7702 | N16: 2489.0333 | O16: 6.8192694
A17: 2011 | B17: 11.644009 | C17: 9.1534014 | D17: 8.7389401 | E17: 3.8340476 | F17: 3.2774962 | G17: 1.8910317 | H17: 0.50176651 | I17: 0.81459293 | J17: 1.0246825 | K17: 3.4271889 | L17: 5.9681746 | M17: 9.5788018 | N17: 1815.3 | O17: 4.9734247
A18: 2012 | B18: 10.03126 | C18: 11.111412 | D18: 7.0460829 | E18: 8.1605556 | F18: 4.2368664 | G18: 2.1284127 | H18: 0.84485407 | I18: 0.25745008 | J18: 2.5852381 | K18: 5.988172 | L18: 8.8489683 | M18: 10.66467 | N18: 2185.0762 | O18: 5.9701535
A19: 2013 | B19: 11.574424 | C19: 12.118622 | D19: 12.547312 | E19: 8.0898413 | F19: 4.9482335 | G19: 1.6752381 | H19: 0.1234255 | I19: 0.1140553 | J19: 1.9122222 | K19: 3.0975422 | L19: 9.1303175 | M19: 9.1036866 | N19: 2250.319 | O19: 6.1652577
... A29: 2023 | B29: 10.244086 | C29: 8.8522109 | D29: 8.5230415 | E29: 6.8684921 | F29: 2.9149002 | G29: 0.59984127 | H29: 0.26228879 | I29: 0.41789555 | J29: 0.57984127 | K29: 3.6403994 | L29: 7.9692063 | M29: 8.5650538 | N29: 1799.981 | O29: 4.9314547
A30: 2024 | B30: 10.496851 | C30: 7.8528736 | D30: 7.6412442 | E30: 6.0338889 | F30: 1.7907066 | G30: 1.7500794 | H30: [x] | I30: [x] | J30: [x] | K30: [x] | L30: [x] | M30: [x] | N30: [x] | O30: [x]

Sheet Degree-days
B3: Annual Heat Demand (kWh/a) | C3: 7527
B5: Mean Heating Days 1991 to 2020 Source: DUKES
B6: Month | C6: Jan | D6: Feb | E6: Mar | F6: Apr | G6: May | H6: Jun | I6: Jul | J6: Aug | K6: Sep | L6: Oct | M6: Nov | N6: Dec | O6: Total
B7: Mean Degree-Days (k.days) | C7: =Table_1.1.8_Mean_heating_degree_days_in_Great_Britain[[#This Row],[January]] -> 10.591253 | D7: =Table_1.1.8_Mean_heating_degree_days_in_Great_Britain[[#This Row],[February]] -> 10.331654 | E7: =Table_1.1.8_Mean_heating_degree_days_in_Great_Britain[[#This Row],[March]] -> 8.7443241 | F7: =Table_1.1.8_Mean_heating_degree_days_in_Great_Britain[[#This Row],[April]] -> 6.6107303 | G7: =Table_1.1.8_Mean_heating_degree_days_in_Great_Britain[[#This Row],[May]] -> 3.8731422 | H7: =Table_1.1.8_Mean_heating_degree_days_in_Great_Britain[[#This Row],[June]] -> 1.7088802 | I7: =Table_1.1.8_Mean_heating_degree_days_in_Great_Britain[[#This Row],[July]] -> 0.61067221 | J7: =Table_1.1.8_Mean_heating_degree_days_in_Great_Britain[[#This Row],[August]] -> 0.67392994 | K7: =Table_1.1.8_Mean_heating_degree_days_in_Great_Britain[[#This Row],[September]] -> 1.9294969 | L7: =Table_1.1.8_Mean_heating_degree_days_in_Great_Britain[[#This Row],[October]] -> 4.6426107 | M7: =Table_1.1.8_Mean_heating_degree_days_in_Great_Britain[[#This Row],[November]] -> 7.9338589 | N7: =Table_1.1.8_Mean_heating_degree_days_in_Great_Britain[[#This Row],[December]] -> 10.331529
B8: Days per month | C8: 31 | D8: 28 | E8: 31 | F8: 30 | G8: 31 | H8: 30 | I8: 31 | J8: 31 | K8: 30 | L8: 31 | M8: 30 | N8: 31 | O8: =SUM(C8:N8) -> 365
B9: Degree-days per month | C9: =C7*C8 -> 328.32885 | D9: =D7*D8 -> 289.28633 | E9: =E7*E8 -> 271.07405 | F9: =F7*F8 -> 198.32191 | G9: =G7*G8 -> 120.06741 | H9: =H7*H8 -> 51.266406 | I9: =I7*I8 -> 18.930839 | J9: =J7*J8 -> 20.891828 | ... N9: =N7*N8 -> 320.2774 | O9: =SUM(C9:N9) -> 2058.2666
B10: % annual degree-days | C10: =C9/$O$9 -> 0.15951716 | D10: =D9/$O$9 -> 0.14054852 | E10: =E9/$O$9 -> 0.13170016 | F10: =F9/$O$9 -> 0.096353849 | G10: =G9/$O$9 -> 0.058334235 | H10: =H9/$O$9 -> 0.024907563 | I10: =I9/$O$9 -> 0.0091974667 | J10: =J9/$O$9 -> 0.010150205 | ... N10: =N9/$O$9 -> 0.1556054 | O10: =SUM(C10:N10) -> 1
B11: Monthly heat demand (kWh/month) | C11: =$C$3*C10 -> 1200.6857 | D11: =$C$3*D10 -> 1057.9087 | E11: =$C$3*E10 -> 991.30712 | F11: =$C$3*F10 -> 725.25542 | G11: =$C$3*G10 -> 439.08178 | H11: =$C$3*H10 -> 187.47923 | I11: =$C$3*I10 -> 69.229332 | J11: =$C$3*J10 -> 76.400593 | ... N11: =$C$3*N10 -> 1171.2418 | O11: =SUM(C11:N11) -> 7527
B12: kWh/h when heating called | C12: =C11/'Heat System Daily Operation'!AH10 -> 3.5107768 | D12: =D11/'Heat System Daily Operation'!AI10 -> 3.4347685 | E12: =E11/'Heat System Daily Operation'!AJ10 -> 2.9591257 | F12: =F11/'Heat System Daily Operation'!AK10 -> 2.1331042 | G12: =G11/'Heat System Daily Operation'!AL10 -> 1.3106919 | H12: =H11/'Heat System Daily Operation'!AM10 -> 0.57508966 | I12: =I11/'Heat System Daily Operation'!AN10 -> 0.19836485 | J12: =J11/'Heat System Daily Operation'!AO10 -> 0.22806147 | ... N12: =N11/'Heat System Daily Operation'!AS10 -> 3.3559938
C13: =C11/(C8*24) -> 1.6138248
B14: Period | C14: Winter (Dec to Feb) | D14: Spring/Autumn (Mar to May, Sep to Nov) | E14: Summer (Jun to Aug) | F14: Check Sum | H14: Source
B15: =B7 -> Mean Degree-Days (k.days) | C15: =AVERAGE(C7,D7,N7) -> 10.418146 | D15: =AVERAGE(E7,F7,G7,K7,L7,M7) -> 5.6223605 | E15: =AVERAGE(H7,I7,J7) -> 0.99782745
B16: % Annual Degree-days | C16: =C10+D10+N10 -> 0.45567108 | D16: =SUM(E10:G10)+SUM(K10:M10) -> 0.50007368 | E16: =SUM(H10:J10) -> 0.044255235 | F16: =SUM(C16:E16) -> 1
B17: Number of Days | C17: =N8+C8+D8 -> 90 | D17: =SUM(E8:G8)+SUM(K8:M8) -> 183 | E17: =SUM(H8:J8) -> 92 | F17: =SUM(C17:E17) -> 365
B18: kWh for period | C18: =C11+D11+N11 -> 3429.8362 | D18: =SUM(E11:G11)+SUM(K11:M11) -> 3764.0546 | E18: =SUM(H11:J11) -> 333.10915 | F18: =SUM(C18:E18) -> 7527 | G18: =IF(F18=C3, TRUE,FALSE) -> TRUE
B19: =B12 -> kWh/h when heating called | C19: =C18/('Heat System Daily Operation'!AH10+'Heat System Daily Operation'!AI10+'Heat System Daily Operation'!AS10) -> 3.4332695 | D19: =D18/('Heat System Daily Operation'!AJ10+'Heat System Daily Operation'!AK10+'Heat System Daily Operation'!AL10+'Heat System Daily Operation'!AP10+'Heat System Daily Operation'!AQ10+'Heat System Daily Operation'!AR10) -> 1.8717328 | E19: =E18/SUM('Heat System Daily Operation'!AM10:AO10) -> 0.32981104
B21: Average Air Temperature (°C) | C21: =AVERAGE(8.79,8.42,8.98) -> 8.73 | D21: =AVERAGE(11.73,15,18.37,20.22,15.81,11.47) -> 15.433333 | E21: =AVERAGE(21.57,23.89,23.4) -> 22.953333 | H21: Met Office (1990 - 2020)
B22: HP CoP @ Supply Temp Applies to ASHP and WSHP
B23: 55°C | C23: 2.9 | D23: 3.3 | E23: 3.4
B24: 45°C | C24: 3.5 | D24: 4 | E24: 4.2
B25: 35°C | C25: 4.5 | D25: 5.1 | E25: 5.4
B27: Revised CoPs | C27: ASHP and WSHP, Outlet 35ºC
B28: =B21 -> Average Air Temperature (°C) | C28: 7 | D28: =D21 -> 15.433333 | E28: =E21 -> 22.953333 | F28: Slope | G28: 0.092
B29: Individual ASHP CoP | C29: 4.6 | D29: =$C$29+($G$28*(D21-$C$28)) -> 5.3758667 | E29: =$C$29+($G$28*(E21-$C$28)) -> 6.0677067
B30: Commercial ASHP Qh,Qc | C30: =C29 -> 4.6 | D30: =D29 -> 5.3758667 | E30: =E29 -> 6.0677067
B31: Individual WSHP at W20W35 | C31: 9.5 | D31: =C31 -> 9.5 | E31: =D31 -> 9.5 | F31: Daikin datasheet
B32: Individual WSHP at W10W35 | C32: =(C31-C33)/2+C33 -> 7.12 | D32: =C32 -> 7.12 | E32: =D32 -> 7.12 | F32: Interpolation
B33: Individual WSHP at W0W35 | C33: 4.74 | F33: =F31 -> Daikin datasheet
I56: Performance evaluation of air-source heat pump based on a
I57: pressure drop embedded model
I58: Tim Koopman , Tingting Zhu *, Wilko Rohlfs
I59: 2024

Sheet Heat System Daily Operation
E4: Hour of Day | F4: 1 | G4: 2 | H4: 3 | I4: 4 | J4: 5 | K4: 6 | L4: 7 | M4: 8 | N4: 9 | O4: 10 | P4: 11 | Q4: 12 | R4: 13 | S4: 14 | T4: 15 | U4: 16 | V4: 17 | W4: 18 | X4: 19 | Y4: 20 | Z4: 21 | AA4: 22 | AB4: 23 | AC4: 24
D5: Heating system operating hours | E5: weekend | F5: 0 | G5: 0 | H5: 0 | I5: 0 | J5: 0 | K5: 0 | L5: 1 | M5: 1 | N5: 1 | O5: 1 | P5: 1 | Q5: 1 | R5: 1 | S5: 1 | T5: 1 | U5: 1 | V5: 1 | W5: 1 | X5: 1 | Y5: 1 | Z5: 1 | AA5: 1 | AB5: 0
E6: weekday | F6: 0 | G6: 0 | H6: 0 | I6: 0 | J6: 0 | K6: 0 | L6: 1 | M6: 1 | N6: 0 | O6: 0 | P6: 0 | Q6: 0 | R6: 0 | S6: 0 | T6: 0 | U6: 1 | V6: 1 | W6: 1 | X6: 1 | Y6: 1 | Z6: 1 | AA6: 1 | AB6: 0 | AC6: 0
AD8: Total | AE8: Monthly Total | AH8: Operating Hours per Month
D9: 44927 | E9: =IF(WEEKDAY(D9, 2)<6, "weekday", "weekend") -> weekend | F9: =IF($E9=$E$5,(F$5),(F$6)) -> 0 | G9: =IF($E9=$E$5,(G$5),(G$6)) -> 0 | H9: =IF($E9=$E$5,(H$5),(H$6)) -> 0 | I9: =IF($E9=$E$5,(I$5),(I$6)) -> 0 | J9: =IF($E9=$E$5,(J$5),(J$6)) -> 0 | K9: =IF($E9=$E$5,(K$5),(K$6)) -> 0 | L9: =IF($E9=$E$5,(L$5),(L$6)) -> 1 | M9: =IF($E9=$E$5,(M$5),(M$6)) -> 1 | ... AC9: =IF($E9=$E$5,(AC$5),(AC$6)) -> 0 | AD9: =SUM(F9:AC9) -> 16 | AE9: Jan | AF9: =SUM(AD9:AD39) -> 342 | AH9: {=TRANSPOSE(AE9:AF20)} -> Jan | AI9: Feb | AJ9: Mar | AK9: Apr | AL9: May | AM9: Jun | AN9: Jul | AO9: Aug | AP9: Sep | AQ9: Oct | AR9: Nov | AS9: Dec | AT9: Total
D10: 44928 | E10: =IF(WEEKDAY(D10, 2)<6, "weekday", "weekend") -> weekday | F10: =IF($E10=$E$5,(F$5),(F$6)) -> 0 | G10: =IF($E10=$E$5,(G$5),(G$6)) -> 0 | H10: =IF($E10=$E$5,(H$5),(H$6)) -> 0 | I10: =IF($E10=$E$5,(I$5),(I$6)) -> 0 | J10: =IF($E10=$E$5,(J$5),(J$6)) -> 0 | K10: =IF($E10=$E$5,(K$5),(K$6)) -> 0 | L10: =IF($E10=$E$5,(L$5),(L$6)) -> 1 | M10: =IF($E10=$E$5,(M$5),(M$6)) -> 1 | ... AC10: =IF($E10=$E$5,(AC$5),(AC$6)) -> 0 | AD10: =SUM(F10:AC10) -> 9 | AE10: Feb | AF10: =SUM(AD40:AD67) -> 308 | AH10: 342 | AI10: 308 | AJ10: 335 | AK10: 340 | AL10: 335 | AM10: 326 | AN10: 349 | AO10: 335 | AP10: 333 | AQ10: 342 | AR10: 326 | AS10: 349 | AT10: =SUM(AH10:AS10) -> 4020
D11: 44929 | E11: =IF(WEEKDAY(D11, 2)<6, "weekday", "weekend") -> weekday | F11: =IF($E11=$E$5,(F$5),(F$6)) -> 0 | G11: =IF($E11=$E$5,(G$5),(G$6)) -> 0 | H11: =IF($E11=$E$5,(H$5),(H$6)) -> 0 | I11: =IF($E11=$E$5,(I$5),(I$6)) -> 0 | J11: =IF($E11=$E$5,(J$5),(J$6)) -> 0 | K11: =IF($E11=$E$5,(K$5),(K$6)) -> 0 | L11: =IF($E11=$E$5,(L$5),(L$6)) -> 1 | M11: =IF($E11=$E$5,(M$5),(M$6)) -> 1 | ... AC11: =IF($E11=$E$5,(AC$5),(AC$6)) -> 0 | AD11: =SUM(F11:AC11) -> 9 | AE11: Mar | AF11: =SUM(AD68:AD98) -> 335
D12: 44930 | E12: =IF(WEEKDAY(D12, 2)<6, "weekday", "weekend") -> weekday | F12: =IF($E12=$E$5,(F$5),(F$6)) -> 0 | G12: =IF($E12=$E$5,(G$5),(G$6)) -> 0 | H12: =IF($E12=$E$5,(H$5),(H$6)) -> 0 | I12: =IF($E12=$E$5,(I$5),(I$6)) -> 0 | J12: =IF($E12=$E$5,(J$5),(J$6)) -> 0 | K12: =IF($E12=$E$5,(K$5),(K$6)) -> 0 | L12: =IF($E12=$E$5,(L$5),(L$6)) -> 1 | M12: =IF($E12=$E$5,(M$5),(M$6)) -> 1 | ... AC12: =IF($E12=$E$5,(AC$5),(AC$6)) -> 0 | AD12: =SUM(F12:AC12) -> 9 | AE12: Apr | AF12: =SUM(AD99:AD128) -> 340
D13: 44931 | E13: =IF(WEEKDAY(D13, 2)<6, "weekday", "weekend") -> weekday | F13: =IF($E13=$E$5,(F$5),(F$6)) -> 0 | G13: =IF($E13=$E$5,(G$5),(G$6)) -> 0 | H13: =IF($E13=$E$5,(H$5),(H$6)) -> 0 | I13: =IF($E13=$E$5,(I$5),(I$6)) -> 0 | J13: =IF($E13=$E$5,(J$5),(J$6)) -> 0 | K13: =IF($E13=$E$5,(K$5),(K$6)) -> 0 | L13: =IF($E13=$E$5,(L$5),(L$6)) -> 1 | M13: =IF($E13=$E$5,(M$5),(M$6)) -> 1 | ... AC13: =IF($E13=$E$5,(AC$5),(AC$6)) -> 0 | AD13: =SUM(F13:AC13) -> 9 | AE13: May | AF13: =SUM(AD129:AD159) -> 335
D14: 44932 | E14: =IF(WEEKDAY(D14, 2)<6, "weekday", "weekend") -> weekday | F14: =IF($E14=$E$5,(F$5),(F$6)) -> 0 | G14: =IF($E14=$E$5,(G$5),(G$6)) -> 0 | H14: =IF($E14=$E$5,(H$5),(H$6)) -> 0 | I14: =IF($E14=$E$5,(I$5),(I$6)) -> 0 | J14: =IF($E14=$E$5,(J$5),(J$6)) -> 0 | K14: =IF($E14=$E$5,(K$5),(K$6)) -> 0 | L14: =IF($E14=$E$5,(L$5),(L$6)) -> 1 | M14: =IF($E14=$E$5,(M$5),(M$6)) -> 1 | ... AC14: =IF($E14=$E$5,(AC$5),(AC$6)) -> 0 | AD14: =SUM(F14:AC14) -> 9 | AE14: Jun | AF14: =SUM(AD160:AD189) -> 326
D15: 44933 | E15: =IF(WEEKDAY(D15, 2)<6, "weekday", "weekend") -> weekend | F15: =IF($E15=$E$5,(F$5),(F$6)) -> 0 | G15: =IF($E15=$E$5,(G$5),(G$6)) -> 0 | H15: =IF($E15=$E$5,(H$5),(H$6)) -> 0 | I15: =IF($E15=$E$5,(I$5),(I$6)) -> 0 | J15: =IF($E15=$E$5,(J$5),(J$6)) -> 0 | K15: =IF($E15=$E$5,(K$5),(K$6)) -> 0 | L15: =IF($E15=$E$5,(L$5),(L$6)) -> 1 | M15: =IF($E15=$E$5,(M$5),(M$6)) -> 1 | ... AC15: =IF($E15=$E$5,(AC$5),(AC$6)) -> 0 | AD15: =SUM(F15:AC15) -> 16 | AE15: Jul | AF15: =SUM(AD190:AD220) -> 349
D16: 44934 | E16: =IF(WEEKDAY(D16, 2)<6, "weekday", "weekend") -> weekend | F16: =IF($E16=$E$5,(F$5),(F$6)) -> 0 | G16: =IF($E16=$E$5,(G$5),(G$6)) -> 0 | H16: =IF($E16=$E$5,(H$5),(H$6)) -> 0 | I16: =IF($E16=$E$5,(I$5),(I$6)) -> 0 | J16: =IF($E16=$E$5,(J$5),(J$6)) -> 0 | K16: =IF($E16=$E$5,(K$5),(K$6)) -> 0 | L16: =IF($E16=$E$5,(L$5),(L$6)) -> 1 | M16: =IF($E16=$E$5,(M$5),(M$6)) -> 1 | ... AC16: =IF($E16=$E$5,(AC$5),(AC$6)) -> 0 | AD16: =SUM(F16:AC16) -> 16 | AE16: Aug | AF16: =SUM(AD221:AD251) -> 335
D17: 44935 | E17: =IF(WEEKDAY(D17, 2)<6, "weekday", "weekend") -> weekday | F17: =IF($E17=$E$5,(F$5),(F$6)) -> 0 | G17: =IF($E17=$E$5,(G$5),(G$6)) -> 0 | H17: =IF($E17=$E$5,(H$5),(H$6)) -> 0 | I17: =IF($E17=$E$5,(I$5),(I$6)) -> 0 | J17: =IF($E17=$E$5,(J$5),(J$6)) -> 0 | K17: =IF($E17=$E$5,(K$5),(K$6)) -> 0 | L17: =IF($E17=$E$5,(L$5),(L$6)) -> 1 | M17: =IF($E17=$E$5,(M$5),(M$6)) -> 1 | ... AC17: =IF($E17=$E$5,(AC$5),(AC$6)) -> 0 | AD17: =SUM(F17:AC17) -> 9 | AE17: Sep | AF17: =SUM(AD252:AD281) -> 333
D18: 44936 | E18: =IF(WEEKDAY(D18, 2)<6, "weekday", "weekend") -> weekday | F18: =IF($E18=$E$5,(F$5),(F$6)) -> 0 | G18: =IF($E18=$E$5,(G$5),(G$6)) -> 0 | H18: =IF($E18=$E$5,(H$5),(H$6)) -> 0 | I18: =IF($E18=$E$5,(I$5),(I$6)) -> 0 | J18: =IF($E18=$E$5,(J$5),(J$6)) -> 0 | K18: =IF($E18=$E$5,(K$5),(K$6)) -> 0 | L18: =IF($E18=$E$5,(L$5),(L$6)) -> 1 | M18: =IF($E18=$E$5,(M$5),(M$6)) -> 1 | ... AC18: =IF($E18=$E$5,(AC$5),(AC$6)) -> 0 | AD18: =SUM(F18:AC18) -> 9 | AE18: Oct | AF18: =SUM(AD282:AD312) -> 342
D19: 44937 | E19: =IF(WEEKDAY(D19, 2)<6, "weekday", "weekend") -> weekday | F19: =IF($E19=$E$5,(F$5),(F$6)) -> 0 | G19: =IF($E19=$E$5,(G$5),(G$6)) -> 0 | H19: =IF($E19=$E$5,(H$5),(H$6)) -> 0 | I19: =IF($E19=$E$5,(I$5),(I$6)) -> 0 | J19: =IF($E19=$E$5,(J$5),(J$6)) -> 0 | K19: =IF($E19=$E$5,(K$5),(K$6)) -> 0 | L19: =IF($E19=$E$5,(L$5),(L$6)) -> 1 | M19: =IF($E19=$E$5,(M$5),(M$6)) -> 1 | ... AC19: =IF($E19=$E$5,(AC$5),(AC$6)) -> 0 | AD19: =SUM(F19:AC19) -> 9 | AE19: Nov | AF19: =SUM(AD313:AD342) -> 326
D20: 44938 | E20: =IF(WEEKDAY(D20, 2)<6, "weekday", "weekend") -> weekday | F20: =IF($E20=$E$5,(F$5),(F$6)) -> 0 | G20: =IF($E20=$E$5,(G$5),(G$6)) -> 0 | H20: =IF($E20=$E$5,(H$5),(H$6)) -> 0 | I20: =IF($E20=$E$5,(I$5),(I$6)) -> 0 | J20: =IF($E20=$E$5,(J$5),(J$6)) -> 0 | K20: =IF($E20=$E$5,(K$5),(K$6)) -> 0 | L20: =IF($E20=$E$5,(L$5),(L$6)) -> 1 | M20: =IF($E20=$E$5,(M$5),(M$6)) -> 1 | ... AC20: =IF($E20=$E$5,(AC$5),(AC$6)) -> 0 | AD20: =SUM(F20:AC20) -> 9 | AE20: Dec | AF20: =SUM(AD343:AD373) -> 349
D21: 44939 | E21: =IF(WEEKDAY(D21, 2)<6, "weekday", "weekend") -> weekday | F21: =IF($E21=$E$5,(F$5),(F$6)) -> 0 | G21: =IF($E21=$E$5,(G$5),(G$6)) -> 0 | H21: =IF($E21=$E$5,(H$5),(H$6)) -> 0 | I21: =IF($E21=$E$5,(I$5),(I$6)) -> 0 | J21: =IF($E21=$E$5,(J$5),(J$6)) -> 0 | K21: =IF($E21=$E$5,(K$5),(K$6)) -> 0 | L21: =IF($E21=$E$5,(L$5),(L$6)) -> 1 | M21: =IF($E21=$E$5,(M$5),(M$6)) -> 1 | ... AC21: =IF($E21=$E$5,(AC$5),(AC$6)) -> 0 | AD21: =SUM(F21:AC21) -> 9 | AE21: Total | AF21: =SUM(AF9:AF20) -> 4020
D22: 44940 | E22: =IF(WEEKDAY(D22, 2)<6, "weekday", "weekend") -> weekend | F22: =IF($E22=$E$5,(F$5),(F$6)) -> 0 | G22: =IF($E22=$E$5,(G$5),(G$6)) -> 0 | H22: =IF($E22=$E$5,(H$5),(H$6)) -> 0 | I22: =IF($E22=$E$5,(I$5),(I$6)) -> 0 | J22: =IF($E22=$E$5,(J$5),(J$6)) -> 0 | K22: =IF($E22=$E$5,(K$5),(K$6)) -> 0 | L22: =IF($E22=$E$5,(L$5),(L$6)) -> 1 | M22: =IF($E22=$E$5,(M$5),(M$6)) -> 1 | ... AC22: =IF($E22=$E$5,(AC$5),(AC$6)) -> 0 | AD22: =SUM(F22:AC22) -> 16 | AE22: Check sum | AF22: =SUM(F9:AC373) -> 4020
D23: 44941 | E23: =IF(WEEKDAY(D23, 2)<6, "weekday", "weekend") -> weekend | F23: =IF($E23=$E$5,(F$5),(F$6)) -> 0 | G23: =IF($E23=$E$5,(G$5),(G$6)) -> 0 | H23: =IF($E23=$E$5,(H$5),(H$6)) -> 0 | I23: =IF($E23=$E$5,(I$5),(I$6)) -> 0 | J23: =IF($E23=$E$5,(J$5),(J$6)) -> 0 | K23: =IF($E23=$E$5,(K$5),(K$6)) -> 0 | L23: =IF($E23=$E$5,(L$5),(L$6)) -> 1 | M23: =IF($E23=$E$5,(M$5),(M$6)) -> 1 | ... AC23: =IF($E23=$E$5,(AC$5),(AC$6)) -> 0 | AD23: =SUM(F23:AC23) -> 16 | AE23: Chedk sum | AF23: =AD374 -> 4020
D24: 44942 | E24: =IF(WEEKDAY(D24, 2)<6, "weekday", "weekend") -> weekday | F24: =IF($E24=$E$5,(F$5),(F$6)) -> 0 | G24: =IF($E24=$E$5,(G$5),(G$6)) -> 0 | H24: =IF($E24=$E$5,(H$5),(H$6)) -> 0 | I24: =IF($E24=$E$5,(I$5),(I$6)) -> 0 | J24: =IF($E24=$E$5,(J$5),(J$6)) -> 0 | K24: =IF($E24=$E$5,(K$5),(K$6)) -> 0 | L24: =IF($E24=$E$5,(L$5),(L$6)) -> 1 | M24: =IF($E24=$E$5,(M$5),(M$6)) -> 1 | ... AC24: =IF($E24=$E$5,(AC$5),(AC$6)) -> 0 | AD24: =SUM(F24:AC24) -> 9
D25: 44943 | E25: =IF(WEEKDAY(D25, 2)<6, "weekday", "weekend") -> weekday | F25: =IF($E25=$E$5,(F$5),(F$6)) -> 0 | G25: =IF($E25=$E$5,(G$5),(G$6)) -> 0 | H25: =IF($E25=$E$5,(H$5),(H$6)) -> 0 | I25: =IF($E25=$E$5,(I$5),(I$6)) -> 0 | J25: =IF($E25=$E$5,(J$5),(J$6)) -> 0 | K25: =IF($E25=$E$5,(K$5),(K$6)) -> 0 | L25: =IF($E25=$E$5,(L$5),(L$6)) -> 1 | M25: =IF($E25=$E$5,(M$5),(M$6)) -> 1 | ... AC25: =IF($E25=$E$5,(AC$5),(AC$6)) -> 0 | AD25: =SUM(F25:AC25) -> 9
D26: 44944 | E26: =IF(WEEKDAY(D26, 2)<6, "weekday", "weekend") -> weekday | F26: =IF($E26=$E$5,(F$5),(F$6)) -> 0 | G26: =IF($E26=$E$5,(G$5),(G$6)) -> 0 | H26: =IF($E26=$E$5,(H$5),(H$6)) -> 0 | I26: =IF($E26=$E$5,(I$5),(I$6)) -> 0 | J26: =IF($E26=$E$5,(J$5),(J$6)) -> 0 | K26: =IF($E26=$E$5,(K$5),(K$6)) -> 0 | L26: =IF($E26=$E$5,(L$5),(L$6)) -> 1 | M26: =IF($E26=$E$5,(M$5),(M$6)) -> 1 | ... AC26: =IF($E26=$E$5,(AC$5),(AC$6)) -> 0 | AD26: =SUM(F26:AC26) -> 9
D27: 44945 | E27: =IF(WEEKDAY(D27, 2)<6, "weekday", "weekend") -> weekday | F27: =IF($E27=$E$5,(F$5),(F$6)) -> 0 | G27: =IF($E27=$E$5,(G$5),(G$6)) -> 0 | H27: =IF($E27=$E$5,(H$5),(H$6)) -> 0 | I27: =IF($E27=$E$5,(I$5),(I$6)) -> 0 | J27: =IF($E27=$E$5,(J$5),(J$6)) -> 0 | K27: =IF($E27=$E$5,(K$5),(K$6)) -> 0 | L27: =IF($E27=$E$5,(L$5),(L$6)) -> 1 | M27: =IF($E27=$E$5,(M$5),(M$6)) -> 1 | ... AC27: =IF($E27=$E$5,(AC$5),(AC$6)) -> 0 | AD27: =SUM(F27:AC27) -> 9
D28: 44946 | E28: =IF(WEEKDAY(D28, 2)<6, "weekday", "weekend") -> weekday | F28: =IF($E28=$E$5,(F$5),(F$6)) -> 0 | G28: =IF($E28=$E$5,(G$5),(G$6)) -> 0 | H28: =IF($E28=$E$5,(H$5),(H$6)) -> 0 | I28: =IF($E28=$E$5,(I$5),(I$6)) -> 0 | J28: =IF($E28=$E$5,(J$5),(J$6)) -> 0 | K28: =IF($E28=$E$5,(K$5),(K$6)) -> 0 | L28: =IF($E28=$E$5,(L$5),(L$6)) -> 1 | M28: =IF($E28=$E$5,(M$5),(M$6)) -> 1 | ... AC28: =IF($E28=$E$5,(AC$5),(AC$6)) -> 0 | AD28: =SUM(F28:AC28) -> 9
D29: 44947 | E29: =IF(WEEKDAY(D29, 2)<6, "weekday", "weekend") -> weekend | F29: =IF($E29=$E$5,(F$5),(F$6)) -> 0 | G29: =IF($E29=$E$5,(G$5),(G$6)) -> 0 | H29: =IF($E29=$E$5,(H$5),(H$6)) -> 0 | I29: =IF($E29=$E$5,(I$5),(I$6)) -> 0 | J29: =IF($E29=$E$5,(J$5),(J$6)) -> 0 | K29: =IF($E29=$E$5,(K$5),(K$6)) -> 0 | L29: =IF($E29=$E$5,(L$5),(L$6)) -> 1 | M29: =IF($E29=$E$5,(M$5),(M$6)) -> 1 | ... AC29: =IF($E29=$E$5,(AC$5),(AC$6)) -> 0 | AD29: =SUM(F29:AC29) -> 16
D30: 44948 | E30: =IF(WEEKDAY(D30, 2)<6, "weekday", "weekend") -> weekend | F30: =IF($E30=$E$5,(F$5),(F$6)) -> 0 | G30: =IF($E30=$E$5,(G$5),(G$6)) -> 0 | H30: =IF($E30=$E$5,(H$5),(H$6)) -> 0 | I30: =IF($E30=$E$5,(I$5),(I$6)) -> 0 | J30: =IF($E30=$E$5,(J$5),(J$6)) -> 0 | K30: =IF($E30=$E$5,(K$5),(K$6)) -> 0 | L30: =IF($E30=$E$5,(L$5),(L$6)) -> 1 | M30: =IF($E30=$E$5,(M$5),(M$6)) -> 1 | ... AC30: =IF($E30=$E$5,(AC$5),(AC$6)) -> 0 | AD30: =SUM(F30:AC30) -> 16
D31: 44949 | E31: =IF(WEEKDAY(D31, 2)<6, "weekday", "weekend") -> weekday | F31: =IF($E31=$E$5,(F$5),(F$6)) -> 0 | G31: =IF($E31=$E$5,(G$5),(G$6)) -> 0 | H31: =IF($E31=$E$5,(H$5),(H$6)) -> 0 | I31: =IF($E31=$E$5,(I$5),(I$6)) -> 0 | J31: =IF($E31=$E$5,(J$5),(J$6)) -> 0 | K31: =IF($E31=$E$5,(K$5),(K$6)) -> 0 | L31: =IF($E31=$E$5,(L$5),(L$6)) -> 1 | M31: =IF($E31=$E$5,(M$5),(M$6)) -> 1 | ... AC31: =IF($E31=$E$5,(AC$5),(AC$6)) -> 0 | AD31: =SUM(F31:AC31) -> 9
D32: 44950 | E32: =IF(WEEKDAY(D32, 2)<6, "weekday", "weekend") -> weekday | F32: =IF($E32=$E$5,(F$5),(F$6)) -> 0 | G32: =IF($E32=$E$5,(G$5),(G$6)) -> 0 | H32: =IF($E32=$E$5,(H$5),(H$6)) -> 0 | I32: =IF($E32=$E$5,(I$5),(I$6)) -> 0 | J32: =IF($E32=$E$5,(J$5),(J$6)) -> 0 | K32: =IF($E32=$E$5,(K$5),(K$6)) -> 0 | L32: =IF($E32=$E$5,(L$5),(L$6)) -> 1 | M32: =IF($E32=$E$5,(M$5),(M$6)) -> 1 | ... AC32: =IF($E32=$E$5,(AC$5),(AC$6)) -> 0 | AD32: =SUM(F32:AC32) -> 9
D33: 44951 | E33: =IF(WEEKDAY(D33, 2)<6, "weekday", "weekend") -> weekday | F33: =IF($E33=$E$5,(F$5),(F$6)) -> 0 | G33: =IF($E33=$E$5,(G$5),(G$6)) -> 0 | H33: =IF($E33=$E$5,(H$5),(H$6)) -> 0 | I33: =IF($E33=$E$5,(I$5),(I$6)) -> 0 | J33: =IF($E33=$E$5,(J$5),(J$6)) -> 0 | K33: =IF($E33=$E$5,(K$5),(K$6)) -> 0 | L33: =IF($E33=$E$5,(L$5),(L$6)) -> 1 | M33: =IF($E33=$E$5,(M$5),(M$6)) -> 1 | ... AC33: =IF($E33=$E$5,(AC$5),(AC$6)) -> 0 | AD33: =SUM(F33:AC33) -> 9
D34: 44952 | E34: =IF(WEEKDAY(D34, 2)<6, "weekday", "weekend") -> weekday | F34: =IF($E34=$E$5,(F$5),(F$6)) -> 0 | G34: =IF($E34=$E$5,(G$5),(G$6)) -> 0 | H34: =IF($E34=$E$5,(H$5),(H$6)) -> 0 | I34: =IF($E34=$E$5,(I$5),(I$6)) -> 0 | J34: =IF($E34=$E$5,(J$5),(J$6)) -> 0 | K34: =IF($E34=$E$5,(K$5),(K$6)) -> 0 | L34: =IF($E34=$E$5,(L$5),(L$6)) -> 1 | M34: =IF($E34=$E$5,(M$5),(M$6)) -> 1 | ... AC34: =IF($E34=$E$5,(AC$5),(AC$6)) -> 0 | AD34: =SUM(F34:AC34) -> 9
D35: 44953 | E35: =IF(WEEKDAY(D35, 2)<6, "weekday", "weekend") -> weekday | F35: =IF($E35=$E$5,(F$5),(F$6)) -> 0 | G35: =IF($E35=$E$5,(G$5),(G$6)) -> 0 | H35: =IF($E35=$E$5,(H$5),(H$6)) -> 0 | I35: =IF($E35=$E$5,(I$5),(I$6)) -> 0 | J35: =IF($E35=$E$5,(J$5),(J$6)) -> 0 | K35: =IF($E35=$E$5,(K$5),(K$6)) -> 0 | L35: =IF($E35=$E$5,(L$5),(L$6)) -> 1 | M35: =IF($E35=$E$5,(M$5),(M$6)) -> 1 | ... AC35: =IF($E35=$E$5,(AC$5),(AC$6)) -> 0 | AD35: =SUM(F35:AC35) -> 9
... D373: 45291 | E373: =IF(WEEKDAY(D373, 2)<6, "weekday", "weekend") -> weekend | F373: =IF($E373=$E$5,(F$5),(F$6)) -> 0 | G373: =IF($E373=$E$5,(G$5),(G$6)) -> 0 | H373: =IF($E373=$E$5,(H$5),(H$6)) -> 0 | I373: =IF($E373=$E$5,(I$5),(I$6)) -> 0 | J373: =IF($E373=$E$5,(J$5),(J$6)) -> 0 | K373: =IF($E373=$E$5,(K$5),(K$6)) -> 0 | L373: =IF($E373=$E$5,(L$5),(L$6)) -> 1 | M373: =IF($E373=$E$5,(M$5),(M$6)) -> 1 | ... AC373: =IF($E373=$E$5,(AC$5),(AC$6)) -> 0 | AD373: =SUM(F373:AC373) -> 16
AD374: =SUM(AD9:AD373) -> 4020

Sheet Daily Heat Demand
F3: Hour of Day
F4: 1 | G4: 2 | H4: 3 | I4: 4 | J4: 5 | K4: 6 | L4: 7 | M4: 8 | N4: 9 | O4: 10 | P4: 11 | Q4: 12 | R4: 13 | S4: 14 | T4: 15 | U4: 16 | V4: 17 | W4: 18 | X4: 19 | Y4: 20 | Z4: 21 | AA4: 22 | AB4: 23 | AC4: 24
D5: Heating system operating hours | E5: weekend | F5: 0 | G5: 0 | H5: 0 | I5: 0 | J5: 0 | K5: 0 | L5: 1 | M5: 1 | N5: 1 | O5: 1 | P5: 1 | Q5: 1 | R5: 1 | S5: 1 | T5: 1 | U5: 1 | V5: 1 | W5: 1 | X5: 1 | Y5: 1 | Z5: 1 | AA5: 1 | AB5: 0
E6: weekday | F6: 0 | G6: 0 | H6: 0 | I6: 0 | J6: 0 | K6: 0 | L6: 1 | M6: 1 | N6: 0 | O6: 0 | P6: 0 | Q6: 0 | R6: 0 | S6: 0 | T6: 0 | U6: 1 | V6: 1 | W6: 1 | X6: 1 | Y6: 1 | Z6: 1 | AA6: 1 | AB6: 0 | AC6: 0
AD7: Total | AE7: Month Total | AF7: Check Sum
D8: 44927 | E8: =IF(WEEKDAY(D8, 2)<6, "weekday", "weekend") -> weekend | F8: ='Degree-days'!$C$12*IF($E8=$E$5,(F$5),(F$6)) -> 0 | G8: ='Degree-days'!$C$12*IF($E8=$E$5,(G$5),(G$6)) -> 0 | H8: ='Degree-days'!$C$12*IF($E8=$E$5,(H$5),(H$6)) -> 0 | I8: ='Degree-days'!$C$12*IF($E8=$E$5,(I$5),(I$6)) -> 0 | J8: ='Degree-days'!$C$12*IF($E8=$E$5,(J$5),(J$6)) -> 0 | K8: ='Degree-days'!$C$12*IF($E8=$E$5,(K$5),(K$6)) -> 0 | L8: ='Degree-days'!$C$12*IF($E8=$E$5,(L$5),(L$6)) -> 3.5107768 | M8: ='Degree-days'!$C$12*IF($E8=$E$5,(M$5),(M$6)) -> 3.5107768 | ... AC8: ='Degree-days'!$C$12*IF($E8=$E$5,(AC$5),(AC$6)) -> 0 | AD8: =SUM(F8:AC8) -> 56.172429
D9: 44928 | E9: =IF(WEEKDAY(D9, 2)<6, "weekday", "weekend") -> weekday | F9: ='Degree-days'!$C$12*IF($E9=$E$5,(F$5),(F$6)) -> 0 | G9: ='Degree-days'!$C$12*IF($E9=$E$5,(G$5),(G$6)) -> 0 | H9: ='Degree-days'!$C$12*IF($E9=$E$5,(H$5),(H$6)) -> 0 | I9: ='Degree-days'!$C$12*IF($E9=$E$5,(I$5),(I$6)) -> 0 | J9: ='Degree-days'!$C$12*IF($E9=$E$5,(J$5),(J$6)) -> 0 | K9: ='Degree-days'!$C$12*IF($E9=$E$5,(K$5),(K$6)) -> 0 | L9: ='Degree-days'!$C$12*IF($E9=$E$5,(L$5),(L$6)) -> 3.5107768 | M9: ='Degree-days'!$C$12*IF($E9=$E$5,(M$5),(M$6)) -> 3.5107768 | ... AC9: ='Degree-days'!$C$12*IF($E9=$E$5,(AC$5),(AC$6)) -> 0 | AD9: =SUM(F9:AC9) -> 31.596991
D10: 44929 | E10: =IF(WEEKDAY(D10, 2)<6, "weekday", "weekend") -> weekday | F10: ='Degree-days'!$C$12*IF($E10=$E$5,(F$5),(F$6)) -> 0 | G10: ='Degree-days'!$C$12*IF($E10=$E$5,(G$5),(G$6)) -> 0 | H10: ='Degree-days'!$C$12*IF($E10=$E$5,(H$5),(H$6)) -> 0 | I10: ='Degree-days'!$C$12*IF($E10=$E$5,(I$5),(I$6)) -> 0 | J10: ='Degree-days'!$C$12*IF($E10=$E$5,(J$5),(J$6)) -> 0 | K10: ='Degree-days'!$C$12*IF($E10=$E$5,(K$5),(K$6)) -> 0 | L10: ='Degree-days'!$C$12*IF($E10=$E$5,(L$5),(L$6)) -> 3.5107768 | M10: ='Degree-days'!$C$12*IF($E10=$E$5,(M$5),(M$6)) -> 3.5107768 | ... AC10: ='Degree-days'!$C$12*IF($E10=$E$5,(AC$5),(AC$6)) -> 0 | AD10: =SUM(F10:AC10) -> 31.596991
D11: 44930 | E11: =IF(WEEKDAY(D11, 2)<6, "weekday", "weekend") -> weekday | F11: ='Degree-days'!$C$12*IF($E11=$E$5,(F$5),(F$6)) -> 0 | G11: ='Degree-days'!$C$12*IF($E11=$E$5,(G$5),(G$6)) -> 0 | H11: ='Degree-days'!$C$12*IF($E11=$E$5,(H$5),(H$6)) -> 0 | I11: ='Degree-days'!$C$12*IF($E11=$E$5,(I$5),(I$6)) -> 0 | J11: ='Degree-days'!$C$12*IF($E11=$E$5,(J$5),(J$6)) -> 0 | K11: ='Degree-days'!$C$12*IF($E11=$E$5,(K$5),(K$6)) -> 0 | L11: ='Degree-days'!$C$12*IF($E11=$E$5,(L$5),(L$6)) -> 3.5107768 | M11: ='Degree-days'!$C$12*IF($E11=$E$5,(M$5),(M$6)) -> 3.5107768 | ... AC11: ='Degree-days'!$C$12*IF($E11=$E$5,(AC$5),(AC$6)) -> 0 | AD11: =SUM(F11:AC11) -> 31.596991
D12: 44931 | E12: =IF(WEEKDAY(D12, 2)<6, "weekday", "weekend") -> weekday | F12: ='Degree-days'!$C$12*IF($E12=$E$5,(F$5),(F$6)) -> 0 | G12: ='Degree-days'!$C$12*IF($E12=$E$5,(G$5),(G$6)) -> 0 | H12: ='Degree-days'!$C$12*IF($E12=$E$5,(H$5),(H$6)) -> 0 | I12: ='Degree-days'!$C$12*IF($E12=$E$5,(I$5),(I$6)) -> 0 | J12: ='Degree-days'!$C$12*IF($E12=$E$5,(J$5),(J$6)) -> 0 | K12: ='Degree-days'!$C$12*IF($E12=$E$5,(K$5),(K$6)) -> 0 | L12: ='Degree-days'!$C$12*IF($E12=$E$5,(L$5),(L$6)) -> 3.5107768 | M12: ='Degree-days'!$C$12*IF($E12=$E$5,(M$5),(M$6)) -> 3.5107768 | ... AC12: ='Degree-days'!$C$12*IF($E12=$E$5,(AC$5),(AC$6)) -> 0 | AD12: =SUM(F12:AC12) -> 31.596991
D13: 44932 | E13: =IF(WEEKDAY(D13, 2)<6, "weekday", "weekend") -> weekday | F13: ='Degree-days'!$C$12*IF($E13=$E$5,(F$5),(F$6)) -> 0 | G13: ='Degree-days'!$C$12*IF($E13=$E$5,(G$5),(G$6)) -> 0 | H13: ='Degree-days'!$C$12*IF($E13=$E$5,(H$5),(H$6)) -> 0 | I13: ='Degree-days'!$C$12*IF($E13=$E$5,(I$5),(I$6)) -> 0 | J13: ='Degree-days'!$C$12*IF($E13=$E$5,(J$5),(J$6)) -> 0 | K13: ='Degree-days'!$C$12*IF($E13=$E$5,(K$5),(K$6)) -> 0 | L13: ='Degree-days'!$C$12*IF($E13=$E$5,(L$5),(L$6)) -> 3.5107768 | M13: ='Degree-days'!$C$12*IF($E13=$E$5,(M$5),(M$6)) -> 3.5107768 | ... AC13: ='Degree-days'!$C$12*IF($E13=$E$5,(AC$5),(AC$6)) -> 0 | AD13: =SUM(F13:AC13) -> 31.596991
D14: 44933 | E14: =IF(WEEKDAY(D14, 2)<6, "weekday", "weekend") -> weekend | F14: ='Degree-days'!$C$12*IF($E14=$E$5,(F$5),(F$6)) -> 0 | G14: ='Degree-days'!$C$12*IF($E14=$E$5,(G$5),(G$6)) -> 0 | H14: ='Degree-days'!$C$12*IF($E14=$E$5,(H$5),(H$6)) -> 0 | I14: ='Degree-days'!$C$12*IF($E14=$E$5,(I$5),(I$6)) -> 0 | J14: ='Degree-days'!$C$12*IF($E14=$E$5,(J$5),(J$6)) -> 0 | K14: ='Degree-days'!$C$12*IF($E14=$E$5,(K$5),(K$6)) -> 0 | L14: ='Degree-days'!$C$12*IF($E14=$E$5,(L$5),(L$6)) -> 3.5107768 | M14: ='Degree-days'!$C$12*IF($E14=$E$5,(M$5),(M$6)) -> 3.5107768 | ... AC14: ='Degree-days'!$C$12*IF($E14=$E$5,(AC$5),(AC$6)) -> 0 | AD14: =SUM(F14:AC14) -> 56.172429
D15: 44934 | E15: =IF(WEEKDAY(D15, 2)<6, "weekday", "weekend") -> weekend | F15: ='Degree-days'!$C$12*IF($E15=$E$5,(F$5),(F$6)) -> 0 | G15: ='Degree-days'!$C$12*IF($E15=$E$5,(G$5),(G$6)) -> 0 | H15: ='Degree-days'!$C$12*IF($E15=$E$5,(H$5),(H$6)) -> 0 | I15: ='Degree-days'!$C$12*IF($E15=$E$5,(I$5),(I$6)) -> 0 | J15: ='Degree-days'!$C$12*IF($E15=$E$5,(J$5),(J$6)) -> 0 | K15: ='Degree-days'!$C$12*IF($E15=$E$5,(K$5),(K$6)) -> 0 | L15: ='Degree-days'!$C$12*IF($E15=$E$5,(L$5),(L$6)) -> 3.5107768 | M15: ='Degree-days'!$C$12*IF($E15=$E$5,(M$5),(M$6)) -> 3.5107768 | ... AC15: ='Degree-days'!$C$12*IF($E15=$E$5,(AC$5),(AC$6)) -> 0 | AD15: =SUM(F15:AC15) -> 56.172429
D16: 44935 | E16: =IF(WEEKDAY(D16, 2)<6, "weekday", "weekend") -> weekday | F16: ='Degree-days'!$C$12*IF($E16=$E$5,(F$5),(F$6)) -> 0 | G16: ='Degree-days'!$C$12*IF($E16=$E$5,(G$5),(G$6)) -> 0 | H16: ='Degree-days'!$C$12*IF($E16=$E$5,(H$5),(H$6)) -> 0 | I16: ='Degree-days'!$C$12*IF($E16=$E$5,(I$5),(I$6)) -> 0 | J16: ='Degree-days'!$C$12*IF($E16=$E$5,(J$5),(J$6)) -> 0 | K16: ='Degree-days'!$C$12*IF($E16=$E$5,(K$5),(K$6)) -> 0 | L16: ='Degree-days'!$C$12*IF($E16=$E$5,(L$5),(L$6)) -> 3.5107768 | M16: ='Degree-days'!$C$12*IF($E16=$E$5,(M$5),(M$6)) -> 3.5107768 | ... AC16: ='Degree-days'!$C$12*IF($E16=$E$5,(AC$5),(AC$6)) -> 0 | AD16: =SUM(F16:AC16) -> 31.596991
D17: 44936 | E17: =IF(WEEKDAY(D17, 2)<6, "weekday", "weekend") -> weekday | F17: ='Degree-days'!$C$12*IF($E17=$E$5,(F$5),(F$6)) -> 0 | G17: ='Degree-days'!$C$12*IF($E17=$E$5,(G$5),(G$6)) -> 0 | H17: ='Degree-days'!$C$12*IF($E17=$E$5,(H$5),(H$6)) -> 0 | I17: ='Degree-days'!$C$12*IF($E17=$E$5,(I$5),(I$6)) -> 0 | J17: ='Degree-days'!$C$12*IF($E17=$E$5,(J$5),(J$6)) -> 0 | K17: ='Degree-days'!$C$12*IF($E17=$E$5,(K$5),(K$6)) -> 0 | L17: ='Degree-days'!$C$12*IF($E17=$E$5,(L$5),(L$6)) -> 3.5107768 | M17: ='Degree-days'!$C$12*IF($E17=$E$5,(M$5),(M$6)) -> 3.5107768 | ... AC17: ='Degree-days'!$C$12*IF($E17=$E$5,(AC$5),(AC$6)) -> 0 | AD17: =SUM(F17:AC17) -> 31.596991
D18: 44937 | E18: =IF(WEEKDAY(D18, 2)<6, "weekday", "weekend") -> weekday | F18: ='Degree-days'!$C$12*IF($E18=$E$5,(F$5),(F$6)) -> 0 | G18: ='Degree-days'!$C$12*IF($E18=$E$5,(G$5),(G$6)) -> 0 | H18: ='Degree-days'!$C$12*IF($E18=$E$5,(H$5),(H$6)) -> 0 | I18: ='Degree-days'!$C$12*IF($E18=$E$5,(I$5),(I$6)) -> 0 | J18: ='Degree-days'!$C$12*IF($E18=$E$5,(J$5),(J$6)) -> 0 | K18: ='Degree-days'!$C$12*IF($E18=$E$5,(K$5),(K$6)) -> 0 | L18: ='Degree-days'!$C$12*IF($E18=$E$5,(L$5),(L$6)) -> 3.5107768 | M18: ='Degree-days'!$C$12*IF($E18=$E$5,(M$5),(M$6)) -> 3.5107768 | ... AC18: ='Degree-days'!$C$12*IF($E18=$E$5,(AC$5),(AC$6)) -> 0 | AD18: =SUM(F18:AC18) -> 31.596991
D19: 44938 | E19: =IF(WEEKDAY(D19, 2)<6, "weekday", "weekend") -> weekday | F19: ='Degree-days'!$C$12*IF($E19=$E$5,(F$5),(F$6)) -> 0 | G19: ='Degree-days'!$C$12*IF($E19=$E$5,(G$5),(G$6)) -> 0 | H19: ='Degree-days'!$C$12*IF($E19=$E$5,(H$5),(H$6)) -> 0 | I19: ='Degree-days'!$C$12*IF($E19=$E$5,(I$5),(I$6)) -> 0 | J19: ='Degree-days'!$C$12*IF($E19=$E$5,(J$5),(J$6)) -> 0 | K19: ='Degree-days'!$C$12*IF($E19=$E$5,(K$5),(K$6)) -> 0 | L19: ='Degree-days'!$C$12*IF($E19=$E$5,(L$5),(L$6)) -> 3.5107768 | M19: ='Degree-days'!$C$12*IF($E19=$E$5,(M$5),(M$6)) -> 3.5107768 | ... AC19: ='Degree-days'!$C$12*IF($E19=$E$5,(AC$5),(AC$6)) -> 0 | AD19: =SUM(F19:AC19) -> 31.596991
... D37: 44956 | E37: =IF(WEEKDAY(D37, 2)<6, "weekday", "weekend") -> weekday | F37: ='Degree-days'!$C$12*IF($E37=$E$5,(F$5),(F$6)) -> 0 | G37: ='Degree-days'!$C$12*IF($E37=$E$5,(G$5),(G$6)) -> 0 | H37: ='Degree-days'!$C$12*IF($E37=$E$5,(H$5),(H$6)) -> 0 | I37: ='Degree-days'!$C$12*IF($E37=$E$5,(I$5),(I$6)) -> 0 | J37: ='Degree-days'!$C$12*IF($E37=$E$5,(J$5),(J$6)) -> 0 | K37: ='Degree-days'!$C$12*IF($E37=$E$5,(K$5),(K$6)) -> 0 | L37: ='Degree-days'!$C$12*IF($E37=$E$5,(L$5),(L$6)) -> 3.5107768 | M37: ='Degree-days'!$C$12*IF($E37=$E$5,(M$5),(M$6)) -> 3.5107768 | ... AC37: ='Degree-days'!$C$12*IF($E37=$E$5,(AC$5),(AC$6)) -> 0 | AD37: =SUM(F37:AC37) -> 31.596991
D38: 44957 | E38: =IF(WEEKDAY(D38, 2)<6, "weekday", "weekend") -> weekday | F38: ='Degree-days'!$C$12*IF($E38=$E$5,(F$5),(F$6)) -> 0 | G38: ='Degree-days'!$C$12*IF($E38=$E$5,(G$5),(G$6)) -> 0 | H38: ='Degree-days'!$C$12*IF($E38=$E$5,(H$5),(H$6)) -> 0 | I38: ='Degree-days'!$C$12*IF($E38=$E$5,(I$5),(I$6)) -> 0 | J38: ='Degree-days'!$C$12*IF($E38=$E$5,(J$5),(J$6)) -> 0 | K38: ='Degree-days'!$C$12*IF($E38=$E$5,(K$5),(K$6)) -> 0 | L38: ='Degree-days'!$C$12*IF($E38=$E$5,(L$5),(L$6)) -> 3.5107768 | M38: ='Degree-days'!$C$12*IF($E38=$E$5,(M$5),(M$6)) -> 3.5107768 | ... AC38: ='Degree-days'!$C$12*IF($E38=$E$5,(AC$5),(AC$6)) -> 0 | AD38: =SUM(F38:AC38) -> 31.596991 | AE38: =SUM(AD8:AD38) -> 1200.6857 | AF38: ='Degree-days'!C11 -> 1200.6857
D39: 44958 | E39: =IF(WEEKDAY(D39, 2)<6, "weekday", "weekend") -> weekday | F39: ='Degree-days'!$D$12*IF($E39=$E$5,(F$5),(F$6)) -> 0 | G39: ='Degree-days'!$D$12*IF($E39=$E$5,(G$5),(G$6)) -> 0 | H39: ='Degree-days'!$D$12*IF($E39=$E$5,(H$5),(H$6)) -> 0 | I39: ='Degree-days'!$D$12*IF($E39=$E$5,(I$5),(I$6)) -> 0 | J39: ='Degree-days'!$D$12*IF($E39=$E$5,(J$5),(J$6)) -> 0 | K39: ='Degree-days'!$D$12*IF($E39=$E$5,(K$5),(K$6)) -> 0 | L39: ='Degree-days'!$D$12*IF($E39=$E$5,(L$5),(L$6)) -> 3.4347685 | M39: ='Degree-days'!$D$12*IF($E39=$E$5,(M$5),(M$6)) -> 3.4347685 | ... AC39: ='Degree-days'!$D$12*IF($E39=$E$5,(AC$5),(AC$6)) -> 0 | AD39: =SUM(F39:AC39) -> 30.912917
D40: 44959 | E40: =IF(WEEKDAY(D40, 2)<6, "weekday", "weekend") -> weekday | F40: ='Degree-days'!$D$12*IF($E40=$E$5,(F$5),(F$6)) -> 0 | G40: ='Degree-days'!$D$12*IF($E40=$E$5,(G$5),(G$6)) -> 0 | H40: ='Degree-days'!$D$12*IF($E40=$E$5,(H$5),(H$6)) -> 0 | I40: ='Degree-days'!$D$12*IF($E40=$E$5,(I$5),(I$6)) -> 0 | J40: ='Degree-days'!$D$12*IF($E40=$E$5,(J$5),(J$6)) -> 0 | K40: ='Degree-days'!$D$12*IF($E40=$E$5,(K$5),(K$6)) -> 0 | L40: ='Degree-days'!$D$12*IF($E40=$E$5,(L$5),(L$6)) -> 3.4347685 | M40: ='Degree-days'!$D$12*IF($E40=$E$5,(M$5),(M$6)) -> 3.4347685 | ... AC40: ='Degree-days'!$D$12*IF($E40=$E$5,(AC$5),(AC$6)) -> 0 | AD40: =SUM(F40:AC40) -> 30.912917
D41: 44960 | E41: =IF(WEEKDAY(D41, 2)<6, "weekday", "weekend") -> weekday | F41: ='Degree-days'!$D$12*IF($E41=$E$5,(F$5),(F$6)) -> 0 | G41: ='Degree-days'!$D$12*IF($E41=$E$5,(G$5),(G$6)) -> 0 | H41: ='Degree-days'!$D$12*IF($E41=$E$5,(H$5),(H$6)) -> 0 | I41: ='Degree-days'!$D$12*IF($E41=$E$5,(I$5),(I$6)) -> 0 | J41: ='Degree-days'!$D$12*IF($E41=$E$5,(J$5),(J$6)) -> 0 | K41: ='Degree-days'!$D$12*IF($E41=$E$5,(K$5),(K$6)) -> 0 | L41: ='Degree-days'!$D$12*IF($E41=$E$5,(L$5),(L$6)) -> 3.4347685 | M41: ='Degree-days'!$D$12*IF($E41=$E$5,(M$5),(M$6)) -> 3.4347685 | ... AC41: ='Degree-days'!$D$12*IF($E41=$E$5,(AC$5),(AC$6)) -> 0 | AD41: =SUM(F41:AC41) -> 30.912917
D42: 44961 | E42: =IF(WEEKDAY(D42, 2)<6, "weekday", "weekend") -> weekend | F42: ='Degree-days'!$D$12*IF($E42=$E$5,(F$5),(F$6)) -> 0 | G42: ='Degree-days'!$D$12*IF($E42=$E$5,(G$5),(G$6)) -> 0 | H42: ='Degree-days'!$D$12*IF($E42=$E$5,(H$5),(H$6)) -> 0 | I42: ='Degree-days'!$D$12*IF($E42=$E$5,(I$5),(I$6)) -> 0 | J42: ='Degree-days'!$D$12*IF($E42=$E$5,(J$5),(J$6)) -> 0 | K42: ='Degree-days'!$D$12*IF($E42=$E$5,(K$5),(K$6)) -> 0 | L42: ='Degree-days'!$D$12*IF($E42=$E$5,(L$5),(L$6)) -> 3.4347685 | M42: ='Degree-days'!$D$12*IF($E42=$E$5,(M$5),(M$6)) -> 3.4347685 | ... AC42: ='Degree-days'!$D$12*IF($E42=$E$5,(AC$5),(AC$6)) -> 0 | AD42: =SUM(F42:AC42) -> 54.956296
D43: 44962 | E43: =IF(WEEKDAY(D43, 2)<6, "weekday", "weekend") -> weekend | F43: ='Degree-days'!$D$12*IF($E43=$E$5,(F$5),(F$6)) -> 0 | G43: ='Degree-days'!$D$12*IF($E43=$E$5,(G$5),(G$6)) -> 0 | H43: ='Degree-days'!$D$12*IF($E43=$E$5,(H$5),(H$6)) -> 0 | I43: ='Degree-days'!$D$12*IF($E43=$E$5,(I$5),(I$6)) -> 0 | J43: ='Degree-days'!$D$12*IF($E43=$E$5,(J$5),(J$6)) -> 0 | K43: ='Degree-days'!$D$12*IF($E43=$E$5,(K$5),(K$6)) -> 0 | L43: ='Degree-days'!$D$12*IF($E43=$E$5,(L$5),(L$6)) -> 3.4347685 | M43: ='Degree-days'!$D$12*IF($E43=$E$5,(M$5),(M$6)) -> 3.4347685 | ... AC43: ='Degree-days'!$D$12*IF($E43=$E$5,(AC$5),(AC$6)) -> 0 | AD43: =SUM(F43:AC43) -> 54.956296
D44: 44963 | E44: =IF(WEEKDAY(D44, 2)<6, "weekday", "weekend") -> weekday | F44: ='Degree-days'!$D$12*IF($E44=$E$5,(F$5),(F$6)) -> 0 | G44: ='Degree-days'!$D$12*IF($E44=$E$5,(G$5),(G$6)) -> 0 | H44: ='Degree-days'!$D$12*IF($E44=$E$5,(H$5),(H$6)) -> 0 | I44: ='Degree-days'!$D$12*IF($E44=$E$5,(I$5),(I$6)) -> 0 | J44: ='Degree-days'!$D$12*IF($E44=$E$5,(J$5),(J$6)) -> 0 | K44: ='Degree-days'!$D$12*IF($E44=$E$5,(K$5),(K$6)) -> 0 | L44: ='Degree-days'!$D$12*IF($E44=$E$5,(L$5),(L$6)) -> 3.4347685 | M44: ='Degree-days'!$D$12*IF($E44=$E$5,(M$5),(M$6)) -> 3.4347685 | ... AC44: ='Degree-days'!$D$12*IF($E44=$E$5,(AC$5),(AC$6)) -> 0 | AD44: =SUM(F44:AC44) -> 30.912917
D45: 44964 | E45: =IF(WEEKDAY(D45, 2)<6, "weekday", "weekend") -> weekday | F45: ='Degree-days'!$D$12*IF($E45=$E$5,(F$5),(F$6)) -> 0 | G45: ='Degree-days'!$D$12*IF($E45=$E$5,(G$5),(G$6)) -> 0 | H45: ='Degree-days'!$D$12*IF($E45=$E$5,(H$5),(H$6)) -> 0 | I45: ='Degree-days'!$D$12*IF($E45=$E$5,(I$5),(I$6)) -> 0 | J45: ='Degree-days'!$D$12*IF($E45=$E$5,(J$5),(J$6)) -> 0 | K45: ='Degree-days'!$D$12*IF($E45=$E$5,(K$5),(K$6)) -> 0 | L45: ='Degree-days'!$D$12*IF($E45=$E$5,(L$5),(L$6)) -> 3.4347685 | M45: ='Degree-days'!$D$12*IF($E45=$E$5,(M$5),(M$6)) -> 3.4347685 | ... AC45: ='Degree-days'!$D$12*IF($E45=$E$5,(AC$5),(AC$6)) -> 0 | AD45: =SUM(F45:AC45) -> 30.912917
D46: 44965 | E46: =IF(WEEKDAY(D46, 2)<6, "weekday", "weekend") -> weekday | F46: ='Degree-days'!$D$12*IF($E46=$E$5,(F$5),(F$6)) -> 0 | G46: ='Degree-days'!$D$12*IF($E46=$E$5,(G$5),(G$6)) -> 0 | H46: ='Degree-days'!$D$12*IF($E46=$E$5,(H$5),(H$6)) -> 0 | I46: ='Degree-days'!$D$12*IF($E46=$E$5,(I$5),(I$6)) -> 0 | J46: ='Degree-days'!$D$12*IF($E46=$E$5,(J$5),(J$6)) -> 0 | K46: ='Degree-days'!$D$12*IF($E46=$E$5,(K$5),(K$6)) -> 0 | L46: ='Degree-days'!$D$12*IF($E46=$E$5,(L$5),(L$6)) -> 3.4347685 | M46: ='Degree-days'!$D$12*IF($E46=$E$5,(M$5),(M$6)) -> 3.4347685 | ... AC46: ='Degree-days'!$D$12*IF($E46=$E$5,(AC$5),(AC$6)) -> 0 | AD46: =SUM(F46:AC46) -> 30.912917
D47: 44966 | E47: =IF(WEEKDAY(D47, 2)<6, "weekday", "weekend") -> weekday | F47: ='Degree-days'!$D$12*IF($E47=$E$5,(F$5),(F$6)) -> 0 | G47: ='Degree-days'!$D$12*IF($E47=$E$5,(G$5),(G$6)) -> 0 | H47: ='Degree-days'!$D$12*IF($E47=$E$5,(H$5),(H$6)) -> 0 | I47: ='Degree-days'!$D$12*IF($E47=$E$5,(I$5),(I$6)) -> 0 | J47: ='Degree-days'!$D$12*IF($E47=$E$5,(J$5),(J$6)) -> 0 | K47: ='Degree-days'!$D$12*IF($E47=$E$5,(K$5),(K$6)) -> 0 | L47: ='Degree-days'!$D$12*IF($E47=$E$5,(L$5),(L$6)) -> 3.4347685 | M47: ='Degree-days'!$D$12*IF($E47=$E$5,(M$5),(M$6)) -> 3.4347685 | ... AC47: ='Degree-days'!$D$12*IF($E47=$E$5,(AC$5),(AC$6)) -> 0 | AD47: =SUM(F47:AC47) -> 30.912917
D48: 44967 | E48: =IF(WEEKDAY(D48, 2)<6, "weekday", "weekend") -> weekday | F48: ='Degree-days'!$D$12*IF($E48=$E$5,(F$5),(F$6)) -> 0 | G48: ='Degree-days'!$D$12*IF($E48=$E$5,(G$5),(G$6)) -> 0 | H48: ='Degree-days'!$D$12*IF($E48=$E$5,(H$5),(H$6)) -> 0 | I48: ='Degree-days'!$D$12*IF($E48=$E$5,(I$5),(I$6)) -> 0 | J48: ='Degree-days'!$D$12*IF($E48=$E$5,(J$5),(J$6)) -> 0 | K48: ='Degree-days'!$D$12*IF($E48=$E$5,(K$5),(K$6)) -> 0 | L48: ='Degree-days'!$D$12*IF($E48=$E$5,(L$5),(L$6)) -> 3.4347685 | M48: ='Degree-days'!$D$12*IF($E48=$E$5,(M$5),(M$6)) -> 3.4347685 | ... AC48: ='Degree-days'!$D$12*IF($E48=$E$5,(AC$5),(AC$6)) -> 0 | AD48: =SUM(F48:AC48) -> 30.912917
D49: 44968 | E49: =IF(WEEKDAY(D49, 2)<6, "weekday", "weekend") -> weekend | F49: ='Degree-days'!$D$12*IF($E49=$E$5,(F$5),(F$6)) -> 0 | G49: ='Degree-days'!$D$12*IF($E49=$E$5,(G$5),(G$6)) -> 0 | H49: ='Degree-days'!$D$12*IF($E49=$E$5,(H$5),(H$6)) -> 0 | I49: ='Degree-days'!$D$12*IF($E49=$E$5,(I$5),(I$6)) -> 0 | J49: ='Degree-days'!$D$12*IF($E49=$E$5,(J$5),(J$6)) -> 0 | K49: ='Degree-days'!$D$12*IF($E49=$E$5,(K$5),(K$6)) -> 0 | L49: ='Degree-days'!$D$12*IF($E49=$E$5,(L$5),(L$6)) -> 3.4347685 | M49: ='Degree-days'!$D$12*IF($E49=$E$5,(M$5),(M$6)) -> 3.4347685 | ... AC49: ='Degree-days'!$D$12*IF($E49=$E$5,(AC$5),(AC$6)) -> 0 | AD49: =SUM(F49:AC49) -> 54.956296
D50: 44969 | E50: =IF(WEEKDAY(D50, 2)<6, "weekday", "weekend") -> weekend | F50: ='Degree-days'!$D$12*IF($E50=$E$5,(F$5),(F$6)) -> 0 | G50: ='Degree-days'!$D$12*IF($E50=$E$5,(G$5),(G$6)) -> 0 | H50: ='Degree-days'!$D$12*IF($E50=$E$5,(H$5),(H$6)) -> 0 | I50: ='Degree-days'!$D$12*IF($E50=$E$5,(I$5),(I$6)) -> 0 | J50: ='Degree-days'!$D$12*IF($E50=$E$5,(J$5),(J$6)) -> 0 | K50: ='Degree-days'!$D$12*IF($E50=$E$5,(K$5),(K$6)) -> 0 | L50: ='Degree-days'!$D$12*IF($E50=$E$5,(L$5),(L$6)) -> 3.4347685 | M50: ='Degree-days'!$D$12*IF($E50=$E$5,(M$5),(M$6)) -> 3.4347685 | ... AC50: ='Degree-days'!$D$12*IF($E50=$E$5,(AC$5),(AC$6)) -> 0 | AD50: =SUM(F50:AC50) -> 54.956296
... D65: 44984 | E65: =IF(WEEKDAY(D65, 2)<6, "weekday", "weekend") -> weekday | F65: ='Degree-days'!$D$12*IF($E65=$E$5,(F$5),(F$6)) -> 0 | G65: ='Degree-days'!$D$12*IF($E65=$E$5,(G$5),(G$6)) -> 0 | H65: ='Degree-days'!$D$12*IF($E65=$E$5,(H$5),(H$6)) -> 0 | I65: ='Degree-days'!$D$12*IF($E65=$E$5,(I$5),(I$6)) -> 0 | J65: ='Degree-days'!$D$12*IF($E65=$E$5,(J$5),(J$6)) -> 0 | K65: ='Degree-days'!$D$12*IF($E65=$E$5,(K$5),(K$6)) -> 0 | L65: ='Degree-days'!$D$12*IF($E65=$E$5,(L$5),(L$6)) -> 3.4347685 | M65: ='Degree-days'!$D$12*IF($E65=$E$5,(M$5),(M$6)) -> 3.4347685 | ... AC65: ='Degree-days'!$D$12*IF($E65=$E$5,(AC$5),(AC$6)) -> 0 | AD65: =SUM(F65:AC65) -> 30.912917
D66: 44985 | E66: =IF(WEEKDAY(D66, 2)<6, "weekday", "weekend") -> weekday | F66: ='Degree-days'!$D$12*IF($E66=$E$5,(F$5),(F$6)) -> 0 | G66: ='Degree-days'!$D$12*IF($E66=$E$5,(G$5),(G$6)) -> 0 | H66: ='Degree-days'!$D$12*IF($E66=$E$5,(H$5),(H$6)) -> 0 | I66: ='Degree-days'!$D$12*IF($E66=$E$5,(I$5),(I$6)) -> 0 | J66: ='Degree-days'!$D$12*IF($E66=$E$5,(J$5),(J$6)) -> 0 | K66: ='Degree-days'!$D$12*IF($E66=$E$5,(K$5),(K$6)) -> 0 | L66: ='Degree-days'!$D$12*IF($E66=$E$5,(L$5),(L$6)) -> 3.4347685 | M66: ='Degree-days'!$D$12*IF($E66=$E$5,(M$5),(M$6)) -> 3.4347685 | ... AC66: ='Degree-days'!$D$12*IF($E66=$E$5,(AC$5),(AC$6)) -> 0 | AD66: =SUM(F66:AC66) -> 30.912917 | AE66: =SUM(AD39:AD66) -> 1057.9087 | AF66: ='Degree-days'!D11 -> 1057.9087
D67: 44986 | E67: =IF(WEEKDAY(D67, 2)<6, "weekday", "weekend") -> weekday | F67: ='Degree-days'!$E$12*IF($E67=$E$5,(F$5),(F$6)) -> 0 | G67: ='Degree-days'!$E$12*IF($E67=$E$5,(G$5),(G$6)) -> 0 | H67: ='Degree-days'!$E$12*IF($E67=$E$5,(H$5),(H$6)) -> 0 | I67: ='Degree-days'!$E$12*IF($E67=$E$5,(I$5),(I$6)) -> 0 | J67: ='Degree-days'!$E$12*IF($E67=$E$5,(J$5),(J$6)) -> 0 | K67: ='Degree-days'!$E$12*IF($E67=$E$5,(K$5),(K$6)) -> 0 | L67: ='Degree-days'!$E$12*IF($E67=$E$5,(L$5),(L$6)) -> 2.9591257 | M67: ='Degree-days'!$E$12*IF($E67=$E$5,(M$5),(M$6)) -> 2.9591257 | ... AC67: ='Degree-days'!$E$12*IF($E67=$E$5,(AC$5),(AC$6)) -> 0 | AD67: =SUM(F67:AC67) -> 26.632132
D68: 44987 | E68: =IF(WEEKDAY(D68, 2)<6, "weekday", "weekend") -> weekday | F68: ='Degree-days'!$E$12*IF($E68=$E$5,(F$5),(F$6)) -> 0 | G68: ='Degree-days'!$E$12*IF($E68=$E$5,(G$5),(G$6)) -> 0 | H68: ='Degree-days'!$E$12*IF($E68=$E$5,(H$5),(H$6)) -> 0 | I68: ='Degree-days'!$E$12*IF($E68=$E$5,(I$5),(I$6)) -> 0 | J68: ='Degree-days'!$E$12*IF($E68=$E$5,(J$5),(J$6)) -> 0 | K68: ='Degree-days'!$E$12*IF($E68=$E$5,(K$5),(K$6)) -> 0 | L68: ='Degree-days'!$E$12*IF($E68=$E$5,(L$5),(L$6)) -> 2.9591257 | M68: ='Degree-days'!$E$12*IF($E68=$E$5,(M$5),(M$6)) -> 2.9591257 | ... AC68: ='Degree-days'!$E$12*IF($E68=$E$5,(AC$5),(AC$6)) -> 0 | AD68: =SUM(F68:AC68) -> 26.632132
D69: 44988 | E69: =IF(WEEKDAY(D69, 2)<6, "weekday", "weekend") -> weekday | F69: ='Degree-days'!$E$12*IF($E69=$E$5,(F$5),(F$6)) -> 0 | G69: ='Degree-days'!$E$12*IF($E69=$E$5,(G$5),(G$6)) -> 0 | H69: ='Degree-days'!$E$12*IF($E69=$E$5,(H$5),(H$6)) -> 0 | I69: ='Degree-days'!$E$12*IF($E69=$E$5,(I$5),(I$6)) -> 0 | J69: ='Degree-days'!$E$12*IF($E69=$E$5,(J$5),(J$6)) -> 0 | K69: ='Degree-days'!$E$12*IF($E69=$E$5,(K$5),(K$6)) -> 0 | L69: ='Degree-days'!$E$12*IF($E69=$E$5,(L$5),(L$6)) -> 2.9591257 | M69: ='Degree-days'!$E$12*IF($E69=$E$5,(M$5),(M$6)) -> 2.9591257 | ... AC69: ='Degree-days'!$E$12*IF($E69=$E$5,(AC$5),(AC$6)) -> 0 | AD69: =SUM(F69:AC69) -> 26.632132
D70: 44989 | E70: =IF(WEEKDAY(D70, 2)<6, "weekday", "weekend") -> weekend | F70: ='Degree-days'!$E$12*IF($E70=$E$5,(F$5),(F$6)) -> 0 | G70: ='Degree-days'!$E$12*IF($E70=$E$5,(G$5),(G$6)) -> 0 | H70: ='Degree-days'!$E$12*IF($E70=$E$5,(H$5),(H$6)) -> 0 | I70: ='Degree-days'!$E$12*IF($E70=$E$5,(I$5),(I$6)) -> 0 | J70: ='Degree-days'!$E$12*IF($E70=$E$5,(J$5),(J$6)) -> 0 | K70: ='Degree-days'!$E$12*IF($E70=$E$5,(K$5),(K$6)) -> 0 | L70: ='Degree-days'!$E$12*IF($E70=$E$5,(L$5),(L$6)) -> 2.9591257 | M70: ='Degree-days'!$E$12*IF($E70=$E$5,(M$5),(M$6)) -> 2.9591257 | ... AC70: ='Degree-days'!$E$12*IF($E70=$E$5,(AC$5),(AC$6)) -> 0 | AD70: =SUM(F70:AC70) -> 47.346012
D71: 44990 | E71: =IF(WEEKDAY(D71, 2)<6, "weekday", "weekend") -> weekend | F71: ='Degree-days'!$E$12*IF($E71=$E$5,(F$5),(F$6)) -> 0 | G71: ='Degree-days'!$E$12*IF($E71=$E$5,(G$5),(G$6)) -> 0 | H71: ='Degree-days'!$E$12*IF($E71=$E$5,(H$5),(H$6)) -> 0 | I71: ='Degree-days'!$E$12*IF($E71=$E$5,(I$5),(I$6)) -> 0 | J71: ='Degree-days'!$E$12*IF($E71=$E$5,(J$5),(J$6)) -> 0 | K71: ='Degree-days'!$E$12*IF($E71=$E$5,(K$5),(K$6)) -> 0 | L71: ='Degree-days'!$E$12*IF($E71=$E$5,(L$5),(L$6)) -> 2.9591257 | M71: ='Degree-days'!$E$12*IF($E71=$E$5,(M$5),(M$6)) -> 2.9591257 | ... AC71: ='Degree-days'!$E$12*IF($E71=$E$5,(AC$5),(AC$6)) -> 0 | AD71: =SUM(F71:AC71) -> 47.346012
D72: 44991 | E72: =IF(WEEKDAY(D72, 2)<6, "weekday", "weekend") -> weekday | F72: ='Degree-days'!$E$12*IF($E72=$E$5,(F$5),(F$6)) -> 0 | G72: ='Degree-days'!$E$12*IF($E72=$E$5,(G$5),(G$6)) -> 0 | H72: ='Degree-days'!$E$12*IF($E72=$E$5,(H$5),(H$6)) -> 0 | I72: ='Degree-days'!$E$12*IF($E72=$E$5,(I$5),(I$6)) -> 0 | J72: ='Degree-days'!$E$12*IF($E72=$E$5,(J$5),(J$6)) -> 0 | K72: ='Degree-days'!$E$12*IF($E72=$E$5,(K$5),(K$6)) -> 0 | L72: ='Degree-days'!$E$12*IF($E72=$E$5,(L$5),(L$6)) -> 2.9591257 | M72: ='Degree-days'!$E$12*IF($E72=$E$5,(M$5),(M$6)) -> 2.9591257 | ... AC72: ='Degree-days'!$E$12*IF($E72=$E$5,(AC$5),(AC$6)) -> 0 | AD72: =SUM(F72:AC72) -> 26.632132
D73: 44992 | E73: =IF(WEEKDAY(D73, 2)<6, "weekday", "weekend") -> weekday | F73: ='Degree-days'!$E$12*IF($E73=$E$5,(F$5),(F$6)) -> 0 | G73: ='Degree-days'!$E$12*IF($E73=$E$5,(G$5),(G$6)) -> 0 | H73: ='Degree-days'!$E$12*IF($E73=$E$5,(H$5),(H$6)) -> 0 | I73: ='Degree-days'!$E$12*IF($E73=$E$5,(I$5),(I$6)) -> 0 | J73: ='Degree-days'!$E$12*IF($E73=$E$5,(J$5),(J$6)) -> 0 | K73: ='Degree-days'!$E$12*IF($E73=$E$5,(K$5),(K$6)) -> 0 | L73: ='Degree-days'!$E$12*IF($E73=$E$5,(L$5),(L$6)) -> 2.9591257 | M73: ='Degree-days'!$E$12*IF($E73=$E$5,(M$5),(M$6)) -> 2.9591257 | ... AC73: ='Degree-days'!$E$12*IF($E73=$E$5,(AC$5),(AC$6)) -> 0 | AD73: =SUM(F73:AC73) -> 26.632132
...

Sheet Daily Heat Demand Matrix (2)
C2: Weekend | G2: Weekday | L2: Weighted
D3: ='Degree-days'!C14 -> Winter (Dec to Feb) | E3: ='Degree-days'!D14 -> Spring/Autumn (Mar to May, Sep to Nov) | F3: ='Degree-days'!E14 -> Summer (Jun to Aug) | H3: =D3 -> Winter (Dec to Feb) | I3: =E3 -> Spring/Autumn (Mar to May, Sep to Nov) | J3: =F3 -> Summer (Jun to Aug) | L3: =D3 -> Winter (Dec to Feb) | M3: =E3 -> Spring/Autumn (Mar to May, Sep to Nov) | N3: =F3 -> Summer (Jun to Aug)
B4: Hour | C4: Boiler Running | D4: ='Degree-days'!C19 -> 3.4332695 | E4: ='Degree-days'!D19 -> 1.8717328 | F4: ='Degree-days'!E19 -> 0.32981104 | H4: =D4 -> 3.4332695 | I4: =E4 -> 1.8717328 | J4: =F4 -> 0.32981104
B6: 1 | C6: {=TRANSPOSE('Daily Heat Demand'!F5:AC5)} -> 0 | D6: =IF(C6=0,0,$D$4) -> 0 | E6: =IF(C6=0,0,$E$4) -> 0 | F6: =IF(C6=0,0,F$4) -> 0 | G6: {=TRANSPOSE('Heat System Daily Operation'!F6:AC6)} -> 0 | H6: =IF(G6=0,0,$H$4) -> 0 | I6: =IF(G6=0,0,$I$4) -> 0 | J6: =IF(G6=0,0,$J$4) -> 0
B7: 2 | C7: 0 | D7: =IF(C7=0,0,$D$4) -> 0 | E7: =IF(C7=0,0,$E$4) -> 0 | F7: =IF(C7=0,0,F$4) -> 0 | G7: 0 | H7: =IF(G7=0,0,$H$4) -> 0 | I7: =IF(G7=0,0,$I$4) -> 0 | J7: =IF(G7=0,0,$J$4) -> 0
B8: 3 | C8: 0 | D8: =IF(C8=0,0,$D$4) -> 0 | E8: =IF(C8=0,0,$E$4) -> 0 | F8: =IF(C8=0,0,F$4) -> 0 | G8: 0 | H8: =IF(G8=0,0,$H$4) -> 0 | I8: =IF(G8=0,0,$I$4) -> 0 | J8: =IF(G8=0,0,$J$4) -> 0
B9: 4 | C9: 0 | D9: =IF(C9=0,0,$D$4) -> 0 | E9: =IF(C9=0,0,$E$4) -> 0 | F9: =IF(C9=0,0,F$4) -> 0 | G9: 0 | H9: =IF(G9=0,0,$H$4) -> 0 | I9: =IF(G9=0,0,$I$4) -> 0 | J9: =IF(G9=0,0,$J$4) -> 0
B10: 5 | C10: 0 | D10: =IF(C10=0,0,$D$4) -> 0 | E10: =IF(C10=0,0,$E$4) -> 0 | F10: =IF(C10=0,0,F$4) -> 0 | G10: 0 | H10: =IF(G10=0,0,$H$4) -> 0 | I10: =IF(G10=0,0,$I$4) -> 0 | J10: =IF(G10=0,0,$J$4) -> 0
B11: 6 | C11: 0 | D11: =IF(C11=0,0,$D$4) -> 0 | E11: =IF(C11=0,0,$E$4) -> 0 | F11: =IF(C11=0,0,F$4) -> 0 | G11: 0 | H11: =IF(G11=0,0,$H$4) -> 0 | I11: =IF(G11=0,0,$I$4) -> 0 | J11: =IF(G11=0,0,$J$4) -> 0
B12: 7 | C12: 1 | D12: =IF(C12=0,0,$D$4) -> 3.4332695 | E12: =IF(C12=0,0,$E$4) -> 1.8717328 | F12: =IF(C12=0,0,F$4) -> 0.32981104 | G12: 1 | H12: =IF(G12=0,0,$H$4) -> 3.4332695 | I12: =IF(G12=0,0,$I$4) -> 1.8717328 | J12: =IF(G12=0,0,$J$4) -> 0.32981104
B13: 8 | C13: 1 | D13: =IF(C13=0,0,$D$4) -> 3.4332695 | E13: =IF(C13=0,0,$E$4) -> 1.8717328 | F13: =IF(C13=0,0,F$4) -> 0.32981104 | G13: 1 | H13: =IF(G13=0,0,$H$4) -> 3.4332695 | I13: =IF(G13=0,0,$I$4) -> 1.8717328 | J13: =IF(G13=0,0,$J$4) -> 0.32981104
B14: 9 | C14: 1 | D14: =IF(C14=0,0,$D$4) -> 3.4332695 | E14: =IF(C14=0,0,$E$4) -> 1.8717328 | F14: =IF(C14=0,0,F$4) -> 0.32981104 | G14: 0 | H14: =IF(G14=0,0,$H$4) -> 0 | I14: =IF(G14=0,0,$I$4) -> 0 | J14: =IF(G14=0,0,$J$4) -> 0
B15: 10 | C15: 1 | D15: =IF(C15=0,0,$D$4) -> 3.4332695 | E15: =IF(C15=0,0,$E$4) -> 1.8717328 | F15: =IF(C15=0,0,F$4) -> 0.32981104 | G15: 0 | H15: =IF(G15=0,0,$H$4) -> 0 | I15: =IF(G15=0,0,$I$4) -> 0 | J15: =IF(G15=0,0,$J$4) -> 0
B16: 11 | C16: 1 | D16: =IF(C16=0,0,$D$4) -> 3.4332695 | E16: =IF(C16=0,0,$E$4) -> 1.8717328 | F16: =IF(C16=0,0,F$4) -> 0.32981104 | G16: 0 | H16: =IF(G16=0,0,$H$4) -> 0 | I16: =IF(G16=0,0,$I$4) -> 0 | J16: =IF(G16=0,0,$J$4) -> 0
B17: 12 | C17: 1 | D17: =IF(C17=0,0,$D$4) -> 3.4332695 | E17: =IF(C17=0,0,$E$4) -> 1.8717328 | F17: =IF(C17=0,0,F$4) -> 0.32981104 | G17: 0 | H17: =IF(G17=0,0,$H$4) -> 0 | I17: =IF(G17=0,0,$I$4) -> 0 | J17: =IF(G17=0,0,$J$4) -> 0
B18: 13 | C18: 1 | D18: =IF(C18=0,0,$D$4) -> 3.4332695 | E18: =IF(C18=0,0,$E$4) -> 1.8717328 | F18: =IF(C18=0,0,F$4) -> 0.32981104 | G18: 0 | H18: =IF(G18=0,0,$H$4) -> 0 | I18: =IF(G18=0,0,$I$4) -> 0 | J18: =IF(G18=0,0,$J$4) -> 0
... B29: 24 | C29: 0 | D29: =IF(C29=0,0,$D$4) -> 0 | E29: =IF(C29=0,0,$E$4) -> 0 | F29: =IF(C29=0,0,F$4) -> 0 | G29: 0 | H29: =IF(G29=0,0,$H$4) -> 0 | I29: =IF(G29=0,0,$I$4) -> 0 | J29: =IF(G29=0,0,$J$4) -> 0

Sheet HomeHeatDemand
F1: Individual Home Heat Demand (kWh) | I1: Total Heat Demand (kWh)
B2: Count | C2: Day | D2: Time | E2: WE/WD | F2: Winter | G2: Spring/Autumn | H2: Summer | I2: =F2 -> Winter | J2: =G2 -> Spring/Autumn | K2: =H2 -> Summer
E3: Total | F3: =SUM(F10:F177) -> 264.36175 | G3: =SUM(G10:G177) -> 144.12342 | H3: =SUM(H10:H177) -> 25.39545 | I3: =SUM(I10:I177) -> 634468.2 | J3: =SUM(J10:J177) -> 345896.22 | K3: =SUM(K10:K177) -> 60949.081
F4: (kW) | I4: (kW)
E5: Max | F5: =MAX(F10:F177) -> 3.4332695 | G5: =MAX(G10:G177) -> 1.8717328 | H5: =MAX(H10:H177) -> 0.32981104 | I5: =MAX(I10:I177) -> 8239.8468 | J5: =MAX(J10:J177) -> 4492.1587 | K5: =MAX(K10:K177) -> 791.54651
E6: Min | F6: =MIN(F10:F177) -> 0 | G6: =MIN(G10:G177) -> 0 | H6: =MIN(H10:H177) -> 0 | I6: =MIN(I10:I177) -> 0 | J6: =MIN(J10:J177) -> 0 | K6: =MIN(K10:K177) -> 0
E7: Average | F7: =AVERAGE(F10:F177) -> 1.5735819 | G7: =AVERAGE(G10:G177) -> 0.85787752 | H7: =AVERAGE(H10:H177) -> 0.1511634 | I7: =AVERAGE(I10:I177) -> 3776.5964 | J7: =AVERAGE(J10:J177) -> 2058.9061 | K7: =AVERAGE(K10:K177) -> 362.79215
E8: Data Centre Total Heat Released = Total Home Demand
E9: No of Homes | F9: 2400 | G9: =G8/G3 -> 0 | H9: =F9 -> 2400
B10: 1 | C10: Wednesday | D10: 0 | E10: weekday | F10: ='Daily Heat Demand Matrix (2)'!H6 -> 0 | G10: ='Daily Heat Demand Matrix (2)'!I6 -> 0 | H10: ='Daily Heat Demand Matrix (2)'!J6 -> 0 | I10: =F10*$F$9 -> 0 | J10: =G10*$F$9 -> 0 | K10: =H10*$F$9 -> 0
B11: 2 | C11: =C10 -> Wednesday | D11: 0.041666667 | E11: weekday | F11: ='Daily Heat Demand Matrix (2)'!H7 -> 0 | G11: ='Daily Heat Demand Matrix (2)'!I7 -> 0 | H11: ='Daily Heat Demand Matrix (2)'!J7 -> 0 | I11: =F11*$F$9 -> 0 | J11: =G11*$F$9 -> 0 | K11: =H11*$F$9 -> 0
B12: 3 | C12: =C11 -> Wednesday | D12: 0.083333333 | E12: weekday | F12: ='Daily Heat Demand Matrix (2)'!H8 -> 0 | G12: ='Daily Heat Demand Matrix (2)'!I8 -> 0 | H12: ='Daily Heat Demand Matrix (2)'!J8 -> 0 | I12: =F12*$F$9 -> 0 | J12: =G12*$F$9 -> 0 | K12: =H12*$F$9 -> 0
B13: 4 | C13: =C12 -> Wednesday | D13: 0.125 | E13: weekday | F13: ='Daily Heat Demand Matrix (2)'!H9 -> 0 | G13: ='Daily Heat Demand Matrix (2)'!I9 -> 0 | H13: ='Daily Heat Demand Matrix (2)'!J9 -> 0 | I13: =F13*$F$9 -> 0 | J13: =G13*$F$9 -> 0 | K13: =H13*$F$9 -> 0
B14: 5 | C14: =C13 -> Wednesday | D14: 0.16666667 | E14: weekday | F14: ='Daily Heat Demand Matrix (2)'!H10 -> 0 | G14: ='Daily Heat Demand Matrix (2)'!I10 -> 0 | H14: ='Daily Heat Demand Matrix (2)'!J10 -> 0 | I14: =F14*$F$9 -> 0 | J14: =G14*$F$9 -> 0 | K14: =H14*$F$9 -> 0
B15: 6 | C15: =C14 -> Wednesday | D15: 0.20833333 | E15: weekday | F15: ='Daily Heat Demand Matrix (2)'!H11 -> 0 | G15: ='Daily Heat Demand Matrix (2)'!I11 -> 0 | H15: ='Daily Heat Demand Matrix (2)'!J11 -> 0 | I15: =F15*$F$9 -> 0 | J15: =G15*$F$9 -> 0 | K15: =H15*$F$9 -> 0
B16: 7 | C16: =C15 -> Wednesday | D16: 0.25 | E16: weekday | F16: ='Daily Heat Demand Matrix (2)'!H12 -> 3.4332695 | G16: ='Daily Heat Demand Matrix (2)'!I12 -> 1.8717328 | H16: ='Daily Heat Demand Matrix (2)'!J12 -> 0.32981104 | I16: =F16*$F$9 -> 8239.8468 | J16: =G16*$F$9 -> 4492.1587 | K16: =H16*$F$9 -> 791.54651
B17: 8 | C17: =C16 -> Wednesday | D17: 0.29166667 | E17: weekday | F17: ='Daily Heat Demand Matrix (2)'!H13 -> 3.4332695 | G17: ='Daily Heat Demand Matrix (2)'!I13 -> 1.8717328 | H17: ='Daily Heat Demand Matrix (2)'!J13 -> 0.32981104 | I17: =F17*$F$9 -> 8239.8468 | J17: =G17*$F$9 -> 4492.1587 | K17: =H17*$F$9 -> 791.54651
B18: 9 | C18: =C17 -> Wednesday | D18: 0.33333333 | E18: weekday | F18: ='Daily Heat Demand Matrix (2)'!H14 -> 0 | G18: ='Daily Heat Demand Matrix (2)'!I14 -> 0 | H18: ='Daily Heat Demand Matrix (2)'!J14 -> 0 | I18: =F18*$F$9 -> 0 | J18: =G18*$F$9 -> 0 | K18: =H18*$F$9 -> 0
B19: 10 | C19: =C18 -> Wednesday | D19: 0.375 | E19: weekday | F19: ='Daily Heat Demand Matrix (2)'!H15 -> 0 | G19: ='Daily Heat Demand Matrix (2)'!I15 -> 0 | H19: ='Daily Heat Demand Matrix (2)'!J15 -> 0 | I19: =F19*$F$9 -> 0 | J19: =G19*$F$9 -> 0 | K19: =H19*$F$9 -> 0
B20: 11 | C20: =C19 -> Wednesday | D20: 0.41666667 | E20: weekday | F20: ='Daily Heat Demand Matrix (2)'!H16 -> 0 | G20: ='Daily Heat Demand Matrix (2)'!I16 -> 0 | H20: ='Daily Heat Demand Matrix (2)'!J16 -> 0 | I20: =F20*$F$9 -> 0 | J20: =G20*$F$9 -> 0 | K20: =H20*$F$9 -> 0
B21: 12 | C21: =C20 -> Wednesday | D21: 0.45833333 | E21: weekday | F21: ='Daily Heat Demand Matrix (2)'!H17 -> 0 | G21: ='Daily Heat Demand Matrix (2)'!I17 -> 0 | H21: ='Daily Heat Demand Matrix (2)'!J17 -> 0 | I21: =F21*$F$9 -> 0 | J21: =G21*$F$9 -> 0 | K21: =H21*$F$9 -> 0
B22: 13 | C22: =C21 -> Wednesday | D22: 0.5 | E22: weekday | F22: ='Daily Heat Demand Matrix (2)'!H18 -> 0 | G22: ='Daily Heat Demand Matrix (2)'!I18 -> 0 | H22: ='Daily Heat Demand Matrix (2)'!J18 -> 0 | I22: =F22*$F$9 -> 0 | J22: =G22*$F$9 -> 0 | K22: =H22*$F$9 -> 0
... B33: 24 | C33: =C32 -> Wednesday | D33: 0.95833333 | E33: weekday | F33: ='Daily Heat Demand Matrix (2)'!H29 -> 0 | G33: ='Daily Heat Demand Matrix (2)'!I29 -> 0 | H33: ='Daily Heat Demand Matrix (2)'!J29 -> 0 | I33: =F33*$F$9 -> 0 | J33: =G33*$F$9 -> 0 | K33: =H33*$F$9 -> 0
B34: 25 | C34: Thursday | D34: 1 | E34: weekday | F34: =F10 -> 0 | G34: =G10 -> 0 | H34: =H10 -> 0 | I34: =F34*$F$9 -> 0 | J34: =G34*$F$9 -> 0 | K34: =H34*$F$9 -> 0
B35: 26 | C35: =C34 -> Thursday | D35: 1.0416667 | E35: weekday | F35: =F11 -> 0 | G35: =G11 -> 0 | H35: =H11 -> 0 | I35: =F35*$F$9 -> 0 | J35: =G35*$F$9 -> 0 | K35: =H35*$F$9 -> 0
B36: 27 | C36: =C35 -> Thursday | D36: 1.0833333 | E36: weekday | F36: =F12 -> 0 | G36: =G12 -> 0 | H36: =H12 -> 0 | I36: =F36*$F$9 -> 0 | J36: =G36*$F$9 -> 0 | K36: =H36*$F$9 -> 0
B37: 28 | C37: =C36 -> Thursday | D37: 1.125 | E37: weekday | F37: =F13 -> 0 | G37: =G13 -> 0 | H37: =H13 -> 0 | I37: =F37*$F$9 -> 0 | J37: =G37*$F$9 -> 0 | K37: =H37*$F$9 -> 0
B38: 29 | C38: =C37 -> Thursday | D38: 1.1666667 | E38: weekday | F38: =F14 -> 0 | G38: =G14 -> 0 | H38: =H14 -> 0 | I38: =F38*$F$9 -> 0 | J38: =G38*$F$9 -> 0 | K38: =H38*$F$9 -> 0
B39: 30 | C39: =C38 -> Thursday | D39: 1.2083333 | E39: weekday | F39: =F15 -> 0 | G39: =G15 -> 0 | H39: =H15 -> 0 | I39: =F39*$F$9 -> 0 | J39: =G39*$F$9 -> 0 | K39: =H39*$F$9 -> 0
B40: 31 | C40: =C39 -> Thursday | D40: 1.25 | E40: weekday | F40: =F16 -> 3.4332695 | G40: =G16 -> 1.8717328 | H40: =H16 -> 0.32981104 | I40: =F40*$F$9 -> 8239.8468 | J40: =G40*$F$9 -> 4492.1587 | K40: =H40*$F$9 -> 791.54651
B41: 32 | C41: =C40 -> Thursday | D41: 1.2916667 | E41: weekday | F41: =F17 -> 3.4332695 | G41: =G17 -> 1.8717328 | H41: =H17 -> 0.32981104 | I41: =F41*$F$9 -> 8239.8468 | J41: =G41*$F$9 -> 4492.1587 | K41: =H41*$F$9 -> 791.54651
B42: 33 | C42: =C41 -> Thursday | D42: 1.3333333 | E42: weekday | F42: =F18 -> 0 | G42: =G18 -> 0 | H42: =H18 -> 0 | I42: =F42*$F$9 -> 0 | J42: =G42*$F$9 -> 0 | K42: =H42*$F$9 -> 0
B43: 34 | C43: =C42 -> Thursday | D43: 1.375 | E43: weekday | F43: =F19 -> 0 | G43: =G19 -> 0 | H43: =H19 -> 0 | I43: =F43*$F$9 -> 0 | J43: =G43*$F$9 -> 0 | K43: =H43*$F$9 -> 0
B44: 35 | C44: =C43 -> Thursday | D44: 1.4166667 | E44: weekday | F44: =F20 -> 0 | G44: =G20 -> 0 | H44: =H20 -> 0 | I44: =F44*$F$9 -> 0 | J44: =G44*$F$9 -> 0 | K44: =H44*$F$9 -> 0
B45: 36 | C45: =C44 -> Thursday | D45: 1.4583333 | E45: weekday | F45: =F21 -> 0 | G45: =G21 -> 0 | H45: =H21 -> 0 | I45: =F45*$F$9 -> 0 | J45: =G45*$F$9 -> 0 | K45: =H45*$F$9 -> 0
