Workbook

Sheet Properties
A2: Refrigerant | C2: R32
A3: Data source | C3: tlk-energy.de pressure-enthalpy
A4: Compressor Efficiency | C4: 0.7 | D4: ref: Star
A5: Superheating | B5: K | C5: 6
A6: Subcooling | B6: K | C6: 5
A7: T0 | B7: K | C7: 273
A8: Tevap, h | B8: ºC | C8: 17 | D8: =C8+273 -> 290 | E8: K
A9: Tevap, c | B9: ºC | C9: 7 | D9: =C9+273 -> 280 | E9: K
C12: Hot (h) | G12: Cold (c)
B13: Rating Condition | C13: W20W35 | F13: W10W35
C14: Winter | D14: Spring/autumn | E14: Summer | F14: =C14 -> Winter | G14: =D14 -> Spring/autumn | H14: =E14 -> Summer
A15: h1 | B15: kJ/kg | C15: 525.4 | D15: 525.4 | E15: 525.4 | F15: 524 | G15: 524 | H15: 524
A16: h2,act | B16: kJ/kg | C16: 559.6 | D16: =C16 -> 559.6 | E16: =D16 -> 559.6 | F16: 576.7 | G16: 576.7 | H16: 576.7
A17: h2 | B17: kJ/kg
A18: h3 | B18: kJ/kg | C18: 265.1 | D18: 265.1 | E18: 265.1 | F18: 265.1 | G18: 265.1 | H18: 265.1
A19: h4 | B19: kJ/kg | C19: 265.1 | D19: 265.1 | E19: 265.1 | F19: 265.1 | G19: 265.1 | H19: 265.1
A20: s1 | B20: J/kg.K | C20: 2122.4 | D20: 2122.4 | E20: 2122.4 | F20: 2156.2 | G20: 2156.2 | H20: 2156.2
A21: s2,act | B21: J/kg.K | C21: 2152.7 | D21: 2152.7 | E21: 2152.7 | F21: 2201.3 | G21: 2201.3 | H21: 2201.3
A22: s2 | B22: J/kg.K
A23: s3 | B23: J/kg.K | C23: 1218.1 | D23: 1218.1 | E23: 1218.1 | F23: 1218.1 | G23: 1218.1 | H23: 1218.1
A24: s4 | B24: J/kg.K | C24: 1225.6 | D24: 1225.6 | E24: 1225.6 | F24: 1232.2 | G24: 1232.2 | H24: 1232.2
D40: Expansion Valve | E40: Compressor | F40: Evaporator | G40: Proportion
C41: Winter
C42: Hot leg | D42: =Winter!E8 -> 0.049875809 | E42: =Winter!F8 -> 0.20149827 | F42: =Winter!G8 -> 0.74862592 | G42: =Winter!H8 -> 0.88490494
C43: Cold leg | D43: =Winter!K8 -> 0.13145574 | E43: =Winter!L8 -> 0.42047189 | F43: =Winter!M8 -> 0.44807237 | G43: =Winter!N8 -> 0.11509506
C44: Spring/autumn
C45: =C42 -> Hot leg | D45: ='Spring Autumn'!E8 -> 0.049875809 | E45: ='Spring Autumn'!F8 -> 0.20149827 | F45: ='Spring Autumn'!G8 -> 0.74862592 | G45: ='Spring Autumn'!H8 -> 0.78223593
C46: =C43 -> Cold leg | D46: ='Spring Autumn'!K8 -> 0.13145574 | E46: ='Spring Autumn'!L8 -> 0.42047189 | F46: ='Spring Autumn'!M8 -> 0.44807237 | G46: ='Spring Autumn'!N8 -> 0.21776407
C47: Summer
C48: =C45 -> Hot leg | D48: =IFERROR(Summer!E8, 0) -> 0 | E48: =IFERROR(Summer!F8, 0) -> 0 | F48: =IFERROR(Summer!G8, 0) -> 0 | G48: =IFERROR(Summer!H8, 0) -> 0
C49: =C46 -> Cold leg | D49: =Summer!K8 -> 0.13145574 | E49: =Summer!L8 -> 0.42047189 | F49: =Summer!M8 -> 0.44807237 | G49: =Summer!N8 -> 1

Sheet Winter
C2: Winter
C3: Hot Sink | I3: Cold Sink
C4: W20W35 | I4: W10W35
C5: Evap Duty | D5: Refrig mass flow rate | E5: Exergy Destruction | I5: Evap Duty | J5: Refrig mass flow rate | K5: Exergy Destruction
C6: Qevap,h | D6: ṁ ref | E6: Expansion Valve | F6: Compressor | G6: Evaporator | H6: Total | I6: Qevap,c | J6: ṁ ref | K6: Expansion Valve | L6: Compressor | M6: Evaporator | N6: Total | O6: Total
B7: Total | C7: =SUM(C10:C681) -> 1909081 | E7: =SUM(E10:E681) -> 15016.686 | F7: =SUM(F10:F681) -> 60667.41 | G7: =SUM(G10:G681) -> 225397.45 | H7: =SUM(H10:H681) -> 301081.54 | I7: =SUM(I10:I681) -> 346237.44 | K7: =SUM(K10:K681) -> 5147.8246 | L7: =SUM(L10:L681) -> 16465.737 | M7: =SUM(M10:M681) -> 17546.575 | N7: =SUM(N10:N681) -> 39160.137 | O7: =SUM(O10:O681) -> 340241.68
E8: =E7/$H$7 -> 0.049875809 | F8: =F7/$H$7 -> 0.20149827 | G8: =G7/$H$7 -> 0.74862592 | H8: =H7/O7 -> 0.88490494 | K8: =K7/$N$7 -> 0.13145574 | L8: =L7/$N$7 -> 0.42047189 | M8: =M7/$N$7 -> 0.44807237 | N8: =N7/O7 -> 0.11509506
B9: Hours | C9: kW | D9: kg/s | E9: kW | F9: kW | G9: kW | H9: kW | I9: kW | J9: kg/s | K9: kW | L9: kW | M9: kW | N9: kW | O9: kW
B10: 1 | C10: 0 | D10: =C10/(Properties!$C$15-Properties!$C$19) -> 0 | E10: =D10*Properties!$C$7*(Properties!$C$24-Properties!$C$23)/1000 -> 0 | F10: =D10*Properties!$C$7*(Properties!$C$21-Properties!$C$20)/1000 -> 0 | G10: =D10*((Properties!$C$15-Properties!$C$19)-Properties!$C$7*(Properties!$C$20-Properties!$C$24)/1000)+Winter!C10*(1-Properties!$C$7/Properties!$D$8) -> 0 | H10: =SUM(E10:G10) -> 0 | I10: 0 | J10: =I10/(Properties!$F$15-Properties!$F$19) -> 0 | K10: =J10*Properties!$C$7*(Properties!$F$24-Properties!$F$23)/1000 -> 0 | L10: =J10*Properties!$C$7*(Properties!$F$21-Properties!$F$20)/1000 -> 0 | M10: =J10*((Properties!$F$15-Properties!$F$19)-Properties!$C$7*(Properties!$F$20-Properties!$F$24)/1000)+Winter!I10*(1-Properties!$C$7/Properties!$D$9) -> 0 | N10: =SUM(K10:M10) -> 0 | O10: =N10+H10 -> 0
B11: 2 | C11: 0 | D11: =C11/(Properties!$C$15-Properties!$C$19) -> 0 | E11: =D11*Properties!$C$7*(Properties!$C$24-Properties!$C$23)/1000 -> 0 | F11: =D11*Properties!$C$7*(Properties!$C$21-Properties!$C$20)/1000 -> 0 | G11: =D11*((Properties!$C$15-Properties!$C$19)-Properties!$C$7*(Properties!$C$20-Properties!$C$24)/1000)+Winter!C11*(1-Properties!$C$7/Properties!$D$8) -> 0 | H11: =SUM(E11:G11) -> 0 | I11: 0 | J11: =I11/(Properties!$F$15-Properties!$F$19) -> 0 | K11: =J11*Properties!$C$7*(Properties!$F$24-Properties!$F$23)/1000 -> 0 | L11: =J11*Properties!$C$7*(Properties!$F$21-Properties!$F$20)/1000 -> 0 | M11: =J11*((Properties!$F$15-Properties!$F$19)-Properties!$C$7*(Properties!$F$20-Properties!$F$24)/1000)+Winter!I11*(1-Properties!$C$7/Properties!$D$9) -> 0 | N11: =SUM(K11:M11) -> 0 | O11: =N11+H11 -> 0
B12: 3 | C12: 0 | D12: =C12/(Properties!$C$15-Properties!$C$19) -> 0 | E12: =D12*Properties!$C$7*(Properties!$C$24-Properties!$C$23)/1000 -> 0 | F12: =D12*Properties!$C$7*(Properties!$C$21-Properties!$C$20)/1000 -> 0 | G12: =D12*((Properties!$C$15-Properties!$C$19)-Properties!$C$7*(Properties!$C$20-Properties!$C$24)/1000)+Winter!C12*(1-Properties!$C$7/Properties!$D$8) -> 0 | H12: =SUM(E12:G12) -> 0 | I12: 0 | J12: =I12/(Properties!$F$15-Properties!$F$19) -> 0 | K12: =J12*Properties!$C$7*(Properties!$F$24-Properties!$F$23)/1000 -> 0 | L12: =J12*Properties!$C$7*(Properties!$F$21-Properties!$F$20)/1000 -> 0 | M12: =J12*((Properties!$F$15-Properties!$F$19)-Properties!$C$7*(Properties!$F$20-Properties!$F$24)/1000)+Winter!I12*(1-Properties!$C$7/Properties!$D$9) -> 0 | N12: =SUM(K12:M12) -> 0 | O12: =N12+H12 -> 0
B13: 4 | C13: 0 | D13: =C13/(Properties!$C$15-Properties!$C$19) -> 0 | E13: =D13*Properties!$C$7*(Properties!$C$24-Properties!$C$23)/1000 -> 0 | F13: =D13*Properties!$C$7*(Properties!$C$21-Properties!$C$20)/1000 -> 0 | G13: =D13*((Properties!$C$15-Properties!$C$19)-Properties!$C$7*(Properties!$C$20-Properties!$C$24)/1000)+Winter!C13*(1-Properties!$C$7/Properties!$D$8) -> 0 | H13: =SUM(E13:G13) -> 0 | I13: 0 | J13: =I13/(Properties!$F$15-Properties!$F$19) -> 0 | K13: =J13*Properties!$C$7*(Properties!$F$24-Properties!$F$23)/1000 -> 0 | L13: =J13*Properties!$C$7*(Properties!$F$21-Properties!$F$20)/1000 -> 0 | M13: =J13*((Properties!$F$15-Properties!$F$19)-Properties!$C$7*(Properties!$F$20-Properties!$F$24)/1000)+Winter!I13*(1-Properties!$C$7/Properties!$D$9) -> 0 | N13: =SUM(K13:M13) -> 0 | O13: =N13+H13 -> 0
B14: 5 | C14: 0 | D14: =C14/(Properties!$C$15-Properties!$C$19) -> 0 | E14: =D14*Properties!$C$7*(Properties!$C$24-Properties!$C$23)/1000 -> 0 | F14: =D14*Properties!$C$7*(Properties!$C$21-Properties!$C$20)/1000 -> 0 | G14: =D14*((Properties!$C$15-Properties!$C$19)-Properties!$C$7*(Properties!$C$20-Properties!$C$24)/1000)+Winter!C14*(1-Properties!$C$7/Properties!$D$8) -> 0 | H14: =SUM(E14:G14) -> 0 | I14: 0 | J14: =I14/(Properties!$F$15-Properties!$F$19) -> 0 | K14: =J14*Properties!$C$7*(Properties!$F$24-Properties!$F$23)/1000 -> 0 | L14: =J14*Properties!$C$7*(Properties!$F$21-Properties!$F$20)/1000 -> 0 | M14: =J14*((Properties!$F$15-Properties!$F$19)-Properties!$C$7*(Properties!$F$20-Properties!$F$24)/1000)+Winter!I14*(1-Properties!$C$7/Properties!$D$9) -> 0 | N14: =SUM(K14:M14) -> 0 | O14: =N14+H14 -> 0
B15: 6 | C15: 0 | D15: =C15/(Properties!$C$15-Properties!$C$19) -> 0 | E15: =D15*Properties!$C$7*(Properties!$C$24-Properties!$C$23)/1000 -> 0 | F15: =D15*Properties!$C$7*(Properties!$C$21-Properties!$C$20)/1000 -> 0 | G15: =D15*((Properties!$C$15-Properties!$C$19)-Properties!$C$7*(Properties!$C$20-Properties!$C$24)/1000)+Winter!C15*(1-Properties!$C$7/Properties!$D$8) -> 0 | H15: =SUM(E15:G15) -> 0 | I15: 0 | J15: =I15/(Properties!$F$15-Properties!$F$19) -> 0 | K15: =J15*Properties!$C$7*(Properties!$F$24-Properties!$F$23)/1000 -> 0 | L15: =J15*Properties!$C$7*(Properties!$F$21-Properties!$F$20)/1000 -> 0 | M15: =J15*((Properties!$F$15-Properties!$F$19)-Properties!$C$7*(Properties!$F$20-Properties!$F$24)/1000)+Winter!I15*(1-Properties!$C$7/Properties!$D$9) -> 0 | N15: =SUM(K15:M15) -> 0 | O15: =N15+H15 -> 0
B16: 7 | C16: 6195.2581 | D16: =C16/(Properties!$C$15-Properties!$C$19) -> 23.800454 | E16: =D16*Properties!$C$7*(Properties!$C$24-Properties!$C$23)/1000 -> 48.731429 | F16: =D16*Properties!$C$7*(Properties!$C$21-Properties!$C$20)/1000 -> 196.87497 | G16: =D16*((Properties!$C$15-Properties!$C$19)-Properties!$C$7*(Properties!$C$20-Properties!$C$24)/1000)+Winter!C16*(1-Properties!$C$7/Properties!$D$8) -> 731.449 | H16: =SUM(E16:G16) -> 977.05541 | I16: 1127.2042 | J16: =I16/(Properties!$F$15-Properties!$F$19) -> 4.3538209 | K16: =J16*Properties!$C$7*(Properties!$F$24-Properties!$F$23)/1000 -> 16.759163 | L16: =J16*Properties!$C$7*(Properties!$F$21-Properties!$F$20)/1000 -> 53.605549 | M16: =J16*((Properties!$F$15-Properties!$F$19)-Properties!$C$7*(Properties!$F$20-Properties!$F$24)/1000)+Winter!I16*(1-Properties!$C$7/Properties!$D$9) -> 57.124307 | N16: =SUM(K16:M16) -> 127.48902 | O16: =N16+H16 -> 1104.5444
B17: 8 | C17: 6196.777 | D17: =C17/(Properties!$C$15-Properties!$C$19) -> 23.806289 | E17: =D17*Properties!$C$7*(Properties!$C$24-Properties!$C$23)/1000 -> 48.743376 | F17: =D17*Properties!$C$7*(Properties!$C$21-Properties!$C$20)/1000 -> 196.92324 | G17: =D17*((Properties!$C$15-Properties!$C$19)-Properties!$C$7*(Properties!$C$20-Properties!$C$24)/1000)+Winter!C17*(1-Properties!$C$7/Properties!$D$8) -> 731.62833 | H17: =SUM(E17:G17) -> 977.29495 | I17: 1125.6854 | J17: =I17/(Properties!$F$15-Properties!$F$19) -> 4.3479543 | K17: =J17*Properties!$C$7*(Properties!$F$24-Properties!$F$23)/1000 -> 16.73658 | L17: =J17*Properties!$C$7*(Properties!$F$21-Properties!$F$20)/1000 -> 53.533317 | M17: =J17*((Properties!$F$15-Properties!$F$19)-Properties!$C$7*(Properties!$F$20-Properties!$F$24)/1000)+Winter!I17*(1-Properties!$C$7/Properties!$D$9) -> 57.047334 | N17: =SUM(K17:M17) -> 127.31723 | O17: =N17+H17 -> 1104.6122 | Q17: Specific Exergy Destruction
B18: 9 | C18: 0 | D18: =C18/(Properties!$C$15-Properties!$C$19) -> 0 | E18: =D18*Properties!$C$7*(Properties!$C$24-Properties!$C$23)/1000 -> 0 | F18: =D18*Properties!$C$7*(Properties!$C$21-Properties!$C$20)/1000 -> 0 | G18: =D18*((Properties!$C$15-Properties!$C$19)-Properties!$C$7*(Properties!$C$20-Properties!$C$24)/1000)+Winter!C18*(1-Properties!$C$7/Properties!$D$8) -> 0 | H18: =SUM(E18:G18) -> 0 | I18: 0 | J18: =I18/(Properties!$F$15-Properties!$F$19) -> 0 | K18: =J18*Properties!$C$7*(Properties!$F$24-Properties!$F$23)/1000 -> 0 | L18: =J18*Properties!$C$7*(Properties!$F$21-Properties!$F$20)/1000 -> 0 | M18: =J18*((Properties!$F$15-Properties!$F$19)-Properties!$C$7*(Properties!$F$20-Properties!$F$24)/1000)+Winter!I18*(1-Properties!$C$7/Properties!$D$9) -> 0 | N18: =SUM(K18:M18) -> 0 | O18: =N18+H18 -> 0 | P18: Hot | Q18: =H7/C7 -> 0.1577102
B19: 10 | C19: 0 | D19: =C19/(Properties!$C$15-Properties!$C$19) -> 0 | E19: =D19*Properties!$C$7*(Properties!$C$24-Properties!$C$23)/1000 -> 0 | F19: =D19*Properties!$C$7*(Properties!$C$21-Properties!$C$20)/1000 -> 0 | G19: =D19*((Properties!$C$15-Properties!$C$19)-Properties!$C$7*(Properties!$C$20-Properties!$C$24)/1000)+Winter!C19*(1-Properties!$C$7/Properties!$D$8) -> 0 | H19: =SUM(E19:G19) -> 0 | I19: 0 | J19: =I19/(Properties!$F$15-Properties!$F$19) -> 0 | K19: =J19*Properties!$C$7*(Properties!$F$24-Properties!$F$23)/1000 -> 0 | L19: =J19*Properties!$C$7*(Properties!$F$21-Properties!$F$20)/1000 -> 0 | M19: =J19*((Properties!$F$15-Properties!$F$19)-Properties!$C$7*(Properties!$F$20-Properties!$F$24)/1000)+Winter!I19*(1-Properties!$C$7/Properties!$D$9) -> 0 | N19: =SUM(K19:M19) -> 0 | O19: =N19+H19 -> 0 | P19: Cold | Q19: =N7/I7 -> 0.11310197
B20: 11 | C20: 0 | D20: =C20/(Properties!$C$15-Properties!$C$19) -> 0 | E20: =D20*Properties!$C$7*(Properties!$C$24-Properties!$C$23)/1000 -> 0 | F20: =D20*Properties!$C$7*(Properties!$C$21-Properties!$C$20)/1000 -> 0 | G20: =D20*((Properties!$C$15-Properties!$C$19)-Properties!$C$7*(Properties!$C$20-Properties!$C$24)/1000)+Winter!C20*(1-Properties!$C$7/Properties!$D$8) -> 0 | H20: =SUM(E20:G20) -> 0 | I20: 0 | J20: =I20/(Properties!$F$15-Properties!$F$19) -> 0 | K20: =J20*Properties!$C$7*(Properties!$F$24-Properties!$F$23)/1000 -> 0 | L20: =J20*Properties!$C$7*(Properties!$F$21-Properties!$F$20)/1000 -> 0 | M20: =J20*((Properties!$F$15-Properties!$F$19)-Properties!$C$7*(Properties!$F$20-Properties!$F$24)/1000)+Winter!I20*(1-Properties!$C$7/Properties!$D$9) -> 0 | N20: =SUM(K20:M20) -> 0 | O20: =N20+H20 -> 0
B21: 12 | C21: 0 | D21: =C21/(Properties!$C$15-Properties!$C$19) -> 0 | E21: =D21*Properties!$C$7*(Properties!$C$24-Properties!$C$23)/1000 -> 0 | F21: =D21*Properties!$C$7*(Properties!$C$21-Properties!$C$20)/1000 -> 0 | G21: =D21*((Properties!$C$15-Properties!$C$19)-Properties!$C$7*(Properties!$C$20-Properties!$C$24)/1000)+Winter!C21*(1-Properties!$C$7/Properties!$D$8) -> 0 | H21: =SUM(E21:G21) -> 0 | I21: 0 | J21: =I21/(Properties!$F$15-Properties!$F$19) -> 0 | K21: =J21*Properties!$C$7*(Properties!$F$24-Properties!$F$23)/1000 -> 0 | L21: =J21*Properties!$C$7*(Properties!$F$21-Properties!$F$20)/1000 -> 0 | M21: =J21*((Properties!$F$15-Properties!$F$19)-Properties!$C$7*(Properties!$F$20-Properties!$F$24)/1000)+Winter!I21*(1-Properties!$C$7/Properties!$D$9) -> 0 | N21: =SUM(K21:M21) -> 0 | O21: =N21+H21 -> 0
B22: 13 | C22: 0 | D22: =C22/(Properties!$C$15-Properties!$C$19) -> 0 | E22: =D22*Properties!$C$7*(Properties!$C$24-Properties!$C$23)/1000 -> 0 | F22: =D22*Properties!$C$7*(Properties!$C$21-Properties!$C$20)/1000 -> 0 | G22: =D22*((Properties!$C$15-Properties!$C$19)-Properties!$C$7*(Properties!$C$20-Properties!$C$24)/1000)+Winter!C22*(1-Properties!$C$7/Properties!$D$8) -> 0 | H22: =SUM(E22:G22) -> 0 | I22: 0 | J22: =I22/(Properties!$F$15-Properties!$F$19) -> 0 | K22: =J22*Properties!$C$7*(Properties!$F$24-Properties!$F$23)/1000 -> 0 | L22: =J22*Properties!$C$7*(Properties!$F$21-Properties!$F$20)/1000 -> 0 | M22: =J22*((Properties!$F$15-Properties!$F$19)-Properties!$C$7*(Properties!$F$20-Properties!$F$24)/1000)+Winter!I22*(1-Properties!$C$7/Properties!$D$9) -> 0 | N22: =SUM(K22:M22) -> 0 | O22: =N22+H22 -> 0
B23: 14 | C23: 0 | D23: =C23/(Properties!$C$15-Properties!$C$19) -> 0 | E23: =D23*Properties!$C$7*(Properties!$C$24-Properties!$C$23)/1000 -> 0 | F23: =D23*Properties!$C$7*(Properties!$C$21-Properties!$C$20)/1000 -> 0 | G23: =D23*((Properties!$C$15-Properties!$C$19)-Properties!$C$7*(Properties!$C$20-Properties!$C$24)/1000)+Winter!C23*(1-Properties!$C$7/Properties!$D$8) -> 0 | H23: =SUM(E23:G23) -> 0 | I23: 0 | J23: =I23/(Properties!$F$15-Properties!$F$19) -> 0 | K23: =J23*Properties!$C$7*(Properties!$F$24-Properties!$F$23)/1000 -> 0 | L23: =J23*Properties!$C$7*(Properties!$F$21-Properties!$F$20)/1000 -> 0 | M23: =J23*((Properties!$F$15-Properties!$F$19)-Properties!$C$7*(Properties!$F$20-Properties!$F$24)/1000)+Winter!I23*(1-Properties!$C$7/Properties!$D$9) -> 0 | N23: =SUM(K23:M23) -> 0 | O23: =N23+H23 -> 0
B24: 15 | C24: 0 | D24: =C24/(Properties!$C$15-Properties!$C$19) -> 0 | E24: =D24*Properties!$C$7*(Properties!$C$24-Properties!$C$23)/1000 -> 0 | F24: =D24*Properties!$C$7*(Properties!$C$21-Properties!$C$20)/1000 -> 0 | G24: =D24*((Properties!$C$15-Properties!$C$19)-Properties!$C$7*(Properties!$C$20-Properties!$C$24)/1000)+Winter!C24*(1-Properties!$C$7/Properties!$D$8) -> 0 | H24: =SUM(E24:G24) -> 0 | I24: 0 | J24: =I24/(Properties!$F$15-Properties!$F$19) -> 0 | K24: =J24*Properties!$C$7*(Properties!$F$24-Properties!$F$23)/1000 -> 0 | L24: =J24*Properties!$C$7*(Properties!$F$21-Properties!$F$20)/1000 -> 0 | M24: =J24*((Properties!$F$15-Properties!$F$19)-Properties!$C$7*(Properties!$F$20-Properties!$F$24)/1000)+Winter!I24*(1-Properties!$C$7/Properties!$D$9) -> 0 | N24: =SUM(K24:M24) -> 0 | O24: =N24+H24 -> 0
B25: 16 | C25: 6190.7174 | D25: =C25/(Properties!$C$15-Properties!$C$19) -> 23.78301 | E25: =D25*Properties!$C$7*(Properties!$C$24-Properties!$C$23)/1000 -> 48.695712 | F25: =D25*Properties!$C$7*(Properties!$C$21-Properties!$C$20)/1000 -> 196.73068 | G25: =D25*((Properties!$C$15-Properties!$C$19)-Properties!$C$7*(Properties!$C$20-Properties!$C$24)/1000)+Winter!C25*(1-Properties!$C$7/Properties!$D$8) -> 730.9129 | H25: =SUM(E25:G25) -> 976.33929 | I25: 1131.7449 | J25: =I25/(Properties!$F$15-Properties!$F$19) -> 4.3713594 | K25: =J25*Properties!$C$7*(Properties!$F$24-Properties!$F$23)/1000 -> 16.826674 | L25: =J25*Properties!$C$7*(Properties!$F$21-Properties!$F$20)/1000 -> 53.821488 | M25: =J25*((Properties!$F$15-Properties!$F$19)-Properties!$C$7*(Properties!$F$20-Properties!$F$24)/1000)+Winter!I25*(1-Properties!$C$7/Properties!$D$9) -> 57.354421 | N25: =SUM(K25:M25) -> 128.00258 | O25: =N25+H25 -> 1104.3419
B26: 17 | C26: 6189.8846 | D26: =C26/(Properties!$C$15-Properties!$C$19) -> 23.77981 | E26: =D26*Properties!$C$7*(Properties!$C$24-Properties!$C$23)/1000 -> 48.689161 | F26: =D26*Properties!$C$7*(Properties!$C$21-Properties!$C$20)/1000 -> 196.70421 | G26: =D26*((Properties!$C$15-Properties!$C$19)-Properties!$C$7*(Properties!$C$20-Properties!$C$24)/1000)+Winter!C26*(1-Properties!$C$7/Properties!$D$8) -> 730.81457 | H26: =SUM(E26:G26) -> 976.20795 | I26: 1132.5778 | J26: =I26/(Properties!$F$15-Properties!$F$19) -> 4.3745761 | K26: =J26*Properties!$C$7*(Properties!$F$24-Properties!$F$23)/1000 -> 16.839056 | L26: =J26*Properties!$C$7*(Properties!$F$21-Properties!$F$20)/1000 -> 53.861094 | M26: =J26*((Properties!$F$15-Properties!$F$19)-Properties!$C$7*(Properties!$F$20-Properties!$F$24)/1000)+Winter!I26*(1-Properties!$C$7/Properties!$D$9) -> 57.396626 | N26: =SUM(K26:M26) -> 128.09678 | O26: =N26+H26 -> 1104.3047
B27: 18 | C27: 6188.6965 | D27: =C27/(Properties!$C$15-Properties!$C$19) -> 23.775246 | E27: =D27*Properties!$C$7*(Properties!$C$24-Properties!$C$23)/1000 -> 48.679816 | F27: =D27*Properties!$C$7*(Properties!$C$21-Properties!$C$20)/1000 -> 196.66646 | G27: =D27*((Properties!$C$15-Properties!$C$19)-Properties!$C$7*(Properties!$C$20-Properties!$C$24)/1000)+Winter!C27*(1-Properties!$C$7/Properties!$D$8) -> 730.6743 | H27: =SUM(E27:G27) -> 976.02057 | I27: 1133.7659 | J27: =I27/(Properties!$F$15-Properties!$F$19) -> 4.3791651 | K27: =J27*Properties!$C$7*(Properties!$F$24-Properties!$F$23)/1000 -> 16.85672 | L27: =J27*Properties!$C$7*(Properties!$F$21-Properties!$F$20)/1000 -> 53.917595 | M27: =J27*((Properties!$F$15-Properties!$F$19)-Properties!$C$7*(Properties!$F$20-Properties!$F$24)/1000)+Winter!I27*(1-Properties!$C$7/Properties!$D$9) -> 57.456836 | N27: =SUM(K27:M27) -> 128.23115 | O27: =N27+H27 -> 1104.2517
B28: 19 | C28: 6187.4206 | D28: =C28/(Properties!$C$15-Properties!$C$19) -> 23.770344 | E28: =D28*Properties!$C$7*(Properties!$C$24-Properties!$C$23)/1000 -> 48.66978 | F28: =D28*Properties!$C$7*(Properties!$C$21-Properties!$C$20)/1000 -> 196.62591 | G28: =D28*((Properties!$C$15-Properties!$C$19)-Properties!$C$7*(Properties!$C$20-Properties!$C$24)/1000)+Winter!C28*(1-Properties!$C$7/Properties!$D$8) -> 730.52366 | H28: =SUM(E28:G28) -> 975.81935 | I28: 1135.0418 | J28: =I28/(Properties!$F$15-Properties!$F$19) -> 4.3840933 | K28: =J28*Properties!$C$7*(Properties!$F$24-Properties!$F$23)/1000 -> 16.87569 | L28: =J28*Properties!$C$7*(Properties!$F$21-Properties!$F$20)/1000 -> 53.978272 | M28: =J28*((Properties!$F$15-Properties!$F$19)-Properties!$C$7*(Properties!$F$20-Properties!$F$24)/1000)+Winter!I28*(1-Properties!$C$7/Properties!$D$9) -> 57.521497 | N28: =SUM(K28:M28) -> 128.37546 | O28: =N28+H28 -> 1104.1948
B29: 20 | C29: 6186.1574 | D29: =C29/(Properties!$C$15-Properties!$C$19) -> 23.765491 | E29: =D29*Properties!$C$7*(Properties!$C$24-Properties!$C$23)/1000 -> 48.659843 | F29: =D29*Properties!$C$7*(Properties!$C$21-Properties!$C$20)/1000 -> 196.58577 | G29: =D29*((Properties!$C$15-Properties!$C$19)-Properties!$C$7*(Properties!$C$20-Properties!$C$24)/1000)+Winter!C29*(1-Properties!$C$7/Properties!$D$8) -> 730.37452 | H29: =SUM(E29:G29) -> 975.62013 | I29: 1136.3049 | J29: =I29/(Properties!$F$15-Properties!$F$19) -> 4.3889724 | K29: =J29*Properties!$C$7*(Properties!$F$24-Properties!$F$23)/1000 -> 16.894471 | L29: =J29*Properties!$C$7*(Properties!$F$21-Properties!$F$20)/1000 -> 54.038344 | M29: =J29*((Properties!$F$15-Properties!$F$19)-Properties!$C$7*(Properties!$F$20-Properties!$F$24)/1000)+Winter!I29*(1-Properties!$C$7/Properties!$D$9) -> 57.585512 | N29: =SUM(K29:M29) -> 128.51833 | O29: =N29+H29 -> 1104.1385
B30: 21 | C30: 6184.8066 | D30: =C30/(Properties!$C$15-Properties!$C$19) -> 23.760302 | E30: =D30*Properties!$C$7*(Properties!$C$24-Properties!$C$23)/1000 -> 48.649218 | F30: =D30*Properties!$C$7*(Properties!$C$21-Properties!$C$20)/1000 -> 196.54284 | G30: =D30*((Properties!$C$15-Properties!$C$19)-Properties!$C$7*(Properties!$C$20-Properties!$C$24)/1000)+Winter!C30*(1-Properties!$C$7/Properties!$D$8) -> 730.21504 | H30: =SUM(E30:G30) -> 975.4071 | I30: 1137.6557 | J30: =I30/(Properties!$F$15-Properties!$F$19) -> 4.3941897 | K30: =J30*Properties!$C$7*(Properties!$F$24-Properties!$F$23)/1000 -> 16.914555 | L30: =J30*Properties!$C$7*(Properties!$F$21-Properties!$F$20)/1000 -> 54.102582 | M30: =J30*((Properties!$F$15-Properties!$F$19)-Properties!$C$7*(Properties!$F$20-Properties!$F$24)/1000)+Winter!I30*(1-Properties!$C$7/Properties!$D$9) -> 57.653967 | N30: =SUM(K30:M30) -> 128.6711 | O30: =N30+H30 -> 1104.0782
B31: 22 | C31: 6183.6692 | D31: =C31/(Properties!$C$15-Properties!$C$19) -> 23.755933 | E31: =D31*Properties!$C$7*(Properties!$C$24-Properties!$C$23)/1000 -> 48.640272 | F31: =D31*Properties!$C$7*(Properties!$C$21-Properties!$C$20)/1000 -> 196.5067 | G31: =D31*((Properties!$C$15-Properties!$C$19)-Properties!$C$7*(Properties!$C$20-Properties!$C$24)/1000)+Winter!C31*(1-Properties!$C$7/Properties!$D$8) -> 730.08075 | H31: =SUM(E31:G31) -> 975.22772 | I31: 1138.7931 | J31: =I31/(Properties!$F$15-Properties!$F$19) -> 4.3985828 | K31: =J31*Properties!$C$7*(Properties!$F$24-Properties!$F$23)/1000 -> 16.931465 | L31: =J31*Properties!$C$7*(Properties!$F$21-Properties!$F$20)/1000 -> 54.156671 | M31: =J31*((Properties!$F$15-Properties!$F$19)-Properties!$C$7*(Properties!$F$20-Properties!$F$24)/1000)+Winter!I31*(1-Properties!$C$7/Properties!$D$9) -> 57.711606 | N31: =SUM(K31:M31) -> 128.79974 | O31: =N31+H31 -> 1104.0275
... B681: 672 | C681: 0 | D681: =C681/(Properties!$C$15-Properties!$C$19) -> 0 | E681: =D681*Properties!$C$7*(Properties!$C$24-Properties!$C$23)/1000 -> 0 | F681: =D681*Properties!$C$7*(Properties!$C$21-Properties!$C$20)/1000 -> 0 | G681: =D681*((Properties!$C$15-Properties!$C$19)-Properties!$C$7*(Properties!$C$20-Properties!$C$24)/1000)+Winter!C681*(1-Properties!$C$7/Properties!$D$8) -> 0 | H681: =SUM(E681:G681) -> 0 | I681: 0 | J681: =I681/(Properties!$F$15-Properties!$F$19) -> 0 | K681: =J681*Properties!$C$7*(Properties!$F$24-Properties!$F$23)/1000 -> 0 | L681: =J681*Properties!$C$7*(Properties!$F$21-Properties!$F$20)/1000 -> 0 | M681: =J681*((Properties!$F$15-Properties!$F$19)-Properties!$C$7*(Properties!$F$20-Properties!$F$24)/1000)+Winter!I681*(1-Properties!$C$7/Properties!$D$9) -> 0 | N681: =SUM(K681:M681) -> 0 | O681: =N681+H681 -> 0
I682: =SUM(I10:I681) -> 346237.44

Sheet Spring Autumn
C2: Spring/Autumn
C3: Hot Sink | I3: Cold Sink
C4: W20W35 | I4: W10W35
C5: Evap Duty | D5: Refrig mass flow rate | E5: Exergy Destruction | I5: Evap Duty | J5: Refrig mass flow rate | K5: Exergy Destruction
C6: Qevap,h | D6: ṁ ref | E6: Expansion Valve | F6: Compressor | G6: Evaporator | H6: Total | I6: Qevap,c | J6: ṁ ref | K6: Expansion Valve | L6: Compressor | M6: Evaporator | N6: Total | O6: Total
B7: Total | C7: =SUM(C10:C681) -> 879763.28 | E7: =SUM(E10:E681) -> 6920.151 | F7: =SUM(F10:F681) -> 27957.41 | G7: =SUM(G10:G681) -> 103870.08 | H7: =SUM(H10:H681) -> 138747.64 | I7: =SUM(I10:I681) -> 341510.38 | K7: =SUM(K10:K681) -> 5077.5431 | L7: =SUM(L10:L681) -> 16240.936 | M7: =SUM(M10:M681) -> 17307.018 | N7: =SUM(N10:N681) -> 38625.497 | O7: =SUM(O10:O681) -> 177373.14
E8: =E7/$H$7 -> 0.049875809 | F8: =F7/$H$7 -> 0.20149827 | G8: =G7/$H$7 -> 0.74862592 | H8: =H7/O7 -> 0.78223593 | K8: =K7/$N$7 -> 0.13145574 | L8: =L7/$N$7 -> 0.42047189 | M8: =M7/$N$7 -> 0.44807237 | N8: =N7/O7 -> 0.21776407
B9: Hours | C9: kW | D9: kg/s | E9: kW | F9: kW | G9: kW | H9: kW | I9: kW | J9: kg/s | K9: kW | L9: kW | M9: kW | N9: kW | O9: kW
B10: 1 | C10: 0 | D10: =C10/(Properties!$D$15-Properties!$D$19) -> 0 | E10: =D10*Properties!$C$7*(Properties!$D$24-Properties!$D$23)/1000 -> 0 | F10: =D10*Properties!$C$7*(Properties!$D$21-Properties!$D$20)/1000 -> 0 | G10: =D10*((Properties!$D$15-Properties!$D$19)-Properties!$C$7*(Properties!$D$20-Properties!$D$24)/1000)+'Spring Autumn'!C10*(1-Properties!$C$7/Properties!$D$8) -> 0 | H10: =SUM(E10:G10) -> 0 | I10: 0 | J10: =I10/(Properties!$G$15-Properties!$G$19) -> 0 | K10: =J10*Properties!$C$7*(Properties!$G$24-Properties!$G$23)/1000 -> 0 | L10: =J10*Properties!$C$7*(Properties!$G$21-Properties!$G$20)/1000 -> 0 | M10: =J10*((Properties!$G$15-Properties!$G$19)-Properties!$C$7*(Properties!$G$20-Properties!$G$24)/1000)+'Spring Autumn'!I10*(1-Properties!$C$7/Properties!$D$9) -> 0 | N10: =SUM(K10:M10) -> 0 | O10: =N10+H10 -> 0
B11: 2 | C11: 0 | D11: =C11/(Properties!$D$15-Properties!$D$19) -> 0 | E11: =D11*Properties!$C$7*(Properties!$D$24-Properties!$D$23)/1000 -> 0 | F11: =D11*Properties!$C$7*(Properties!$D$21-Properties!$D$20)/1000 -> 0 | G11: =D11*((Properties!$D$15-Properties!$D$19)-Properties!$C$7*(Properties!$D$20-Properties!$D$24)/1000)+'Spring Autumn'!C11*(1-Properties!$C$7/Properties!$D$8) -> 0 | H11: =SUM(E11:G11) -> 0 | I11: 0 | J11: =I11/(Properties!$G$15-Properties!$G$19) -> 0 | K11: =J11*Properties!$C$7*(Properties!$G$24-Properties!$G$23)/1000 -> 0 | L11: =J11*Properties!$C$7*(Properties!$G$21-Properties!$G$20)/1000 -> 0 | M11: =J11*((Properties!$G$15-Properties!$G$19)-Properties!$C$7*(Properties!$G$20-Properties!$G$24)/1000)+'Spring Autumn'!I11*(1-Properties!$C$7/Properties!$D$9) -> 0 | N11: =SUM(K11:M11) -> 0 | O11: =N11+H11 -> 0
B12: 3 | C12: 0 | D12: =C12/(Properties!$D$15-Properties!$D$19) -> 0 | E12: =D12*Properties!$C$7*(Properties!$D$24-Properties!$D$23)/1000 -> 0 | F12: =D12*Properties!$C$7*(Properties!$D$21-Properties!$D$20)/1000 -> 0 | G12: =D12*((Properties!$D$15-Properties!$D$19)-Properties!$C$7*(Properties!$D$20-Properties!$D$24)/1000)+'Spring Autumn'!C12*(1-Properties!$C$7/Properties!$D$8) -> 0 | H12: =SUM(E12:G12) -> 0 | I12: 0 | J12: =I12/(Properties!$G$15-Properties!$G$19) -> 0 | K12: =J12*Properties!$C$7*(Properties!$G$24-Properties!$G$23)/1000 -> 0 | L12: =J12*Properties!$C$7*(Properties!$G$21-Properties!$G$20)/1000 -> 0 | M12: =J12*((Properties!$G$15-Properties!$G$19)-Properties!$C$7*(Properties!$G$20-Properties!$G$24)/1000)+'Spring Autumn'!I12*(1-Properties!$C$7/Properties!$D$9) -> 0 | N12: =SUM(K12:M12) -> 0 | O12: =N12+H12 -> 0
B13: 4 | C13: 0 | D13: =C13/(Properties!$D$15-Properties!$D$19) -> 0 | E13: =D13*Properties!$C$7*(Properties!$D$24-Properties!$D$23)/1000 -> 0 | F13: =D13*Properties!$C$7*(Properties!$D$21-Properties!$D$20)/1000 -> 0 | G13: =D13*((Properties!$D$15-Properties!$D$19)-Properties!$C$7*(Properties!$D$20-Properties!$D$24)/1000)+'Spring Autumn'!C13*(1-Properties!$C$7/Properties!$D$8) -> 0 | H13: =SUM(E13:G13) -> 0 | I13: 0 | J13: =I13/(Properties!$G$15-Properties!$G$19) -> 0 | K13: =J13*Properties!$C$7*(Properties!$G$24-Properties!$G$23)/1000 -> 0 | L13: =J13*Properties!$C$7*(Properties!$G$21-Properties!$G$20)/1000 -> 0 | M13: =J13*((Properties!$G$15-Properties!$G$19)-Properties!$C$7*(Properties!$G$20-Properties!$G$24)/1000)+'Spring Autumn'!I13*(1-Properties!$C$7/Properties!$D$9) -> 0 | N13: =SUM(K13:M13) -> 0 | O13: =N13+H13 -> 0
B14: 5 | C14: 0 | D14: =C14/(Properties!$D$15-Properties!$D$19) -> 0 | E14: =D14*Properties!$C$7*(Properties!$D$24-Properties!$D$23)/1000 -> 0 | F14: =D14*Properties!$C$7*(Properties!$D$21-Properties!$D$20)/1000 -> 0 | G14: =D14*((Properties!$D$15-Properties!$D$19)-Properties!$C$7*(Properties!$D$20-Properties!$D$24)/1000)+'Spring Autumn'!C14*(1-Properties!$C$7/Properties!$D$8) -> 0 | H14: =SUM(E14:G14) -> 0 | I14: 0 | J14: =I14/(Properties!$G$15-Properties!$G$19) -> 0 | K14: =J14*Properties!$C$7*(Properties!$G$24-Properties!$G$23)/1000 -> 0 | L14: =J14*Properties!$C$7*(Properties!$G$21-Properties!$G$20)/1000 -> 0 | M14: =J14*((Properties!$G$15-Properties!$G$19)-Properties!$C$7*(Properties!$G$20-Properties!$G$24)/1000)+'Spring Autumn'!I14*(1-Properties!$C$7/Properties!$D$9) -> 0 | N14: =SUM(K14:M14) -> 0 | O14: =N14+H14 -> 0
B15: 6 | C15: 0 | D15: =C15/(Properties!$D$15-Properties!$D$19) -> 0 | E15: =D15*Properties!$C$7*(Properties!$D$24-Properties!$D$23)/1000 -> 0 | F15: =D15*Properties!$C$7*(Properties!$D$21-Properties!$D$20)/1000 -> 0 | G15: =D15*((Properties!$D$15-Properties!$D$19)-Properties!$C$7*(Properties!$D$20-Properties!$D$24)/1000)+'Spring Autumn'!C15*(1-Properties!$C$7/Properties!$D$8) -> 0 | H15: =SUM(E15:G15) -> 0 | I15: 0 | J15: =I15/(Properties!$G$15-Properties!$G$19) -> 0 | K15: =J15*Properties!$C$7*(Properties!$G$24-Properties!$G$23)/1000 -> 0 | L15: =J15*Properties!$C$7*(Properties!$G$21-Properties!$G$20)/1000 -> 0 | M15: =J15*((Properties!$G$15-Properties!$G$19)-Properties!$C$7*(Properties!$G$20-Properties!$G$24)/1000)+'Spring Autumn'!I15*(1-Properties!$C$7/Properties!$D$9) -> 0 | N15: =SUM(K15:M15) -> 0 | O15: =N15+H15 -> 0
B16: 7 | C16: 2837.8677 | D16: =C16/(Properties!$D$15-Properties!$D$19) -> 10.902296 | E16: =D16*Properties!$C$7*(Properties!$D$24-Properties!$D$23)/1000 -> 22.322451 | F16: =D16*Properties!$C$7*(Properties!$D$21-Properties!$D$20)/1000 -> 90.182703 | G16: =D16*((Properties!$D$15-Properties!$D$19)-Properties!$C$7*(Properties!$D$20-Properties!$D$24)/1000)+'Spring Autumn'!C16*(1-Properties!$C$7/Properties!$D$8) -> 335.05553 | H16: =SUM(E16:G16) -> 447.56068 | I16: 1127.3066 | J16: =I16/(Properties!$G$15-Properties!$G$19) -> 4.3542162 | K16: =J16*Properties!$C$7*(Properties!$G$24-Properties!$G$23)/1000 -> 16.760684 | L16: =J16*Properties!$C$7*(Properties!$G$21-Properties!$G$20)/1000 -> 53.610416 | M16: =J16*((Properties!$G$15-Properties!$G$19)-Properties!$C$7*(Properties!$G$20-Properties!$G$24)/1000)+'Spring Autumn'!I16*(1-Properties!$C$7/Properties!$D$9) -> 57.129493 | N16: =SUM(K16:M16) -> 127.50059 | O16: =N16+H16 -> 575.06127
B17: 8 | C17: 2839.1798 | D17: =C17/(Properties!$D$15-Properties!$D$19) -> 10.907337 | E17: =D17*Properties!$C$7*(Properties!$D$24-Properties!$D$23)/1000 -> 22.332772 | F17: =D17*Properties!$C$7*(Properties!$D$21-Properties!$D$20)/1000 -> 90.224399 | G17: =D17*((Properties!$D$15-Properties!$D$19)-Properties!$C$7*(Properties!$D$20-Properties!$D$24)/1000)+'Spring Autumn'!C17*(1-Properties!$C$7/Properties!$D$8) -> 335.21044 | H17: =SUM(E17:G17) -> 447.76761 | I17: 1125.9945 | J17: =I17/(Properties!$G$15-Properties!$G$19) -> 4.3491482 | K17: =J17*Properties!$C$7*(Properties!$G$24-Properties!$G$23)/1000 -> 16.741176 | L17: =J17*Properties!$C$7*(Properties!$G$21-Properties!$G$20)/1000 -> 53.548017 | M17: =J17*((Properties!$G$15-Properties!$G$19)-Properties!$C$7*(Properties!$G$20-Properties!$G$24)/1000)+'Spring Autumn'!I17*(1-Properties!$C$7/Properties!$D$9) -> 57.062999 | N17: =SUM(K17:M17) -> 127.35219 | O17: =N17+H17 -> 575.1198
B18: 9 | C18: 0 | D18: =C18/(Properties!$D$15-Properties!$D$19) -> 0 | E18: =D18*Properties!$C$7*(Properties!$D$24-Properties!$D$23)/1000 -> 0 | F18: =D18*Properties!$C$7*(Properties!$D$21-Properties!$D$20)/1000 -> 0 | G18: =D18*((Properties!$D$15-Properties!$D$19)-Properties!$C$7*(Properties!$D$20-Properties!$D$24)/1000)+'Spring Autumn'!C18*(1-Properties!$C$7/Properties!$D$8) -> 0 | H18: =SUM(E18:G18) -> 0 | I18: 0 | J18: =I18/(Properties!$G$15-Properties!$G$19) -> 0 | K18: =J18*Properties!$C$7*(Properties!$G$24-Properties!$G$23)/1000 -> 0 | L18: =J18*Properties!$C$7*(Properties!$G$21-Properties!$G$20)/1000 -> 0 | M18: =J18*((Properties!$G$15-Properties!$G$19)-Properties!$C$7*(Properties!$G$20-Properties!$G$24)/1000)+'Spring Autumn'!I18*(1-Properties!$C$7/Properties!$D$9) -> 0 | N18: =SUM(K18:M18) -> 0 | O18: =N18+H18 -> 0 | Q18: Specific Exergy Destruction
B19: 10 | C19: 0 | D19: =C19/(Properties!$D$15-Properties!$D$19) -> 0 | E19: =D19*Properties!$C$7*(Properties!$D$24-Properties!$D$23)/1000 -> 0 | F19: =D19*Properties!$C$7*(Properties!$D$21-Properties!$D$20)/1000 -> 0 | G19: =D19*((Properties!$D$15-Properties!$D$19)-Properties!$C$7*(Properties!$D$20-Properties!$D$24)/1000)+'Spring Autumn'!C19*(1-Properties!$C$7/Properties!$D$8) -> 0 | H19: =SUM(E19:G19) -> 0 | I19: 0 | J19: =I19/(Properties!$G$15-Properties!$G$19) -> 0 | K19: =J19*Properties!$C$7*(Properties!$G$24-Properties!$G$23)/1000 -> 0 | L19: =J19*Properties!$C$7*(Properties!$G$21-Properties!$G$20)/1000 -> 0 | M19: =J19*((Properties!$G$15-Properties!$G$19)-Properties!$C$7*(Properties!$G$20-Properties!$G$24)/1000)+'Spring Autumn'!I19*(1-Properties!$C$7/Properties!$D$9) -> 0 | N19: =SUM(K19:M19) -> 0 | O19: =N19+H19 -> 0 | P19: Hot | Q19: =H7/C7 -> 0.1577102
B20: 11 | C20: 0 | D20: =C20/(Properties!$D$15-Properties!$D$19) -> 0 | E20: =D20*Properties!$C$7*(Properties!$D$24-Properties!$D$23)/1000 -> 0 | F20: =D20*Properties!$C$7*(Properties!$D$21-Properties!$D$20)/1000 -> 0 | G20: =D20*((Properties!$D$15-Properties!$D$19)-Properties!$C$7*(Properties!$D$20-Properties!$D$24)/1000)+'Spring Autumn'!C20*(1-Properties!$C$7/Properties!$D$8) -> 0 | H20: =SUM(E20:G20) -> 0 | I20: 0 | J20: =I20/(Properties!$G$15-Properties!$G$19) -> 0 | K20: =J20*Properties!$C$7*(Properties!$G$24-Properties!$G$23)/1000 -> 0 | L20: =J20*Properties!$C$7*(Properties!$G$21-Properties!$G$20)/1000 -> 0 | M20: =J20*((Properties!$G$15-Properties!$G$19)-Properties!$C$7*(Properties!$G$20-Properties!$G$24)/1000)+'Spring Autumn'!I20*(1-Properties!$C$7/Properties!$D$9) -> 0 | N20: =SUM(K20:M20) -> 0 | O20: =N20+H20 -> 0 | P20: Cold | Q20: =N7/I7 -> 0.11310197
B21: 12 | C21: 0 | D21: =C21/(Properties!$D$15-Properties!$D$19) -> 0 | E21: =D21*Properties!$C$7*(Properties!$D$24-Properties!$D$23)/1000 -> 0 | F21: =D21*Properties!$C$7*(Properties!$D$21-Properties!$D$20)/1000 -> 0 | G21: =D21*((Properties!$D$15-Properties!$D$19)-Properties!$C$7*(Properties!$D$20-Properties!$D$24)/1000)+'Spring Autumn'!C21*(1-Properties!$C$7/Properties!$D$8) -> 0 | H21: =SUM(E21:G21) -> 0 | I21: 0 | J21: =I21/(Properties!$G$15-Properties!$G$19) -> 0 | K21: =J21*Properties!$C$7*(Properties!$G$24-Properties!$G$23)/1000 -> 0 | L21: =J21*Properties!$C$7*(Properties!$G$21-Properties!$G$20)/1000 -> 0 | M21: =J21*((Properties!$G$15-Properties!$G$19)-Properties!$C$7*(Properties!$G$20-Properties!$G$24)/1000)+'Spring Autumn'!I21*(1-Properties!$C$7/Properties!$D$9) -> 0 | N21: =SUM(K21:M21) -> 0 | O21: =N21+H21 -> 0
B22: 13 | C22: 0 | D22: =C22/(Properties!$D$15-Properties!$D$19) -> 0 | E22: =D22*Properties!$C$7*(Properties!$D$24-Properties!$D$23)/1000 -> 0 | F22: =D22*Properties!$C$7*(Properties!$D$21-Properties!$D$20)/1000 -> 0 | G22: =D22*((Properties!$D$15-Properties!$D$19)-Properties!$C$7*(Properties!$D$20-Properties!$D$24)/1000)+'Spring Autumn'!C22*(1-Properties!$C$7/Properties!$D$8) -> 0 | H22: =SUM(E22:G22) -> 0 | I22: 0 | J22: =I22/(Properties!$G$15-Properties!$G$19) -> 0 | K22: =J22*Properties!$C$7*(Properties!$G$24-Properties!$G$23)/1000 -> 0 | L22: =J22*Properties!$C$7*(Properties!$G$21-Properties!$G$20)/1000 -> 0 | M22: =J22*((Properties!$G$15-Properties!$G$19)-Properties!$C$7*(Properties!$G$20-Properties!$G$24)/1000)+'Spring Autumn'!I22*(1-Properties!$C$7/Properties!$D$9) -> 0 | N22: =SUM(K22:M22) -> 0 | O22: =N22+H22 -> 0
B23: 14 | C23: 0 | D23: =C23/(Properties!$D$15-Properties!$D$19) -> 0 | E23: =D23*Properties!$C$7*(Properties!$D$24-Properties!$D$23)/1000 -> 0 | F23: =D23*Properties!$C$7*(Properties!$D$21-Properties!$D$20)/1000 -> 0 | G23: =D23*((Properties!$D$15-Properties!$D$19)-Properties!$C$7*(Properties!$D$20-Properties!$D$24)/1000)+'Spring Autumn'!C23*(1-Properties!$C$7/Properties!$D$8) -> 0 | H23: =SUM(E23:G23) -> 0 | I23: 0 | J23: =I23/(Properties!$G$15-Properties!$G$19) -> 0 | K23: =J23*Properties!$C$7*(Properties!$G$24-Properties!$G$23)/1000 -> 0 | L23: =J23*Properties!$C$7*(Properties!$G$21-Properties!$G$20)/1000 -> 0 | M23: =J23*((Properties!$G$15-Properties!$G$19)-Properties!$C$7*(Properties!$G$20-Properties!$G$24)/1000)+'Spring Autumn'!I23*(1-Properties!$C$7/Properties!$D$9) -> 0 | N23: =SUM(K23:M23) -> 0 | O23: =N23+H23 -> 0
B24: 15 | C24: 0 | D24: =C24/(Properties!$D$15-Properties!$D$19) -> 0 | E24: =D24*Properties!$C$7*(Properties!$D$24-Properties!$D$23)/1000 -> 0 | F24: =D24*Properties!$C$7*(Properties!$D$21-Properties!$D$20)/1000 -> 0 | G24: =D24*((Properties!$D$15-Properties!$D$19)-Properties!$C$7*(Properties!$D$20-Properties!$D$24)/1000)+'Spring Autumn'!C24*(1-Properties!$C$7/Properties!$D$8) -> 0 | H24: =SUM(E24:G24) -> 0 | I24: 0 | J24: =I24/(Properties!$G$15-Properties!$G$19) -> 0 | K24: =J24*Properties!$C$7*(Properties!$G$24-Properties!$G$23)/1000 -> 0 | L24: =J24*Properties!$C$7*(Properties!$G$21-Properties!$G$20)/1000 -> 0 | M24: =J24*((Properties!$G$15-Properties!$G$19)-Properties!$C$7*(Properties!$G$20-Properties!$G$24)/1000)+'Spring Autumn'!I24*(1-Properties!$C$7/Properties!$D$9) -> 0 | N24: =SUM(K24:M24) -> 0 | O24: =N24+H24 -> 0
B25: 16 | C25: 2829.0195 | D25: =C25/(Properties!$D$15-Properties!$D$19) -> 10.868304 | E25: =D25*Properties!$C$7*(Properties!$D$24-Properties!$D$23)/1000 -> 22.252852 | F25: =D25*Properties!$C$7*(Properties!$D$21-Properties!$D$20)/1000 -> 89.901521 | G25: =D25*((Properties!$D$15-Properties!$D$19)-Properties!$C$7*(Properties!$D$20-Properties!$D$24)/1000)+'Spring Autumn'!C25*(1-Properties!$C$7/Properties!$D$8) -> 334.01086 | H25: =SUM(E25:G25) -> 446.16523 | I25: 1136.1548 | J25: =I25/(Properties!$G$15-Properties!$G$19) -> 4.3883923 | K25: =J25*Properties!$C$7*(Properties!$G$24-Properties!$G$23)/1000 -> 16.892239 | L25: =J25*Properties!$C$7*(Properties!$G$21-Properties!$G$20)/1000 -> 54.031203 | M25: =J25*((Properties!$G$15-Properties!$G$19)-Properties!$C$7*(Properties!$G$20-Properties!$G$24)/1000)+'Spring Autumn'!I25*(1-Properties!$C$7/Properties!$D$9) -> 57.577901 | N25: =SUM(K25:M25) -> 128.50134 | O25: =N25+H25 -> 574.66657
B26: 17 | C26: 2827.5987 | D26: =C26/(Properties!$D$15-Properties!$D$19) -> 10.862846 | E26: =D26*Properties!$C$7*(Properties!$D$24-Properties!$D$23)/1000 -> 22.241677 | F26: =D26*Properties!$C$7*(Properties!$D$21-Properties!$D$20)/1000 -> 89.856373 | G26: =D26*((Properties!$D$15-Properties!$D$19)-Properties!$C$7*(Properties!$D$20-Properties!$D$24)/1000)+'Spring Autumn'!C26*(1-Properties!$C$7/Properties!$D$8) -> 333.84312 | H26: =SUM(E26:G26) -> 445.94117 | I26: 1137.5755 | J26: =I26/(Properties!$G$15-Properties!$G$19) -> 4.3938799 | K26: =J26*Properties!$C$7*(Properties!$G$24-Properties!$G$23)/1000 -> 16.913362 | L26: =J26*Properties!$C$7*(Properties!$G$21-Properties!$G$20)/1000 -> 54.098767 | M26: =J26*((Properties!$G$15-Properties!$G$19)-Properties!$C$7*(Properties!$G$20-Properties!$G$24)/1000)+'Spring Autumn'!I26*(1-Properties!$C$7/Properties!$D$9) -> 57.649901 | N26: =SUM(K26:M26) -> 128.66203 | O26: =N26+H26 -> 574.6032
B27: 18 | C27: 2825.7853 | D27: =C27/(Properties!$D$15-Properties!$D$19) -> 10.855879 | E27: =D27*Properties!$C$7*(Properties!$D$24-Properties!$D$23)/1000 -> 22.227412 | F27: =D27*Properties!$C$7*(Properties!$D$21-Properties!$D$20)/1000 -> 89.798746 | G27: =D27*((Properties!$D$15-Properties!$D$19)-Properties!$C$7*(Properties!$D$20-Properties!$D$24)/1000)+'Spring Autumn'!C27*(1-Properties!$C$7/Properties!$D$8) -> 333.62901 | H27: =SUM(E27:G27) -> 445.65517 | I27: 1139.3889 | J27: =I27/(Properties!$G$15-Properties!$G$19) -> 4.4008842 | K27: =J27*Properties!$C$7*(Properties!$G$24-Properties!$G$23)/1000 -> 16.940323 | L27: =J27*Properties!$C$7*(Properties!$G$21-Properties!$G$20)/1000 -> 54.185006 | M27: =J27*((Properties!$G$15-Properties!$G$19)-Properties!$C$7*(Properties!$G$20-Properties!$G$24)/1000)+'Spring Autumn'!I27*(1-Properties!$C$7/Properties!$D$9) -> 57.741801 | N27: =SUM(K27:M27) -> 128.86713 | O27: =N27+H27 -> 574.5223
B28: 19 | C28: 2823.8669 | D28: =C28/(Properties!$D$15-Properties!$D$19) -> 10.848509 | E28: =D28*Properties!$C$7*(Properties!$D$24-Properties!$D$23)/1000 -> 22.212322 | F28: =D28*Properties!$C$7*(Properties!$D$21-Properties!$D$20)/1000 -> 89.737781 | G28: =D28*((Properties!$D$15-Properties!$D$19)-Properties!$C$7*(Properties!$D$20-Properties!$D$24)/1000)+'Spring Autumn'!C28*(1-Properties!$C$7/Properties!$D$8) -> 333.40251 | H28: =SUM(E28:G28) -> 445.35261 | I28: 1141.3073 | J28: =I28/(Properties!$G$15-Properties!$G$19) -> 4.4082941 | K28: =J28*Properties!$C$7*(Properties!$G$24-Properties!$G$23)/1000 -> 16.968847 | L28: =J28*Properties!$C$7*(Properties!$G$21-Properties!$G$20)/1000 -> 54.27624 | M28: =J28*((Properties!$G$15-Properties!$G$19)-Properties!$C$7*(Properties!$G$20-Properties!$G$24)/1000)+'Spring Autumn'!I28*(1-Properties!$C$7/Properties!$D$9) -> 57.839023 | N28: =SUM(K28:M28) -> 129.08411 | O28: =N28+H28 -> 574.43672
B29: 20 | C29: 2821.9516 | D29: =C29/(Properties!$D$15-Properties!$D$19) -> 10.841151 | E29: =D29*Properties!$C$7*(Properties!$D$24-Properties!$D$23)/1000 -> 22.197257 | F29: =D29*Properties!$C$7*(Properties!$D$21-Properties!$D$20)/1000 -> 89.676917 | G29: =D29*((Properties!$D$15-Properties!$D$19)-Properties!$C$7*(Properties!$D$20-Properties!$D$24)/1000)+'Spring Autumn'!C29*(1-Properties!$C$7/Properties!$D$8) -> 333.17638 | H29: =SUM(E29:G29) -> 445.05056 | I29: 1143.2226 | J29: =I29/(Properties!$G$15-Properties!$G$19) -> 4.4156918 | K29: =J29*Properties!$C$7*(Properties!$G$24-Properties!$G$23)/1000 -> 16.997322 | L29: =J29*Properties!$C$7*(Properties!$G$21-Properties!$G$20)/1000 -> 54.367322 | M29: =J29*((Properties!$G$15-Properties!$G$19)-Properties!$C$7*(Properties!$G$20-Properties!$G$24)/1000)+'Spring Autumn'!I29*(1-Properties!$C$7/Properties!$D$9) -> 57.936084 | N29: =SUM(K29:M29) -> 129.30073 | O29: =N29+H29 -> 574.35129
B30: 21 | C30: 2819.9318 | D30: =C30/(Properties!$D$15-Properties!$D$19) -> 10.833391 | E30: =D30*Properties!$C$7*(Properties!$D$24-Properties!$D$23)/1000 -> 22.181369 | F30: =D30*Properties!$C$7*(Properties!$D$21-Properties!$D$20)/1000 -> 89.612731 | G30: =D30*((Properties!$D$15-Properties!$D$19)-Properties!$C$7*(Properties!$D$20-Properties!$D$24)/1000)+'Spring Autumn'!C30*(1-Properties!$C$7/Properties!$D$8) -> 332.93791 | H30: =SUM(E30:G30) -> 444.73201 | I30: 1145.2424 | J30: =I30/(Properties!$G$15-Properties!$G$19) -> 4.4234934 | K30: =J30*Properties!$C$7*(Properties!$G$24-Properties!$G$23)/1000 -> 17.027353 | L30: =J30*Properties!$C$7*(Properties!$G$21-Properties!$G$20)/1000 -> 54.463377 | M30: =J30*((Properties!$G$15-Properties!$G$19)-Properties!$C$7*(Properties!$G$20-Properties!$G$24)/1000)+'Spring Autumn'!I30*(1-Properties!$C$7/Properties!$D$9) -> 58.038445 | N30: =SUM(K30:M30) -> 129.52917 | O30: =N30+H30 -> 574.26119
B31: 22 | C31: 2818.1311 | D31: =C31/(Properties!$D$15-Properties!$D$19) -> 10.826474 | E31: =D31*Properties!$C$7*(Properties!$D$24-Properties!$D$23)/1000 -> 22.167205 | F31: =D31*Properties!$C$7*(Properties!$D$21-Properties!$D$20)/1000 -> 89.555509 | G31: =D31*((Properties!$D$15-Properties!$D$19)-Properties!$C$7*(Properties!$D$20-Properties!$D$24)/1000)+'Spring Autumn'!C31*(1-Properties!$C$7/Properties!$D$8) -> 332.72532 | H31: =SUM(E31:G31) -> 444.44803 | I31: 1147.0431 | J31: =I31/(Properties!$G$15-Properties!$G$19) -> 4.4304484 | K31: =J31*Properties!$C$7*(Properties!$G$24-Properties!$G$23)/1000 -> 17.054125 | L31: =J31*Properties!$C$7*(Properties!$G$21-Properties!$G$20)/1000 -> 54.54901 | M31: =J31*((Properties!$G$15-Properties!$G$19)-Properties!$C$7*(Properties!$G$20-Properties!$G$24)/1000)+'Spring Autumn'!I31*(1-Properties!$C$7/Properties!$D$9) -> 58.129698 | N31: =SUM(K31:M31) -> 129.73283 | O31: =N31+H31 -> 574.18086
B32: 23 | C32: 0 | D32: =C32/(Properties!$D$15-Properties!$D$19) -> 0 | E32: =D32*Properties!$C$7*(Properties!$D$24-Properties!$D$23)/1000 -> 0 | F32: =D32*Properties!$C$7*(Properties!$D$21-Properties!$D$20)/1000 -> 0 | G32: =D32*((Properties!$D$15-Properties!$D$19)-Properties!$C$7*(Properties!$D$20-Properties!$D$24)/1000)+'Spring Autumn'!C32*(1-Properties!$C$7/Properties!$D$8) -> 0 | H32: =SUM(E32:G32) -> 0 | I32: 0 | J32: =I32/(Properties!$G$15-Properties!$G$19) -> 0 | K32: =J32*Properties!$C$7*(Properties!$G$24-Properties!$G$23)/1000 -> 0 | L32: =J32*Properties!$C$7*(Properties!$G$21-Properties!$G$20)/1000 -> 0 | M32: =J32*((Properties!$G$15-Properties!$G$19)-Properties!$C$7*(Properties!$G$20-Properties!$G$24)/1000)+'Spring Autumn'!I32*(1-Properties!$C$7/Properties!$D$9) -> 0 | N32: =SUM(K32:M32) -> 0 | O32: =N32+H32 -> 0
... B681: 672 | C681: 0 | D681: =C681/(Properties!$D$15-Properties!$D$19) -> 0 | E681: =D681*Properties!$C$7*(Properties!$D$24-Properties!$D$23)/1000 -> 0 | F681: =D681*Properties!$C$7*(Properties!$D$21-Properties!$D$20)/1000 -> 0 | G681: =D681*((Properties!$D$15-Properties!$D$19)-Properties!$C$7*(Properties!$D$20-Properties!$D$24)/1000)+'Spring Autumn'!C681*(1-Properties!$C$7/Properties!$D$8) -> 0 | H681: =SUM(E681:G681) -> 0 | I681: 0 | J681: =I681/(Properties!$G$15-Properties!$G$19) -> 0 | K681: =J681*Properties!$C$7*(Properties!$G$24-Properties!$G$23)/1000 -> 0 | L681: =J681*Properties!$C$7*(Properties!$G$21-Properties!$G$20)/1000 -> 0 | M681: =J681*((Properties!$G$15-Properties!$G$19)-Properties!$C$7*(Properties!$G$20-Properties!$G$24)/1000)+'Spring Autumn'!I681*(1-Properties!$C$7/Properties!$D$9) -> 0 | N681: =SUM(K681:M681) -> 0 | O681: =N681+H681 -> 0

Sheet Summer
C2: Summer
C3: Hot Sink | I3: Cold Sink
C4: W20W35 | I4: W10W35
C5: Evap Duty | D5: Refrig mass flow rate | E5: Exergy Destruction | I5: Evap Duty | J5: Refrig mass flow rate | K5: Exergy Destruction
C6: Qevap,h | D6: ṁ ref | E6: Expansion Valve | F6: Compressor | G6: Evaporator | H6: Total | I6: Qevap,c | J6: ṁ ref | K6: Expansion Valve | L6: Compressor | M6: Evaporator | N6: Total | O6: Total
B7: Total | C7: =SUM(C10:C681) -> 0 | E7: =SUM(E10:E681) -> 0 | F7: =SUM(F10:F681) -> 0 | G7: =SUM(G10:G681) -> 0 | H7: =SUM(H10:H681) -> 0 | I7: =SUM(I10:I681) -> 209555.27 | K7: =SUM(K10:K681) -> 3115.6473 | L7: =SUM(L10:L681) -> 9965.652 | M7: =SUM(M10:M681) -> 10619.814 | N7: =SUM(N10:N681) -> 23701.113 | O7: =SUM(O10:O681) -> 23701.113
E8: =E7/$H$7 -> #DIV/0! | F8: =F7/$H$7 -> #DIV/0! | G8: =G7/$H$7 -> #DIV/0! | H8: =H7/O7 -> 0 | K8: =K7/$N$7 -> 0.13145574 | L8: =L7/$N$7 -> 0.42047189 | M8: =M7/$N$7 -> 0.44807237 | N8: =N7/O7 -> 1
B9: Hours | C9: kW | D9: kg/s | E9: kW | F9: kW | G9: kW | H9: kW | I9: kW | J9: kg/s | K9: kW | L9: kW | M9: kW | N9: kW | O9: kW
B10: 1 | C10: 0 | D10: =C10/(Properties!$E$15-Properties!$E$19) -> 0 | E10: =D10*Properties!$C$7*(Properties!$E$24-Properties!$E$23)/1000 -> 0 | F10: =D10*Properties!$C$7*(Properties!$D$21-Properties!$D$20)/1000 -> 0 | G10: =D10*((Properties!$E$15-Properties!$E$19)-Properties!$C$7*(Properties!$E$20-Properties!$E$24)/1000)+Summer!C10*(1-Properties!$C$7/Properties!$D$8) -> 0 | H10: =SUM(E10:G10) -> 0 | I10: 0 | J10: =I10/(Properties!$H$15-Properties!$H$19) -> 0 | K10: =J10*Properties!$C$7*(Properties!$H$24-Properties!$H$23)/1000 -> 0 | L10: =J10*Properties!$C$7*(Properties!$H$21-Properties!$H$20)/1000 -> 0 | M10: =J10*((Properties!$H$15-Properties!$H$19)-Properties!$C$7*(Properties!$H$20-Properties!$H$24)/1000)+Summer!I10*(1-Properties!$C$7/Properties!$D$9) -> 0 | N10: =SUM(K10:M10) -> 0 | O10: =N10+H10 -> 0
B11: 2 | C11: 0 | D11: =C11/(Properties!$E$15-Properties!$E$19) -> 0 | E11: =D11*Properties!$C$7*(Properties!$D$24-Properties!$D$23)/1000 -> 0 | F11: =D11*Properties!$C$7*(Properties!$D$21-Properties!$D$20)/1000 -> 0 | G11: =D11*((Properties!$E$15-Properties!$E$19)-Properties!$C$7*(Properties!$E$20-Properties!$E$24)/1000)+Summer!C11*(1-Properties!$C$7/Properties!$D$8) -> 0 | H11: =SUM(E11:G11) -> 0 | I11: 0 | J11: =I11/(Properties!$H$15-Properties!$H$19) -> 0 | K11: =J11*Properties!$C$7*(Properties!$H$24-Properties!$H$23)/1000 -> 0 | L11: =J11*Properties!$C$7*(Properties!$H$21-Properties!$H$20)/1000 -> 0 | M11: =J11*((Properties!$H$15-Properties!$H$19)-Properties!$C$7*(Properties!$H$20-Properties!$H$24)/1000)+Summer!I11*(1-Properties!$C$7/Properties!$D$9) -> 0 | N11: =SUM(K11:M11) -> 0 | O11: =N11+H11 -> 0
B12: 3 | C12: 0 | D12: =C12/(Properties!$E$15-Properties!$E$19) -> 0 | E12: =D12*Properties!$C$7*(Properties!$D$24-Properties!$D$23)/1000 -> 0 | F12: =D12*Properties!$C$7*(Properties!$D$21-Properties!$D$20)/1000 -> 0 | G12: =D12*((Properties!$E$15-Properties!$E$19)-Properties!$C$7*(Properties!$E$20-Properties!$E$24)/1000)+Summer!C12*(1-Properties!$C$7/Properties!$D$8) -> 0 | H12: =SUM(E12:G12) -> 0 | I12: 0 | J12: =I12/(Properties!$H$15-Properties!$H$19) -> 0 | K12: =J12*Properties!$C$7*(Properties!$H$24-Properties!$H$23)/1000 -> 0 | L12: =J12*Properties!$C$7*(Properties!$H$21-Properties!$H$20)/1000 -> 0 | M12: =J12*((Properties!$H$15-Properties!$H$19)-Properties!$C$7*(Properties!$H$20-Properties!$H$24)/1000)+Summer!I12*(1-Properties!$C$7/Properties!$D$9) -> 0 | N12: =SUM(K12:M12) -> 0 | O12: =N12+H12 -> 0
B13: 4 | C13: 0 | D13: =C13/(Properties!$E$15-Properties!$E$19) -> 0 | E13: =D13*Properties!$C$7*(Properties!$D$24-Properties!$D$23)/1000 -> 0 | F13: =D13*Properties!$C$7*(Properties!$D$21-Properties!$D$20)/1000 -> 0 | G13: =D13*((Properties!$E$15-Properties!$E$19)-Properties!$C$7*(Properties!$E$20-Properties!$E$24)/1000)+Summer!C13*(1-Properties!$C$7/Properties!$D$8) -> 0 | H13: =SUM(E13:G13) -> 0 | I13: 0 | J13: =I13/(Properties!$H$15-Properties!$H$19) -> 0 | K13: =J13*Properties!$C$7*(Properties!$H$24-Properties!$H$23)/1000 -> 0 | L13: =J13*Properties!$C$7*(Properties!$H$21-Properties!$H$20)/1000 -> 0 | M13: =J13*((Properties!$H$15-Properties!$H$19)-Properties!$C$7*(Properties!$H$20-Properties!$H$24)/1000)+Summer!I13*(1-Properties!$C$7/Properties!$D$9) -> 0 | N13: =SUM(K13:M13) -> 0 | O13: =N13+H13 -> 0
B14: 5 | C14: 0 | D14: =C14/(Properties!$E$15-Properties!$E$19) -> 0 | E14: =D14*Properties!$C$7*(Properties!$D$24-Properties!$D$23)/1000 -> 0 | F14: =D14*Properties!$C$7*(Properties!$D$21-Properties!$D$20)/1000 -> 0 | G14: =D14*((Properties!$E$15-Properties!$E$19)-Properties!$C$7*(Properties!$E$20-Properties!$E$24)/1000)+Summer!C14*(1-Properties!$C$7/Properties!$D$8) -> 0 | H14: =SUM(E14:G14) -> 0 | I14: 0 | J14: =I14/(Properties!$H$15-Properties!$H$19) -> 0 | K14: =J14*Properties!$C$7*(Properties!$H$24-Properties!$H$23)/1000 -> 0 | L14: =J14*Properties!$C$7*(Properties!$H$21-Properties!$H$20)/1000 -> 0 | M14: =J14*((Properties!$H$15-Properties!$H$19)-Properties!$C$7*(Properties!$H$20-Properties!$H$24)/1000)+Summer!I14*(1-Properties!$C$7/Properties!$D$9) -> 0 | N14: =SUM(K14:M14) -> 0 | O14: =N14+H14 -> 0
B15: 6 | C15: 0 | D15: =C15/(Properties!$E$15-Properties!$E$19) -> 0 | E15: =D15*Properties!$C$7*(Properties!$D$24-Properties!$D$23)/1000 -> 0 | F15: =D15*Properties!$C$7*(Properties!$D$21-Properties!$D$20)/1000 -> 0 | G15: =D15*((Properties!$E$15-Properties!$E$19)-Properties!$C$7*(Properties!$E$20-Properties!$E$24)/1000)+Summer!C15*(1-Properties!$C$7/Properties!$D$8) -> 0 | H15: =SUM(E15:G15) -> 0 | I15: 0 | J15: =I15/(Properties!$H$15-Properties!$H$19) -> 0 | K15: =J15*Properties!$C$7*(Properties!$H$24-Properties!$H$23)/1000 -> 0 | L15: =J15*Properties!$C$7*(Properties!$H$21-Properties!$H$20)/1000 -> 0 | M15: =J15*((Properties!$H$15-Properties!$H$19)-Properties!$C$7*(Properties!$H$20-Properties!$H$24)/1000)+Summer!I15*(1-Properties!$C$7/Properties!$D$9) -> 0 | N15: =SUM(K15:M15) -> 0 | O15: =N15+H15 -> 0
B16: 7 | C16: 0 | D16: =C16/(Properties!$E$15-Properties!$E$19) -> 0 | E16: =D16*Properties!$C$7*(Properties!$D$24-Properties!$D$23)/1000 -> 0 | F16: =D16*Properties!$C$7*(Properties!$D$21-Properties!$D$20)/1000 -> 0 | G16: =D16*((Properties!$E$15-Properties!$E$19)-Properties!$C$7*(Properties!$E$20-Properties!$E$24)/1000)+Summer!C16*(1-Properties!$C$7/Properties!$D$8) -> 0 | H16: =SUM(E16:G16) -> 0 | I16: 680.37424 | J16: =I16/(Properties!$H$15-Properties!$H$19) -> 2.6279422 | K16: =J16*Properties!$C$7*(Properties!$H$24-Properties!$H$23)/1000 -> 10.115738 | L16: =J16*Properties!$C$7*(Properties!$H$21-Properties!$H$20)/1000 -> 32.356013 | M16: =J16*((Properties!$H$15-Properties!$H$19)-Properties!$C$7*(Properties!$H$20-Properties!$H$24)/1000)+Summer!I16*(1-Properties!$C$7/Properties!$D$9) -> 34.479916 | N16: =SUM(K16:M16) -> 76.951667 | O16: =N16+H16 -> 76.951667
B17: 8 | C17: 0 | D17: =C17/(Properties!$E$15-Properties!$E$19) -> 0 | E17: =D17*Properties!$C$7*(Properties!$D$24-Properties!$D$23)/1000 -> 0 | F17: =D17*Properties!$C$7*(Properties!$D$21-Properties!$D$20)/1000 -> 0 | G17: =D17*((Properties!$E$15-Properties!$E$19)-Properties!$C$7*(Properties!$E$20-Properties!$E$24)/1000)+Summer!C17*(1-Properties!$C$7/Properties!$D$8) -> 0 | H17: =SUM(E17:G17) -> 0 | I17: 680.37424 | J17: =I17/(Properties!$H$15-Properties!$H$19) -> 2.6279422 | K17: =J17*Properties!$C$7*(Properties!$H$24-Properties!$H$23)/1000 -> 10.115738 | L17: =J17*Properties!$C$7*(Properties!$H$21-Properties!$H$20)/1000 -> 32.356013 | M17: =J17*((Properties!$H$15-Properties!$H$19)-Properties!$C$7*(Properties!$H$20-Properties!$H$24)/1000)+Summer!I17*(1-Properties!$C$7/Properties!$D$9) -> 34.479916 | N17: =SUM(K17:M17) -> 76.951667 | O17: =N17+H17 -> 76.951667 | Q17: Specific Exergy Destruction
B18: 9 | C18: 0 | D18: =C18/(Properties!$E$15-Properties!$E$19) -> 0 | E18: =D18*Properties!$C$7*(Properties!$D$24-Properties!$D$23)/1000 -> 0 | F18: =D18*Properties!$C$7*(Properties!$D$21-Properties!$D$20)/1000 -> 0 | G18: =D18*((Properties!$E$15-Properties!$E$19)-Properties!$C$7*(Properties!$E$20-Properties!$E$24)/1000)+Summer!C18*(1-Properties!$C$7/Properties!$D$8) -> 0 | H18: =SUM(E18:G18) -> 0 | I18: 0 | J18: =I18/(Properties!$H$15-Properties!$H$19) -> 0 | K18: =J18*Properties!$C$7*(Properties!$H$24-Properties!$H$23)/1000 -> 0 | L18: =J18*Properties!$C$7*(Properties!$H$21-Properties!$H$20)/1000 -> 0 | M18: =J18*((Properties!$H$15-Properties!$H$19)-Properties!$C$7*(Properties!$H$20-Properties!$H$24)/1000)+Summer!I18*(1-Properties!$C$7/Properties!$D$9) -> 0 | N18: =SUM(K18:M18) -> 0 | O18: =N18+H18 -> 0 | P18: Hot | Q18: 0
B19: 10 | C19: 0 | D19: =C19/(Properties!$E$15-Properties!$E$19) -> 0 | E19: =D19*Properties!$C$7*(Properties!$D$24-Properties!$D$23)/1000 -> 0 | F19: =D19*Properties!$C$7*(Properties!$D$21-Properties!$D$20)/1000 -> 0 | G19: =D19*((Properties!$E$15-Properties!$E$19)-Properties!$C$7*(Properties!$E$20-Properties!$E$24)/1000)+Summer!C19*(1-Properties!$C$7/Properties!$D$8) -> 0 | H19: =SUM(E19:G19) -> 0 | I19: 0 | J19: =I19/(Properties!$H$15-Properties!$H$19) -> 0 | K19: =J19*Properties!$C$7*(Properties!$H$24-Properties!$H$23)/1000 -> 0 | L19: =J19*Properties!$C$7*(Properties!$H$21-Properties!$H$20)/1000 -> 0 | M19: =J19*((Properties!$H$15-Properties!$H$19)-Properties!$C$7*(Properties!$H$20-Properties!$H$24)/1000)+Summer!I19*(1-Properties!$C$7/Properties!$D$9) -> 0 | N19: =SUM(K19:M19) -> 0 | O19: =N19+H19 -> 0 | P19: Cold | Q19: =N7/I7 -> 0.11310197
B20: 11 | C20: 0 | D20: =C20/(Properties!$E$15-Properties!$E$19) -> 0 | E20: =D20*Properties!$C$7*(Properties!$D$24-Properties!$D$23)/1000 -> 0 | F20: =D20*Properties!$C$7*(Properties!$D$21-Properties!$D$20)/1000 -> 0 | G20: =D20*((Properties!$E$15-Properties!$E$19)-Properties!$C$7*(Properties!$E$20-Properties!$E$24)/1000)+Summer!C20*(1-Properties!$C$7/Properties!$D$8) -> 0 | H20: =SUM(E20:G20) -> 0 | I20: 0 | J20: =I20/(Properties!$H$15-Properties!$H$19) -> 0 | K20: =J20*Properties!$C$7*(Properties!$H$24-Properties!$H$23)/1000 -> 0 | L20: =J20*Properties!$C$7*(Properties!$H$21-Properties!$H$20)/1000 -> 0 | M20: =J20*((Properties!$H$15-Properties!$H$19)-Properties!$C$7*(Properties!$H$20-Properties!$H$24)/1000)+Summer!I20*(1-Properties!$C$7/Properties!$D$9) -> 0 | N20: =SUM(K20:M20) -> 0 | O20: =N20+H20 -> 0
B21: 12 | C21: 0 | D21: =C21/(Properties!$E$15-Properties!$E$19) -> 0 | E21: =D21*Properties!$C$7*(Properties!$D$24-Properties!$D$23)/1000 -> 0 | F21: =D21*Properties!$C$7*(Properties!$D$21-Properties!$D$20)/1000 -> 0 | G21: =D21*((Properties!$E$15-Properties!$E$19)-Properties!$C$7*(Properties!$E$20-Properties!$E$24)/1000)+Summer!C21*(1-Properties!$C$7/Properties!$D$8) -> 0 | H21: =SUM(E21:G21) -> 0 | I21: 0 | J21: =I21/(Properties!$H$15-Properties!$H$19) -> 0 | K21: =J21*Properties!$C$7*(Properties!$H$24-Properties!$H$23)/1000 -> 0 | L21: =J21*Properties!$C$7*(Properties!$H$21-Properties!$H$20)/1000 -> 0 | M21: =J21*((Properties!$H$15-Properties!$H$19)-Properties!$C$7*(Properties!$H$20-Properties!$H$24)/1000)+Summer!I21*(1-Properties!$C$7/Properties!$D$9) -> 0 | N21: =SUM(K21:M21) -> 0 | O21: =N21+H21 -> 0
B22: 13 | C22: 0 | D22: =C22/(Properties!$E$15-Properties!$E$19) -> 0 | E22: =D22*Properties!$C$7*(Properties!$D$24-Properties!$D$23)/1000 -> 0 | F22: =D22*Properties!$C$7*(Properties!$D$21-Properties!$D$20)/1000 -> 0 | G22: =D22*((Properties!$E$15-Properties!$E$19)-Properties!$C$7*(Properties!$E$20-Properties!$E$24)/1000)+Summer!C22*(1-Properties!$C$7/Properties!$D$8) -> 0 | H22: =SUM(E22:G22) -> 0 | I22: 0 | J22: =I22/(Properties!$H$15-Properties!$H$19) -> 0 | K22: =J22*Properties!$C$7*(Properties!$H$24-Properties!$H$23)/1000 -> 0 | L22: =J22*Properties!$C$7*(Properties!$H$21-Properties!$H$20)/1000 -> 0 | M22: =J22*((Properties!$H$15-Properties!$H$19)-Properties!$C$7*(Properties!$H$20-Properties!$H$24)/1000)+Summer!I22*(1-Properties!$C$7/Properties!$D$9) -> 0 | N22: =SUM(K22:M22) -> 0 | O22: =N22+H22 -> 0
B23: 14 | C23: 0 | D23: =C23/(Properties!$E$15-Properties!$E$19) -> 0 | E23: =D23*Properties!$C$7*(Properties!$D$24-Properties!$D$23)/1000 -> 0 | F23: =D23*Properties!$C$7*(Properties!$D$21-Properties!$D$20)/1000 -> 0 | G23: =D23*((Properties!$E$15-Properties!$E$19)-Properties!$C$7*(Properties!$E$20-Properties!$E$24)/1000)+Summer!C23*(1-Properties!$C$7/Properties!$D$8) -> 0 | H23: =SUM(E23:G23) -> 0 | I23: 0 | J23: =I23/(Properties!$H$15-Properties!$H$19) -> 0 | K23: =J23*Properties!$C$7*(Properties!$H$24-Properties!$H$23)/1000 -> 0 | L23: =J23*Properties!$C$7*(Properties!$H$21-Properties!$H$20)/1000 -> 0 | M23: =J23*((Properties!$H$15-Properties!$H$19)-Properties!$C$7*(Properties!$H$20-Properties!$H$24)/1000)+Summer!I23*(1-Properties!$C$7/Properties!$D$9) -> 0 | N23: =SUM(K23:M23) -> 0 | O23: =N23+H23 -> 0
B24: 15 | C24: 0 | D24: =C24/(Properties!$E$15-Properties!$E$19) -> 0 | E24: =D24*Properties!$C$7*(Properties!$D$24-Properties!$D$23)/1000 -> 0 | F24: =D24*Properties!$C$7*(Properties!$D$21-Properties!$D$20)/1000 -> 0 | G24: =D24*((Properties!$E$15-Properties!$E$19)-Properties!$C$7*(Properties!$E$20-Properties!$E$24)/1000)+Summer!C24*(1-Properties!$C$7/Properties!$D$8) -> 0 | H24: =SUM(E24:G24) -> 0 | I24: 0 | J24: =I24/(Properties!$H$15-Properties!$H$19) -> 0 | K24: =J24*Properties!$C$7*(Properties!$H$24-Properties!$H$23)/1000 -> 0 | L24: =J24*Properties!$C$7*(Properties!$H$21-Properties!$H$20)/1000 -> 0 | M24: =J24*((Properties!$H$15-Properties!$H$19)-Properties!$C$7*(Properties!$H$20-Properties!$H$24)/1000)+Summer!I24*(1-Properties!$C$7/Properties!$D$9) -> 0 | N24: =SUM(K24:M24) -> 0 | O24: =N24+H24 -> 0
