Workbook

Sheet Properties
C8: °C | D8: K
B9: T0 | C9: 0 | D9: =C9+273 -> 273
B10: Tcond | C10: 30 | D10: =C10+273 -> 303
C12: Winter | E12: Spring/Autumn | G12: Summer
C13: °C | D13: K | E13: °C | F13: K | G13: °C | H13: K
B14: Tair | C14: 7 | D14: =C14+273 -> 280 | E14: 15.3 | F14: =E14+273 -> 288.3 | G14: 20 | H14: =G14+273 -> 293
B16: Summary
B17: Duty | C17: kWh | D17: =Winter!C7 -> 2227714.5 | F17: ='Spring Autumn'!C4 -> 2439877.8 | H17: =Summer!C4 -> 2657516.1
B18: Edes | C18: kWh | D18: =Winter!D7 -> 164872.93 | F18: ='Spring Autumn'!D4 -> 112088.43 | H18: =Summer!D4 -> 81719.989

Sheet Winter
C5: Condenser Duty | L5: Four Weekly Demand (kWh per 672 hours)
C6: Qcond | D6: Edes | F6: To | G6: =Properties!$D$9 -> 273 | H6: K | L6: Cooler Duty (kWh)
B7: Total | C7: =SUM(C9:C680) -> 2227714.5 | D7: =SUM(D9:D680) -> 164872.93 | F7: Tcond | G7: =Properties!$D$10 -> 303 | H7: K | L7: DCHrW
B8: Hours | C8: kWh | D8: kWh | F8: Tair | G8: =Properties!$D$14 -> 280 | H8: K | L8: Winter
A9: 1 | B9: 1 | C9: 2142 | D9: =$G$6*C9*(1/$G$8-1/$G$7) -> 158.52921 | F9: CoP | G9: 5 | L9: 2142
A10: 2 | B10: 2 | C10: 2016 | D10: =$G$6*C10*(1/$G$8-1/$G$7) -> 149.20396 | L10: 2016
A11: 3 | B11: 3 | C11: 2142 | D11: =$G$6*C11*(1/$G$8-1/$G$7) -> 158.52921 | L11: 2142
A12: 4 | B12: 4 | C12: 2268 | D12: =$G$6*C12*(1/$G$8-1/$G$7) -> 167.85446 | L12: 2268
A13: 5 | B13: 5 | C13: 2583 | D13: =$G$6*C13*(1/$G$8-1/$G$7) -> 191.16757 | L13: 2583
A14: 6 | B14: 6 | C14: 2772 | D14: =$G$6*C14*(1/$G$8-1/$G$7) -> 205.15545 | L14: 2772
A15: 7 | B15: 7 | C15: 2961 | D15: =$G$6*C15*(1/$G$8-1/$G$7) -> 219.14332 | L15: 2961
A16: 8 | B16: 8 | C16: 3150 | D16: =$G$6*C16*(1/$G$8-1/$G$7) -> 233.13119 | L16: 3150
A17: 9 | B17: 9 | C17: 3339 | D17: =$G$6*C17*(1/$G$8-1/$G$7) -> 247.11906 | L17: 3339
A18: 10 | B18: 10 | C18: 3528 | D18: =$G$6*C18*(1/$G$8-1/$G$7) -> 261.10693 | L18: 3528
A19: 11 | B19: 11 | C19: 3717 | D19: =$G$6*C19*(1/$G$8-1/$G$7) -> 275.0948 | L19: 3717
A20: 12 | B20: 12 | C20: 3906 | D20: =$G$6*C20*(1/$G$8-1/$G$7) -> 289.08267 | L20: 3906
A21: 13 | B21: 13 | C21: 4095 | D21: =$G$6*C21*(1/$G$8-1/$G$7) -> 303.07054 | L21: 4095
... A176: 168 | B176: 168 | C176: 2772 | D176: =$G$6*C176*(1/$G$8-1/$G$7) -> 205.15545 | L176: 2772
A177: 1 | B177: 169 | C177: =C9 -> 2142 | D177: =$G$6*C177*(1/$G$8-1/$G$7) -> 158.52921 | L177: 2142
A178: 2 | B178: 170 | C178: =C10 -> 2016 | D178: =$G$6*C178*(1/$G$8-1/$G$7) -> 149.20396 | L178: 2016
A179: 3 | B179: 171 | C179: =C11 -> 2142 | D179: =$G$6*C179*(1/$G$8-1/$G$7) -> 158.52921 | L179: 2142
A180: 4 | B180: 172 | C180: =C12 -> 2268 | D180: =$G$6*C180*(1/$G$8-1/$G$7) -> 167.85446 | L180: 2268
A181: 5 | B181: 173 | C181: =C13 -> 2583 | D181: =$G$6*C181*(1/$G$8-1/$G$7) -> 191.16757 | L181: 2583
A182: 6 | B182: 174 | C182: =C14 -> 2772 | D182: =$G$6*C182*(1/$G$8-1/$G$7) -> 205.15545 | L182: 2772
A183: 7 | B183: 175 | C183: =C15 -> 2961 | D183: =$G$6*C183*(1/$G$8-1/$G$7) -> 219.14332 | L183: 2961
A184: 8 | B184: 176 | C184: =C16 -> 3150 | D184: =$G$6*C184*(1/$G$8-1/$G$7) -> 233.13119 | L184: 3150
A185: 9 | B185: 177 | C185: =C17 -> 3339 | D185: =$G$6*C185*(1/$G$8-1/$G$7) -> 247.11906 | L185: 3339
A186: 10 | B186: 178 | C186: =C18 -> 3528 | D186: =$G$6*C186*(1/$G$8-1/$G$7) -> 261.10693 | L186: 3528
A187: 11 | B187: 179 | C187: =C19 -> 3717 | D187: =$G$6*C187*(1/$G$8-1/$G$7) -> 275.0948 | L187: 3717
A188: 12 | B188: 180 | C188: =C20 -> 3906 | D188: =$G$6*C188*(1/$G$8-1/$G$7) -> 289.08267 | L188: 3906
... A344: 168 | B344: 336 | C344: =C176 -> 2772 | D344: =$G$6*C344*(1/$G$8-1/$G$7) -> 205.15545 | L344: 2772
A345: 1 | B345: 337 | C345: =C9 -> 2142 | D345: =$G$6*C345*(1/$G$8-1/$G$7) -> 158.52921 | L345: 2142
A346: 2 | B346: 338 | C346: =C10 -> 2016 | D346: =$G$6*C346*(1/$G$8-1/$G$7) -> 149.20396 | L346: 2016
A347: 3 | B347: 339 | C347: =C11 -> 2142 | D347: =$G$6*C347*(1/$G$8-1/$G$7) -> 158.52921 | L347: 2142
A348: 4 | B348: 340 | C348: =C12 -> 2268 | D348: =$G$6*C348*(1/$G$8-1/$G$7) -> 167.85446 | L348: 2268
A349: 5 | B349: 341 | C349: =C13 -> 2583 | D349: =$G$6*C349*(1/$G$8-1/$G$7) -> 191.16757 | L349: 2583
A350: 6 | B350: 342 | C350: =C14 -> 2772 | D350: =$G$6*C350*(1/$G$8-1/$G$7) -> 205.15545 | L350: 2772
A351: 7 | B351: 343 | C351: =C15 -> 2961 | D351: =$G$6*C351*(1/$G$8-1/$G$7) -> 219.14332 | L351: 2961
A352: 8 | B352: 344 | C352: =C16 -> 3150 | D352: =$G$6*C352*(1/$G$8-1/$G$7) -> 233.13119 | L352: 3150
A353: 9 | B353: 345 | C353: =C17 -> 3339 | D353: =$G$6*C353*(1/$G$8-1/$G$7) -> 247.11906 | L353: 3339
...

Sheet Spring Autumn
C2: Condenser Duty
C3: Qcond | D3: Edes | F3: To | G3: =Properties!$D$9 -> 273 | H3: K
B4: Total | C4: =SUM(C6:C677) -> 2439877.8 | D4: =SUM(D6:D677) -> 112088.43 | F4: Tcond | G4: =Properties!$D$10 -> 303 | H4: K
B5: Hours | C5: kWh | D5: kWh | F5: Tair | G5: =Properties!$F$14 -> 288.3 | H5: K
A6: =Winter!A9 -> 1 | B6: 1 | C6: 2346 | D6: =$G$3*C6*(1/$G$5-1/$G$4) -> 107.77567
A7: =Winter!A10 -> 2 | B7: 2 | C7: 2208 | D7: =$G$3*C7*(1/$G$5-1/$G$4) -> 101.43592
A8: =Winter!A11 -> 3 | B8: 3 | C8: 2346 | D8: =$G$3*C8*(1/$G$5-1/$G$4) -> 107.77567
A9: =Winter!A12 -> 4 | B9: 4 | C9: 2484 | D9: =$G$3*C9*(1/$G$5-1/$G$4) -> 114.11541
A10: =Winter!A13 -> 5 | B10: 5 | C10: 2829 | D10: =$G$3*C10*(1/$G$5-1/$G$4) -> 129.96477
A11: =Winter!A14 -> 6 | B11: 6 | C11: 3036 | D11: =$G$3*C11*(1/$G$5-1/$G$4) -> 139.47439
A12: =Winter!A15 -> 7 | B12: 7 | C12: 3243 | D12: =$G$3*C12*(1/$G$5-1/$G$4) -> 148.98401
A13: =Winter!A16 -> 8 | B13: 8 | C13: 3450 | D13: =$G$3*C13*(1/$G$5-1/$G$4) -> 158.49363
A14: =Winter!A17 -> 9 | B14: 9 | C14: 3657 | D14: =$G$3*C14*(1/$G$5-1/$G$4) -> 168.00325
A15: =Winter!A18 -> 10 | B15: 10 | C15: 3864 | D15: =$G$3*C15*(1/$G$5-1/$G$4) -> 177.51286
A16: =Winter!A19 -> 11 | B16: 11 | C16: 4071 | D16: =$G$3*C16*(1/$G$5-1/$G$4) -> 187.02248
A17: =Winter!A20 -> 12 | B17: 12 | C17: 4278 | D17: =$G$3*C17*(1/$G$5-1/$G$4) -> 196.5321
... A173: =Winter!A176 -> 168 | B173: 168 | C173: 3036 | D173: =$G$3*C173*(1/$G$5-1/$G$4) -> 139.47439
A174: =Winter!A177 -> 1 | B174: 169 | C174: =C6 -> 2346 | D174: =$G$3*C174*(1/$G$5-1/$G$4) -> 107.77567
A175: =Winter!A178 -> 2 | B175: 170 | C175: =C7 -> 2208 | D175: =$G$3*C175*(1/$G$5-1/$G$4) -> 101.43592
A176: =Winter!A179 -> 3 | B176: 171 | C176: =C8 -> 2346 | D176: =$G$3*C176*(1/$G$5-1/$G$4) -> 107.77567
A177: =Winter!A180 -> 4 | B177: 172 | C177: =C9 -> 2484 | D177: =$G$3*C177*(1/$G$5-1/$G$4) -> 114.11541
A178: =Winter!A181 -> 5 | B178: 173 | C178: =C10 -> 2829 | D178: =$G$3*C178*(1/$G$5-1/$G$4) -> 129.96477
A179: =Winter!A182 -> 6 | B179: 174 | C179: =C11 -> 3036 | D179: =$G$3*C179*(1/$G$5-1/$G$4) -> 139.47439
A180: =Winter!A183 -> 7 | B180: 175 | C180: =C12 -> 3243 | D180: =$G$3*C180*(1/$G$5-1/$G$4) -> 148.98401
A181: =Winter!A184 -> 8 | B181: 176 | C181: =C13 -> 3450 | D181: =$G$3*C181*(1/$G$5-1/$G$4) -> 158.49363
A182: =Winter!A185 -> 9 | B182: 177 | C182: =C14 -> 3657 | D182: =$G$3*C182*(1/$G$5-1/$G$4) -> 168.00325
A183: =Winter!A186 -> 10 | B183: 178 | C183: =C15 -> 3864 | D183: =$G$3*C183*(1/$G$5-1/$G$4) -> 177.51286
A184: =Winter!A187 -> 11 | B184: 179 | C184: =C16 -> 4071 | D184: =$G$3*C184*(1/$G$5-1/$G$4) -> 187.02248
A185: =Winter!A188 -> 12 | B185: 180 | C185: =C17 -> 4278 | D185: =$G$3*C185*(1/$G$5-1/$G$4) -> 196.5321
... A341: =Winter!A344 -> 168 | B341: 336 | C341: =C173 -> 3036 | D341: =$G$3*C341*(1/$G$5-1/$G$4) -> 139.47439
A342: =Winter!A345 -> 1 | B342: 337 | C342: =C6 -> 2346 | D342: =$G$3*C342*(1/$G$5-1/$G$4) -> 107.77567
A343: =Winter!A346 -> 2 | B343: 338 | C343: =C7 -> 2208 | D343: =$G$3*C343*(1/$G$5-1/$G$4) -> 101.43592
A344: =Winter!A347 -> 3 | B344: 339 | C344: =C8 -> 2346 | D344: =$G$3*C344*(1/$G$5-1/$G$4) -> 107.77567
A345: =Winter!A348 -> 4 | B345: 340 | C345: =C9 -> 2484 | D345: =$G$3*C345*(1/$G$5-1/$G$4) -> 114.11541
A346: =Winter!A349 -> 5 | B346: 341 | C346: =C10 -> 2829 | D346: =$G$3*C346*(1/$G$5-1/$G$4) -> 129.96477
A347: =Winter!A350 -> 6 | B347: 342 | C347: =C11 -> 3036 | D347: =$G$3*C347*(1/$G$5-1/$G$4) -> 139.47439
A348: =Winter!A351 -> 7 | B348: 343 | C348: =C12 -> 3243 | D348: =$G$3*C348*(1/$G$5-1/$G$4) -> 148.98401
A349: =Winter!A352 -> 8 | B349: 344 | C349: =C13 -> 3450 | D349: =$G$3*C349*(1/$G$5-1/$G$4) -> 158.49363
A350: =Winter!A353 -> 9 | B350: 345 | C350: =C14 -> 3657 | D350: =$G$3*C350*(1/$G$5-1/$G$4) -> 168.00325
A351: =Winter!A354 -> 10 | B351: 346 | C351: =C15 -> 3864 | D351: =$G$3*C351*(1/$G$5-1/$G$4) -> 177.51286
...

Sheet Summer
C2: Condenser Duty
C3: Qcond | D3: Edes | F3: To | G3: =Properties!$D$9 -> 273
B4: Total | C4: =SUM(C6:C677) -> 2657516.1 | D4: =SUM(D6:D677) -> 81719.989 | F4: Tcond | G4: =Properties!$D$10 -> 303 | I4: =H4+E4 -> 0
B5: Hours | C5: kWh | D5: kWh | F5: Tair | G5: =Properties!$H$14 -> 293
A6: =Winter!A9 -> 1 | B6: 1 | C6: 2550 | D6: =$G$3*C6*(1/$G$5-1/$G$4) -> 78.413814
A7: =Winter!A10 -> 2 | B7: 2 | C7: 2400 | D7: =$G$3*C7*(1/$G$5-1/$G$4) -> 73.801237
A8: =Winter!A11 -> 3 | B8: 3 | C8: 2550 | D8: =$G$3*C8*(1/$G$5-1/$G$4) -> 78.413814
A9: =Winter!A12 -> 4 | B9: 4 | C9: 2700 | D9: =$G$3*C9*(1/$G$5-1/$G$4) -> 83.026391
A10: =Winter!A13 -> 5 | B10: 5 | C10: 3075 | D10: =$G$3*C10*(1/$G$5-1/$G$4) -> 94.557835
A11: =Winter!A14 -> 6 | B11: 6 | C11: 3300 | D11: =$G$3*C11*(1/$G$5-1/$G$4) -> 101.4767
A12: =Winter!A15 -> 7 | B12: 7 | C12: 3525 | D12: =$G$3*C12*(1/$G$5-1/$G$4) -> 108.39557
A13: =Winter!A16 -> 8 | B13: 8 | C13: 3750 | D13: =$G$3*C13*(1/$G$5-1/$G$4) -> 115.31443
A14: =Winter!A17 -> 9 | B14: 9 | C14: 3975 | D14: =$G$3*C14*(1/$G$5-1/$G$4) -> 122.2333
A15: =Winter!A18 -> 10 | B15: 10 | C15: 4200 | D15: =$G$3*C15*(1/$G$5-1/$G$4) -> 129.15216
A16: =Winter!A19 -> 11 | B16: 11 | C16: 4425 | D16: =$G$3*C16*(1/$G$5-1/$G$4) -> 136.07103
A17: =Winter!A20 -> 12 | B17: 12 | C17: 4650 | D17: =$G$3*C17*(1/$G$5-1/$G$4) -> 142.9899
... A173: =Winter!A176 -> 168 | B173: 168 | C173: 3300 | D173: =$G$3*C173*(1/$G$5-1/$G$4) -> 101.4767
A174: =Winter!A177 -> 1 | B174: 169 | C174: =C11 -> 3300 | D174: =$G$3*C174*(1/$G$5-1/$G$4) -> 101.4767
A175: =Winter!A178 -> 2 | B175: 170 | C175: =C12 -> 3525 | D175: =$G$3*C175*(1/$G$5-1/$G$4) -> 108.39557
A176: =Winter!A179 -> 3 | B176: 171 | C176: =C13 -> 3750 | D176: =$G$3*C176*(1/$G$5-1/$G$4) -> 115.31443
A177: =Winter!A180 -> 4 | B177: 172 | C177: =C14 -> 3975 | D177: =$G$3*C177*(1/$G$5-1/$G$4) -> 122.2333
A178: =Winter!A181 -> 5 | B178: 173 | C178: =C15 -> 4200 | D178: =$G$3*C178*(1/$G$5-1/$G$4) -> 129.15216
A179: =Winter!A182 -> 6 | B179: 174 | C179: =C16 -> 4425 | D179: =$G$3*C179*(1/$G$5-1/$G$4) -> 136.07103
A180: =Winter!A183 -> 7 | B180: 175 | C180: =C17 -> 4650 | D180: =$G$3*C180*(1/$G$5-1/$G$4) -> 142.9899
A181: =Winter!A184 -> 8 | B181: 176 | C181: =C18 -> 4875 | D181: =$G$3*C181*(1/$G$5-1/$G$4) -> 149.90876
A182: =Winter!A185 -> 9 | B182: 177 | C182: =C19 -> 5100 | D182: =$G$3*C182*(1/$G$5-1/$G$4) -> 156.82763
A183: =Winter!A186 -> 10 | B183: 178 | C183: =C20 -> 4950 | D183: =$G$3*C183*(1/$G$5-1/$G$4) -> 152.21505
A184: =Winter!A187 -> 11 | B184: 179 | C184: =C21 -> 5150 | D184: =$G$3*C184*(1/$G$5-1/$G$4) -> 158.36515
A185: =Winter!A188 -> 12 | B185: 180 | C185: =C22 -> 5850 | D185: =$G$3*C185*(1/$G$5-1/$G$4) -> 179.89051
... A341: =Winter!A344 -> 168 | B341: 336 | C341: =C178 -> 4200 | D341: =$G$3*C341*(1/$G$5-1/$G$4) -> 129.15216
A342: =Winter!A345 -> 1 | B342: 337 | C342: =C6 -> 2550 | D342: =$G$3*C342*(1/$G$5-1/$G$4) -> 78.413814
A343: =Winter!A346 -> 2 | B343: 338 | C343: =C7 -> 2400 | D343: =$G$3*C343*(1/$G$5-1/$G$4) -> 73.801237
A344: =Winter!A347 -> 3 | B344: 339 | C344: =C8 -> 2550 | D344: =$G$3*C344*(1/$G$5-1/$G$4) -> 78.413814
A345: =Winter!A348 -> 4 | B345: 340 | C345: =C9 -> 2700 | D345: =$G$3*C345*(1/$G$5-1/$G$4) -> 83.026391
A346: =Winter!A349 -> 5 | B346: 341 | C346: =C10 -> 3075 | D346: =$G$3*C346*(1/$G$5-1/$G$4) -> 94.557835
A347: =Winter!A350 -> 6 | B347: 342 | C347: =C11 -> 3300 | D347: =$G$3*C347*(1/$G$5-1/$G$4) -> 101.4767
A348: =Winter!A351 -> 7 | B348: 343 | C348: =C12 -> 3525 | D348: =$G$3*C348*(1/$G$5-1/$G$4) -> 108.39557
A349: =Winter!A352 -> 8 | B349: 344 | C349: =C13 -> 3750 | D349: =$G$3*C349*(1/$G$5-1/$G$4) -> 115.31443
A350: =Winter!A353 -> 9 | B350: 345 | C350: =C14 -> 3975 | D350: =$G$3*C350*(1/$G$5-1/$G$4) -> 122.2333
A351: =Winter!A354 -> 10 | B351: 346 | C351: =C15 -> 4200 | D351: =$G$3*C351*(1/$G$5-1/$G$4) -> 129.15216
...
