Workbook
Name OLE_LINK2: 'Calcs Cold Sink Secondary Sid'!$C$4

Sheet DC Cooler Duty
D1: Hourly Power Demand Coefficient (from graph) | E1: =D1 -> Hourly Power Demand Coefficient (from graph) | F1: Summer Heat Rejection Coefficient | G1: Winter Heat Rejection Coefficient | I1: Data Centre Hourly Power Demand | J1: Hourly Cooler Duty Winter (75.6% of power demand) | L1: Hourly Heat Cooler Duty Spring/Autumn (82.8% of power demand) | N1: Hourly Cooler Duty Summer (90% of power demand)
A2: % values from literature | F2: 0.9 | G2: 0.16 | H2: =F2*(1-G2) -> 0.756 | J2: =H2 -> 0.756 | L2: =(N2+J2)/2 -> 0.828 | N2: =F2 -> 0.9
A3: Max DC Demand (MW) | B3: My input | E3: 7 | F3: =E3*F2 -> 6.3 | G3: =E3*F2*(1-G2) -> 5.292 | I3: MWh | J3: MWh | K3: GJ/s | L3: =J3 -> MWh | M3: =K3 -> GJ/s | N3: MWh | O3: GJ/s
A4: Max Coeff | B4: From row E | E4: =MAX(E8:E175) -> 2.1 | F4: =MAX(F8:F175) -> 1.89 | G4: =MAX(G8:G175) -> 1.5876 | H4: Checksum
A5: Coeff to Demand Multiplier | E5: =E3/E4 -> 3.3333333 | F5: =F3/F4 -> 3.3333333 | G5: =G3/G4 -> 3.3333333 | H5: =F4*F5 -> 6.3 | I5: =G5*G4 -> 5.292
H6: =MAX(H8:H175) -> 1.5876 | I6: =MAX(I8:I175) -> 7
A7: Hours | H7: MWh/week | I7: =SUM(I8:I175) -> 736.67807 | J7: =SUM(J8:J175) -> 556.92862 | K7: =SUM(K8:K175) -> 2004.943 | L7: =SUM(L8:L175) -> 609.96945 | M7: =SUM(M8:M175) -> 0 | N7: =SUM(N8:N175) -> 663.01027 | O7: =SUM(O8:O175) -> 2386.837
A8: 1 | B8: =MOD(((A8-1)),24) -> 0 | C8: Monday | D8: 0.85 | E8: 0.85 | F8: =E8*$F$2 -> 0.765 | G8: =(1-$G$2)*F8 -> 0.6426 | H8: =$H$2*E8 -> 0.6426 | I8: =E8*$E$5 -> 2.8333333 | J8: =I8*$H$2 -> 2.142 | K8: =J8*3.6 -> 7.7112 | L8: =I8*$L$2 -> 2.346 | N8: =$F$2*I8 -> 2.55 | O8: =N8*3.6 -> 9.18
A9: 2 | B9: =MOD(((A9-1)),24) -> 1 | C9: Monday | D9: 0.8 | E9: 0.8 | F9: =E9*$F$2 -> 0.72 | G9: =(1-$G$2)*F9 -> 0.6048 | H9: =$H$2*E9 -> 0.6048 | I9: =E9*$E$5 -> 2.6666667 | J9: =I9*$H$2 -> 2.016 | K9: =J9*3.6 -> 7.2576 | L9: =I9*$L$2 -> 2.208 | N9: =$F$2*I9 -> 2.4 | O9: =N9*3.6 -> 8.64
A10: 3 | B10: =MOD(((A10-1)),24) -> 2 | C10: Monday | D10: =($D$21-D9)/($A$21-A9)+D9 -> 0.875 | E10: 0.85 | F10: =E10*$F$2 -> 0.765 | G10: =(1-$G$2)*F10 -> 0.6426 | H10: =$H$2*E10 -> 0.6426 | I10: =E10*$E$5 -> 2.8333333 | J10: =I10*$H$2 -> 2.142 | K10: =J10*3.6 -> 7.7112 | L10: =I10*$L$2 -> 2.346 | N10: =$F$2*I10 -> 2.55 | O10: =N10*3.6 -> 9.18
A11: 4 | B11: =MOD(((A11-1)),24) -> 3 | C11: Monday | D11: =($D$21-D10)/($A$21-A10)+D10 -> 0.95 | E11: 0.9 | F11: =E11*$F$2 -> 0.81 | G11: =(1-$G$2)*F11 -> 0.6804 | H11: =$H$2*E11 -> 0.6804 | I11: =E11*$E$5 -> 3 | J11: =I11*$H$2 -> 2.268 | K11: =J11*3.6 -> 8.1648 | L11: =I11*$L$2 -> 2.484 | N11: =$F$2*I11 -> 2.7 | O11: =N11*3.6 -> 9.72
A12: 5 | B12: =MOD(((A12-1)),24) -> 4 | C12: Monday | D12: =($D$21-D11)/($A$21-A11)+D11 -> 1.025 | E12: 1.025 | F12: =E12*$F$2 -> 0.9225 | G12: =(1-$G$2)*F12 -> 0.7749 | H12: =$H$2*E12 -> 0.7749 | I12: =E12*$E$5 -> 3.4166667 | J12: =I12*$H$2 -> 2.583 | K12: =J12*3.6 -> 9.2988 | L12: =I12*$L$2 -> 2.829 | N12: =$F$2*I12 -> 3.075 | O12: =N12*3.6 -> 11.07
A13: 6 | B13: =MOD(((A13-1)),24) -> 5 | C13: Monday | D13: =($D$21-D12)/($A$21-A12)+D12 -> 1.1 | E13: 1.1 | F13: =E13*$F$2 -> 0.99 | G13: =(1-$G$2)*F13 -> 0.8316 | H13: =$H$2*E13 -> 0.8316 | I13: =E13*$E$5 -> 3.6666667 | J13: =I13*$H$2 -> 2.772 | K13: =J13*3.6 -> 9.9792 | L13: =I13*$L$2 -> 3.036 | N13: =$F$2*I13 -> 3.3 | O13: =N13*3.6 -> 11.88
A14: 7 | B14: =MOD(((A14-1)),24) -> 6 | C14: Monday | D14: =($D$21-D13)/($A$21-A13)+D13 -> 1.175 | E14: 1.175 | F14: =E14*$F$2 -> 1.0575 | G14: =(1-$G$2)*F14 -> 0.8883 | H14: =$H$2*E14 -> 0.8883 | I14: =E14*$E$5 -> 3.9166667 | J14: =I14*$H$2 -> 2.961 | K14: =J14*3.6 -> 10.6596 | L14: =I14*$L$2 -> 3.243 | N14: =$F$2*I14 -> 3.525 | O14: =N14*3.6 -> 12.69
A15: 8 | B15: =MOD(((A15-1)),24) -> 7 | C15: Monday | D15: =($D$21-D14)/($A$21-A14)+D14 -> 1.25 | E15: 1.25 | F15: =E15*$F$2 -> 1.125 | G15: =(1-$G$2)*F15 -> 0.945 | H15: =$H$2*E15 -> 0.945 | I15: =E15*$E$5 -> 4.1666667 | J15: =I15*$H$2 -> 3.15 | K15: =J15*3.6 -> 11.34 | L15: =I15*$L$2 -> 3.45 | N15: =$F$2*I15 -> 3.75 | O15: =N15*3.6 -> 13.5
A16: 9 | B16: =MOD(((A16-1)),24) -> 8 | C16: Monday | D16: =($D$21-D15)/($A$21-A15)+D15 -> 1.325 | E16: 1.325 | F16: =E16*$F$2 -> 1.1925 | G16: =(1-$G$2)*F16 -> 1.0017 | H16: =$H$2*E16 -> 1.0017 | I16: =E16*$E$5 -> 4.4166667 | J16: =I16*$H$2 -> 3.339 | K16: =J16*3.6 -> 12.0204 | L16: =I16*$L$2 -> 3.657 | N16: =$F$2*I16 -> 3.975 | O16: =N16*3.6 -> 14.31
A17: 10 | B17: =MOD(((A17-1)),24) -> 9 | C17: Monday | D17: =($D$21-D16)/($A$21-A16)+D16 -> 1.4 | E17: 1.4 | F17: =E17*$F$2 -> 1.26 | G17: =(1-$G$2)*F17 -> 1.0584 | H17: =$H$2*E17 -> 1.0584 | I17: =E17*$E$5 -> 4.6666667 | J17: =I17*$H$2 -> 3.528 | K17: =J17*3.6 -> 12.7008 | L17: =I17*$L$2 -> 3.864 | N17: =$F$2*I17 -> 4.2 | O17: =N17*3.6 -> 15.12
A18: 11 | B18: =MOD(((A18-1)),24) -> 10 | C18: Monday | D18: =($D$21-D17)/($A$21-A17)+D17 -> 1.475 | E18: 1.475 | F18: =E18*$F$2 -> 1.3275 | G18: =(1-$G$2)*F18 -> 1.1151 | H18: =$H$2*E18 -> 1.1151 | I18: =E18*$E$5 -> 4.9166667 | J18: =I18*$H$2 -> 3.717 | K18: =J18*3.6 -> 13.3812 | L18: =I18*$L$2 -> 4.071 | N18: =$F$2*I18 -> 4.425 | O18: =N18*3.6 -> 15.93
A19: 12 | B19: =MOD(((A19-1)),24) -> 11 | C19: Monday | D19: =($D$21-D18)/($A$21-A18)+D18 -> 1.55 | E19: 1.55 | F19: =E19*$F$2 -> 1.395 | G19: =(1-$G$2)*F19 -> 1.1718 | H19: =$H$2*E19 -> 1.1718 | I19: =E19*$E$5 -> 5.1666667 | J19: =I19*$H$2 -> 3.906 | K19: =J19*3.6 -> 14.0616 | L19: =I19*$L$2 -> 4.278 | N19: =$F$2*I19 -> 4.65 | O19: =N19*3.6 -> 16.74
A20: 13 | B20: =MOD(((A20-1)),24) -> 12 | C20: Monday | D20: =($D$21-D19)/($A$21-A19)+D19 -> 1.625 | E20: 1.625 | F20: =E20*$F$2 -> 1.4625 | G20: =(1-$G$2)*F20 -> 1.2285 | H20: =$H$2*E20 -> 1.2285 | I20: =E20*$E$5 -> 5.4166667 | J20: =I20*$H$2 -> 4.095 | K20: =J20*3.6 -> 14.742 | L20: =I20*$L$2 -> 4.485 | N20: =$F$2*I20 -> 4.875 | O20: =N20*3.6 -> 17.55
A21: 14 | B21: =MOD(((A21-1)),24) -> 13 | C21: Monday | D21: 1.7 | E21: 1.7 | F21: =E21*$F$2 -> 1.53 | G21: =(1-$G$2)*F21 -> 1.2852 | H21: =$H$2*E21 -> 1.2852 | I21: =E21*$E$5 -> 5.6666667 | J21: =I21*$H$2 -> 4.284 | K21: =J21*3.6 -> 15.4224 | L21: =I21*$L$2 -> 4.692 | N21: =$F$2*I21 -> 5.1 | O21: =N21*3.6 -> 18.36
A22: 15 | B22: =MOD(((A22-1)),24) -> 14 | C22: Monday | D22: 1.65 | E22: 1.65 | F22: =E22*$F$2 -> 1.485 | G22: =(1-$G$2)*F22 -> 1.2474 | H22: =$H$2*E22 -> 1.2474 | I22: =E22*$E$5 -> 5.5 | J22: =I22*$H$2 -> 4.158 | K22: =J22*3.6 -> 14.9688 | L22: =I22*$L$2 -> 4.554 | N22: =$F$2*I22 -> 4.95 | O22: =N22*3.6 -> 17.82
A23: 16 | B23: =MOD(((A23-1)),24) -> 15 | C23: Monday | D23: =($D$28-D22)/($A$28-A22)+D22 -> 1.7166667 | E23: 1.7166667 | F23: =E23*$F$2 -> 1.545 | G23: =(1-$G$2)*F23 -> 1.2978 | H23: =$H$2*E23 -> 1.2978 | I23: =E23*$E$5 -> 5.7222222 | J23: =I23*$H$2 -> 4.326 | K23: =J23*3.6 -> 15.5736 | L23: =I23*$L$2 -> 4.738 | N23: =$F$2*I23 -> 5.15 | O23: =N23*3.6 -> 18.54
A24: 17 | B24: =MOD(((A24-1)),24) -> 16 | C24: Monday | D24: =($D$28-D23)/($A$28-A23)+D23 -> 1.7833333 | E24: 1.95 | F24: =E24*$F$2 -> 1.755 | G24: =(1-$G$2)*F24 -> 1.4742 | H24: =$H$2*E24 -> 1.4742 | I24: =E24*$E$5 -> 6.5 | J24: =I24*$H$2 -> 4.914 | K24: =J24*3.6 -> 17.6904 | L24: =I24*$L$2 -> 5.382 | N24: =$F$2*I24 -> 5.85 | O24: =N24*3.6 -> 21.06
A25: 18 | B25: =MOD(((A25-1)),24) -> 17 | C25: Monday | D25: =($D$28-D24)/($A$28-A24)+D24 -> 1.85 | E25: 1.9 | F25: =E25*$F$2 -> 1.71 | G25: =(1-$G$2)*F25 -> 1.4364 | H25: =$H$2*E25 -> 1.4364 | I25: =E25*$E$5 -> 6.3333333 | J25: =I25*$H$2 -> 4.788 | K25: =J25*3.6 -> 17.2368 | L25: =I25*$L$2 -> 5.244 | N25: =$F$2*I25 -> 5.7 | O25: =N25*3.6 -> 20.52
A26: 19 | B26: =MOD(((A26-1)),24) -> 18 | C26: Monday | D26: =($D$28-D25)/($A$28-A25)+D25 -> 1.9166667 | E26: 2 | F26: =E26*$F$2 -> 1.8 | G26: =(1-$G$2)*F26 -> 1.512 | H26: =$H$2*E26 -> 1.512 | I26: =E26*$E$5 -> 6.6666667 | J26: =I26*$H$2 -> 5.04 | K26: =J26*3.6 -> 18.144 | L26: =I26*$L$2 -> 5.52 | N26: =$F$2*I26 -> 6 | O26: =N26*3.6 -> 21.6
A27: 20 | B27: =MOD(((A27-1)),24) -> 19 | C27: Monday | D27: =($D$28-D26)/($A$28-A26)+D26 -> 1.9833333 | E27: 1.9 | F27: =E27*$F$2 -> 1.71 | G27: =(1-$G$2)*F27 -> 1.4364 | H27: =$H$2*E27 -> 1.4364 | I27: =E27*$E$5 -> 6.3333333 | J27: =I27*$H$2 -> 4.788 | K27: =J27*3.6 -> 17.2368 | L27: =I27*$L$2 -> 5.244 | N27: =$F$2*I27 -> 5.7 | O27: =N27*3.6 -> 20.52
A28: 21 | B28: =MOD(((A28-1)),24) -> 20 | C28: Monday | D28: 2.05 | E28: 2.05 | F28: =E28*$F$2 -> 1.845 | G28: =(1-$G$2)*F28 -> 1.5498 | H28: =$H$2*E28 -> 1.5498 | I28: =E28*$E$5 -> 6.8333333 | J28: =I28*$H$2 -> 5.166 | K28: =J28*3.6 -> 18.5976 | L28: =I28*$L$2 -> 5.658 | N28: =$F$2*I28 -> 6.15 | O28: =N28*3.6 -> 22.14
A29: 22 | B29: =MOD(((A29-1)),24) -> 21 | C29: Monday | D29: =($D$33-D28)/($A$33-A28)+D28 -> 1.8 | E29: 1.8 | F29: =E29*$F$2 -> 1.62 | G29: =(1-$G$2)*F29 -> 1.3608 | H29: =$H$2*E29 -> 1.3608 | I29: =E29*$E$5 -> 6 | J29: =I29*$H$2 -> 4.536 | K29: =J29*3.6 -> 16.3296 | L29: =I29*$L$2 -> 4.968 | N29: =$F$2*I29 -> 5.4 | O29: =N29*3.6 -> 19.44
A30: 23 | B30: =MOD(((A30-1)),24) -> 22 | C30: Monday | D30: =($D$33-D29)/($A$33-A29)+D29 -> 1.55 | E30: 1.55 | F30: =E30*$F$2 -> 1.395 | G30: =(1-$G$2)*F30 -> 1.1718 | H30: =$H$2*E30 -> 1.1718 | I30: =E30*$E$5 -> 5.1666667 | J30: =I30*$H$2 -> 3.906 | K30: =J30*3.6 -> 14.0616 | L30: =I30*$L$2 -> 4.278 | N30: =$F$2*I30 -> 4.65 | O30: =N30*3.6 -> 16.74
A31: 24 | B31: =MOD(((A31-1)),24) -> 23 | C31: Monday | D31: =($D$33-D30)/($A$33-A30)+D30 -> 1.3 | E31: 1.3 | F31: =E31*$F$2 -> 1.17 | G31: =(1-$G$2)*F31 -> 0.9828 | H31: =$H$2*E31 -> 0.9828 | I31: =E31*$E$5 -> 4.3333333 | J31: =I31*$H$2 -> 3.276 | K31: =J31*3.6 -> 11.7936 | L31: =I31*$L$2 -> 3.588 | N31: =$F$2*I31 -> 3.9 | O31: =N31*3.6 -> 14.04
A32: 25 | B32: =MOD(((A32-1)),24) -> 0 | C32: Tuesday | D32: =($D$33-D31)/($A$33-A31)+D31 -> 1.05 | E32: 0.85 | F32: =E32*$F$2 -> 0.765 | G32: =(1-$G$2)*F32 -> 0.6426 | H32: =$H$2*E32 -> 0.6426 | I32: =E32*$E$5 -> 2.8333333 | J32: =I32*$H$2 -> 2.142 | K32: =J32*3.6 -> 7.7112 | L32: =I32*$L$2 -> 2.346 | N32: =$F$2*I32 -> 2.55 | O32: =N32*3.6 -> 9.18
A33: 26 | B33: =MOD(((A33-1)),24) -> 1 | C33: =C32 -> Tuesday | D33: 0.8 | E33: 0.8 | F33: =E33*$F$2 -> 0.72 | G33: =(1-$G$2)*F33 -> 0.6048 | H33: =$H$2*E33 -> 0.6048 | I33: =E33*$E$5 -> 2.6666667 | J33: =I33*$H$2 -> 2.016 | K33: =J33*3.6 -> 7.2576 | L33: =I33*$L$2 -> 2.208 | N33: =$F$2*I33 -> 2.4 | O33: =N33*3.6 -> 8.64
A34: 27 | B34: =MOD(((A34-1)),24) -> 2 | C34: =C33 -> Tuesday | D34: =($D$47-D33)/($A$47-A33)+D33 -> 0.86428571 | E34: 0.86 | F34: =E34*$F$2 -> 0.774 | G34: =(1-$G$2)*F34 -> 0.65016 | H34: =$H$2*E34 -> 0.65016 | I34: =E34*$E$5 -> 2.8666667 | J34: =I34*$H$2 -> 2.1672 | K34: =J34*3.6 -> 7.80192 | L34: =I34*$L$2 -> 2.3736 | N34: =$F$2*I34 -> 2.58 | O34: =N34*3.6 -> 9.288
A35: 28 | B35: =MOD(((A35-1)),24) -> 3 | C35: =C34 -> Tuesday | D35: =($D$47-D34)/($A$47-A34)+D34 -> 0.92857143 | E35: 0.9 | F35: =E35*$F$2 -> 0.81 | G35: =(1-$G$2)*F35 -> 0.6804 | H35: =$H$2*E35 -> 0.6804 | I35: =E35*$E$5 -> 3 | J35: =I35*$H$2 -> 2.268 | K35: =J35*3.6 -> 8.1648 | L35: =I35*$L$2 -> 2.484 | N35: =$F$2*I35 -> 2.7 | O35: =N35*3.6 -> 9.72
A36: 29 | B36: =MOD(((A36-1)),24) -> 4 | C36: =C35 -> Tuesday | D36: =($D$47-D35)/($A$47-A35)+D35 -> 0.99285714 | E36: 0.99285714 | F36: =E36*$F$2 -> 0.89357143 | G36: =(1-$G$2)*F36 -> 0.7506 | H36: =$H$2*E36 -> 0.7506 | I36: =E36*$E$5 -> 3.3095238 | J36: =I36*$H$2 -> 2.502 | K36: =J36*3.6 -> 9.0072 | L36: =I36*$L$2 -> 2.7402857 | N36: =$F$2*I36 -> 2.9785714 | O36: =N36*3.6 -> 10.722857
A37: 30 | B37: =MOD(((A37-1)),24) -> 5 | C37: =C36 -> Tuesday | D37: =($D$47-D36)/($A$47-A36)+D36 -> 1.0571429 | E37: 1.0571429 | F37: =E37*$F$2 -> 0.95142857 | G37: =(1-$G$2)*F37 -> 0.7992 | H37: =$H$2*E37 -> 0.7992 | I37: =E37*$E$5 -> 3.5238095 | J37: =I37*$H$2 -> 2.664 | K37: =J37*3.6 -> 9.5904 | L37: =I37*$L$2 -> 2.9177143 | N37: =$F$2*I37 -> 3.1714286 | O37: =N37*3.6 -> 11.417143
A38: 31 | B38: =MOD(((A38-1)),24) -> 6 | C38: =C37 -> Tuesday | D38: =($D$47-D37)/($A$47-A37)+D37 -> 1.1214286 | E38: 1.1214286 | F38: =E38*$F$2 -> 1.0092857 | G38: =(1-$G$2)*F38 -> 0.8478 | H38: =$H$2*E38 -> 0.8478 | I38: =E38*$E$5 -> 3.7380952 | J38: =I38*$H$2 -> 2.826 | K38: =J38*3.6 -> 10.1736 | L38: =I38*$L$2 -> 3.0951429 | N38: =$F$2*I38 -> 3.3642857 | O38: =N38*3.6 -> 12.111429
A39: 32 | B39: =MOD(((A39-1)),24) -> 7 | C39: =C38 -> Tuesday | D39: =($D$47-D38)/($A$47-A38)+D38 -> 1.1857143 | E39: 1.1857143 | F39: =E39*$F$2 -> 1.0671429 | G39: =(1-$G$2)*F39 -> 0.8964 | H39: =$H$2*E39 -> 0.8964 | I39: =E39*$E$5 -> 3.952381 | J39: =I39*$H$2 -> 2.988 | K39: =J39*3.6 -> 10.7568 | L39: =I39*$L$2 -> 3.2725714 | N39: =$F$2*I39 -> 3.5571429 | O39: =N39*3.6 -> 12.805714
A40: 33 | B40: =MOD(((A40-1)),24) -> 8 | C40: =C39 -> Tuesday | D40: =($D$47-D39)/($A$47-A39)+D39 -> 1.25 | E40: 1.25 | F40: =E40*$F$2 -> 1.125 | G40: =(1-$G$2)*F40 -> 0.945 | H40: =$H$2*E40 -> 0.945 | I40: =E40*$E$5 -> 4.1666667 | J40: =I40*$H$2 -> 3.15 | K40: =J40*3.6 -> 11.34 | L40: =I40*$L$2 -> 3.45 | N40: =$F$2*I40 -> 3.75 | O40: =N40*3.6 -> 13.5
...

Sheet Thermal Store Sizing
B1: Daily Heat Release
B2: Winter | K2: Summer
B3: MWh/day | K3: =B3 -> MWh/day
A4: Monday | B4: =SUM('DC Cooler Duty'!J8:J31) -> 87.801 | K4: =SUM('DC Cooler Duty'!N8:N31) -> 104.525
A5: Tuesday | B5: =SUM('DC Cooler Duty'!J32:J55) -> 84.2112 | K5: =SUM('DC Cooler Duty'!N32:N55) -> 100.25143
A6: Wednesday | B6: =SUM('DC Cooler Duty'!J56:J79) -> 86.567815 | K6: =SUM('DC Cooler Duty'!N56:N79) -> 103.05692
A7: Thursday | B7: =SUM('DC Cooler Duty'!J80:J103) -> 79.9785 | K7: =SUM('DC Cooler Duty'!N80:N103) -> 95.2125
A8: Friday | B8: =SUM('DC Cooler Duty'!J104:J127) -> 73.102909 | K8: =SUM('DC Cooler Duty'!N104:N127) -> 87.027273
A9: Saturday | B9: =SUM('DC Cooler Duty'!J128:J151) -> 71.5572 | K9: =SUM('DC Cooler Duty'!N128:N151) -> 85.187143
A10: Sunday | B10: =SUM('DC Cooler Duty'!J152:J175) -> 73.71 | K10: =SUM('DC Cooler Duty'!N152:N175) -> 87.75
A11: Total | B11: =SUM(B4:B10) -> 556.92862 | K11: =SUM(K4:K10) -> 663.01027
A13: Max daily winter heat release | B13: Q | C13: =MAX(B4:B10) -> 87.801 | E13: MWh/day
C14: =C13*3600 -> 316083.6 | E14: MJ/day
A15: Thermal store operating temperature range | B15: dt | C15: 10 | E15: °K | G15: CheckSum
A16: Water specific heat capacity | B16: cp | C16: 4.18 | E16: kJ/kg°K | F16: MJ/t°K | G16: =C13*1000*3600 -> 3.160836e+08
A18: Thermal store mass | B18: m | C18: =C14/(C16*C15) -> 7561.8086 | E18: tonnes | F18: m = Q/(cp x dt) | G18: =G16/C16/C15 -> 7561808.6
A19: Equivalent volume | C19: =G18/1000 -> 7561.8086 | E19: m3 | F19: Cross reference with literature
A20: Cube side length | C20: =C19^(1/3) -> 19.627963 | E20: m

Sheet R410a Enthalpy
B1: Evaporator Temp | C1: 10 | D1: °C
B2: Condensor Temp | C2: 35 | D2: °C
B3: Superheat | C3: 5 | D3: °C
B4: Intercooler superheat (2') | C4: 2 | D4: °C
B5: Compressor Efficiency | C5: 0
E6: §
D8: Saturated | E8: Single Stage | F8: Two Stage
B9: Pc | C9: bar(a) | D9: 22 | E9: =D9 -> 22 | F9: =D9 -> 22
B10: Pi | C10: bar(a) | F10: =SQRT(F9*F11) -> 15.556349
B11: Pe | C11: bar(a) | D11: 11 | E11: =D11 -> 11 | F11: =D11 -> 11
B12: h6 | C12: kJ/kg | E12: 260 | F12: =E12 -> 260
B13: h5 | C13: kJ/kg | E13: =E12 -> 260 | F13: =E12 -> 260
B14: h4 | C14: kJ/kg | F14: 438
B15: h3 | C15: kJ/kg | E15: 448
B16: h2' | C16: =C15 -> kJ/kg | F16: 430
B17: h2 | C17: kJ/kg | F17: 439
B18: h1 | C18: kJ/kg | E18: 432 | F18: =E18 -> 432
B19: T2' | C19: °C | F19: 22
B20: T2 | C20: °C | F20: 29
B21: T1 | C21: °C | F21: =C1+C3 -> 15
B22: T4 | C22: °C | F22: 41
B23: CoPref | E23: =(E18-E12)/(E15-E18) -> 10.75 | F23: =(F18-F12)/((F17-F18)+(F14-F16)) -> 11.466667 | G23: =1-E23/F23 -> 0.0625

Sheet Winter Energy Calcs
B1: Winter Cooler Duty | C1: Refrigerant Mass Flow Rate | D1: Intercooler Heat Rejection | E1: Stage 1 Compressor Power | F1: Stage 2 Compressor Power | G1: Total Compressor Power | H1: Single Stage Compressor Power | I1: 2-Stage Improvement
C2: ṁ=Cooler Duty/(h1-h6) | D2: Qi=ṁ(h2-h2') | E2: Qcp1=ṁ(h1-h2) | F2: Qcp2=ṁ(h2'-h4) | G2: Qcp1+Qcp2
A3: Hours | B3: kJ/s | C3: kg/s | D3: kJ/s | E3: kJ/s | F3: kJ/s | G3: kJ/s | H3: kJ/s
A4: ='DC Cooler Duty'!A8 -> 1 | B4: ='DC Cooler Duty'!K8 -> 7.7112 | C4: =B4/('R410a Enthalpy'!$F$18-'R410a Enthalpy'!$F$12) -> 0.044832558 | D4: =C4*('R410a Enthalpy'!$F$17-'R410a Enthalpy'!$F$16) -> 0.40349302 | E4: =C4*('R410a Enthalpy'!$F$17-'R410a Enthalpy'!$F$18) -> 0.31382791 | F4: =C4*('R410a Enthalpy'!$F$14-'R410a Enthalpy'!$F$16) -> 0.35866047 | G4: =E4+F4 -> 0.67248837 | H4: =C4*('R410a Enthalpy'!$E$15-'R410a Enthalpy'!$E$18) -> 0.71732093 | I4: =1-(G4/H4) -> 0.0625
A5: ='DC Cooler Duty'!A9 -> 2 | B5: ='DC Cooler Duty'!K9 -> 7.2576 | C5: =B5/('R410a Enthalpy'!$F$18-'R410a Enthalpy'!$F$12) -> 0.042195349 | D5: =C5*('R410a Enthalpy'!$F$17-'R410a Enthalpy'!$F$16) -> 0.37975814 | E5: =C5*('R410a Enthalpy'!$F$17-'R410a Enthalpy'!$F$18) -> 0.29536744 | F5: =C5*('R410a Enthalpy'!$F$14-'R410a Enthalpy'!$F$16) -> 0.33756279 | G5: =E5+F5 -> 0.63293023 | H5: =C5*('R410a Enthalpy'!$E$15-'R410a Enthalpy'!$E$18) -> 0.67512558 | I5: =1-(G5/H5) -> 0.0625
A6: ='DC Cooler Duty'!A10 -> 3 | B6: ='DC Cooler Duty'!K10 -> 7.7112 | C6: =B6/('R410a Enthalpy'!$F$18-'R410a Enthalpy'!$F$12) -> 0.044832558 | D6: =C6*('R410a Enthalpy'!$F$17-'R410a Enthalpy'!$F$16) -> 0.40349302 | E6: =C6*('R410a Enthalpy'!$F$17-'R410a Enthalpy'!$F$18) -> 0.31382791 | F6: =C6*('R410a Enthalpy'!$F$14-'R410a Enthalpy'!$F$16) -> 0.35866047 | G6: =E6+F6 -> 0.67248837 | H6: =C6*('R410a Enthalpy'!$E$15-'R410a Enthalpy'!$E$18) -> 0.71732093 | I6: =1-(G6/H6) -> 0.0625
A7: ='DC Cooler Duty'!A11 -> 4 | B7: ='DC Cooler Duty'!K11 -> 8.1648 | C7: =B7/('R410a Enthalpy'!$F$18-'R410a Enthalpy'!$F$12) -> 0.047469767 | D7: =C7*('R410a Enthalpy'!$F$17-'R410a Enthalpy'!$F$16) -> 0.42722791 | E7: =C7*('R410a Enthalpy'!$F$17-'R410a Enthalpy'!$F$18) -> 0.33228837 | F7: =C7*('R410a Enthalpy'!$F$14-'R410a Enthalpy'!$F$16) -> 0.37975814 | G7: =E7+F7 -> 0.71204651 | H7: =C7*('R410a Enthalpy'!$E$15-'R410a Enthalpy'!$E$18) -> 0.75951628 | I7: =1-(G7/H7) -> 0.0625
A8: ='DC Cooler Duty'!A12 -> 5 | B8: ='DC Cooler Duty'!K12 -> 9.2988 | C8: =B8/('R410a Enthalpy'!$F$18-'R410a Enthalpy'!$F$12) -> 0.054062791 | D8: =C8*('R410a Enthalpy'!$F$17-'R410a Enthalpy'!$F$16) -> 0.48656512 | E8: =C8*('R410a Enthalpy'!$F$17-'R410a Enthalpy'!$F$18) -> 0.37843953 | F8: =C8*('R410a Enthalpy'!$F$14-'R410a Enthalpy'!$F$16) -> 0.43250233 | G8: =E8+F8 -> 0.81094186 | H8: =C8*('R410a Enthalpy'!$E$15-'R410a Enthalpy'!$E$18) -> 0.86500465 | I8: =1-(G8/H8) -> 0.0625
A9: ='DC Cooler Duty'!A13 -> 6 | B9: ='DC Cooler Duty'!K13 -> 9.9792 | C9: =B9/('R410a Enthalpy'!$F$18-'R410a Enthalpy'!$F$12) -> 0.058018605 | D9: =C9*('R410a Enthalpy'!$F$17-'R410a Enthalpy'!$F$16) -> 0.52216744 | E9: =C9*('R410a Enthalpy'!$F$17-'R410a Enthalpy'!$F$18) -> 0.40613023 | F9: =C9*('R410a Enthalpy'!$F$14-'R410a Enthalpy'!$F$16) -> 0.46414884 | G9: =E9+F9 -> 0.87027907 | H9: =C9*('R410a Enthalpy'!$E$15-'R410a Enthalpy'!$E$18) -> 0.92829767 | I9: =1-(G9/H9) -> 0.0625
A10: ='DC Cooler Duty'!A14 -> 7 | B10: ='DC Cooler Duty'!K14 -> 10.6596 | C10: =B10/('R410a Enthalpy'!$F$18-'R410a Enthalpy'!$F$12) -> 0.061974419 | D10: =C10*('R410a Enthalpy'!$F$17-'R410a Enthalpy'!$F$16) -> 0.55776977 | E10: =C10*('R410a Enthalpy'!$F$17-'R410a Enthalpy'!$F$18) -> 0.43382093 | F10: =C10*('R410a Enthalpy'!$F$14-'R410a Enthalpy'!$F$16) -> 0.49579535 | G10: =E10+F10 -> 0.92961628 | H10: =C10*('R410a Enthalpy'!$E$15-'R410a Enthalpy'!$E$18) -> 0.9915907 | I10: =1-(G10/H10) -> 0.0625
A11: ='DC Cooler Duty'!A15 -> 8 | B11: ='DC Cooler Duty'!K15 -> 11.34 | C11: =B11/('R410a Enthalpy'!$F$18-'R410a Enthalpy'!$F$12) -> 0.065930233 | D11: =C11*('R410a Enthalpy'!$F$17-'R410a Enthalpy'!$F$16) -> 0.59337209 | E11: =C11*('R410a Enthalpy'!$F$17-'R410a Enthalpy'!$F$18) -> 0.46151163 | F11: =C11*('R410a Enthalpy'!$F$14-'R410a Enthalpy'!$F$16) -> 0.52744186 | G11: =E11+F11 -> 0.98895349 | H11: =C11*('R410a Enthalpy'!$E$15-'R410a Enthalpy'!$E$18) -> 1.0548837 | I11: =1-(G11/H11) -> 0.0625
A12: ='DC Cooler Duty'!A16 -> 9 | B12: ='DC Cooler Duty'!K16 -> 12.0204 | C12: =B12/('R410a Enthalpy'!$F$18-'R410a Enthalpy'!$F$12) -> 0.069886047 | D12: =C12*('R410a Enthalpy'!$F$17-'R410a Enthalpy'!$F$16) -> 0.62897442 | E12: =C12*('R410a Enthalpy'!$F$17-'R410a Enthalpy'!$F$18) -> 0.48920233 | F12: =C12*('R410a Enthalpy'!$F$14-'R410a Enthalpy'!$F$16) -> 0.55908837 | G12: =E12+F12 -> 1.0482907 | H12: =C12*('R410a Enthalpy'!$E$15-'R410a Enthalpy'!$E$18) -> 1.1181767 | I12: =1-(G12/H12) -> 0.0625
A13: ='DC Cooler Duty'!A17 -> 10 | B13: ='DC Cooler Duty'!K17 -> 12.7008 | C13: =B13/('R410a Enthalpy'!$F$18-'R410a Enthalpy'!$F$12) -> 0.07384186 | D13: =C13*('R410a Enthalpy'!$F$17-'R410a Enthalpy'!$F$16) -> 0.66457674 | E13: =C13*('R410a Enthalpy'!$F$17-'R410a Enthalpy'!$F$18) -> 0.51689302 | F13: =C13*('R410a Enthalpy'!$F$14-'R410a Enthalpy'!$F$16) -> 0.59073488 | G13: =E13+F13 -> 1.1076279 | H13: =C13*('R410a Enthalpy'!$E$15-'R410a Enthalpy'!$E$18) -> 1.1814698 | I13: =1-(G13/H13) -> 0.0625
A14: ='DC Cooler Duty'!A18 -> 11 | B14: ='DC Cooler Duty'!K18 -> 13.3812 | C14: =B14/('R410a Enthalpy'!$F$18-'R410a Enthalpy'!$F$12) -> 0.077797674 | D14: =C14*('R410a Enthalpy'!$F$17-'R410a Enthalpy'!$F$16) -> 0.70017907 | E14: =C14*('R410a Enthalpy'!$F$17-'R410a Enthalpy'!$F$18) -> 0.54458372 | F14: =C14*('R410a Enthalpy'!$F$14-'R410a Enthalpy'!$F$16) -> 0.6223814 | G14: =E14+F14 -> 1.1669651 | H14: =C14*('R410a Enthalpy'!$E$15-'R410a Enthalpy'!$E$18) -> 1.2447628 | I14: =1-(G14/H14) -> 0.0625
A15: ='DC Cooler Duty'!A19 -> 12 | B15: ='DC Cooler Duty'!K19 -> 14.0616 | C15: =B15/('R410a Enthalpy'!$F$18-'R410a Enthalpy'!$F$12) -> 0.081753488 | D15: =C15*('R410a Enthalpy'!$F$17-'R410a Enthalpy'!$F$16) -> 0.7357814 | E15: =C15*('R410a Enthalpy'!$F$17-'R410a Enthalpy'!$F$18) -> 0.57227442 | F15: =C15*('R410a Enthalpy'!$F$14-'R410a Enthalpy'!$F$16) -> 0.65402791 | G15: =E15+F15 -> 1.2263023 | H15: =C15*('R410a Enthalpy'!$E$15-'R410a Enthalpy'!$E$18) -> 1.3080558 | I15: =1-(G15/H15) -> 0.0625
... A171: ='DC Cooler Duty'!A175 -> 168 | B171: ='DC Cooler Duty'!K175 -> 9.9792 | C171: =B171/('R410a Enthalpy'!$F$18-'R410a Enthalpy'!$F$12) -> 0.058018605 | D171: =C171*('R410a Enthalpy'!$F$17-'R410a Enthalpy'!$F$16) -> 0.52216744 | E171: =C171*('R410a Enthalpy'!$F$17-'R410a Enthalpy'!$F$18) -> 0.40613023 | F171: =C171*('R410a Enthalpy'!$F$14-'R410a Enthalpy'!$F$16) -> 0.46414884 | G171: =E171+F171 -> 0.87027907 | H171: =C171*('R410a Enthalpy'!$E$15-'R410a Enthalpy'!$E$18) -> 0.92829767 | I171: =1-(G171/H171) -> 0.0625

Sheet DC Cooler Heat Released
F2: Cooling Duty (MWh) | J2: Heat Released (MWh) | N2: DN250 max | O2: 6.13 | P2: MW
E3: Total | F3: =SUM(F10:F177) -> 556.92862 | G3: =SUM(G10:G177) -> 609.96945 | H3: =SUM(H10:H177) -> 663.01027 | J3: =SUM(J10:J177) -> 656.38016 | K3: =SUM(K10:K177) -> 705.63792 | L3: =SUM(L10:L177) -> 756.81867
E4: Max | F4: =MAX(F10:F177) -> 5.292 | G4: =MAX(G10:G177) -> 5.796 | H4: =MAX(H10:H177) -> 6.3 | J4: =MAX(J10:J177) -> 6.237 | K4: =MAX(K10:K177) -> 6.7050529 | L4: =MAX(L10:L177) -> 7.1913782
E5: Min | F5: =MIN(F10:F177) -> 2.016 | G5: =MIN(G10:G177) -> 2.208 | H5: =MIN(H10:H177) -> 2.4 | J5: =MIN(J10:J177) -> 2.376 | K5: =MIN(K10:K177) -> 2.5543059 | L5: =MIN(L10:L177) -> 2.7395727
E6: Average | F6: =AVERAGE(F10:F177) -> 3.3150513 | G6: =AVERAGE(G10:G177) -> 3.6307705 | H6: =AVERAGE(H10:H177) -> 3.9464897 | J6: =AVERAGE(J10:J177) -> 3.9070248 | K6: =AVERAGE(K10:K177) -> 4.2002257 | L6: =AVERAGE(L10:L177) -> 4.504873
I7: > max design | J7: =(COUNTIF(J10:J177,">6.13")) -> 1
J8: =J7/168 -> 0.005952381
B9: Count | C9: Day | D9: Time | E9: WE/WD | F9: Winter | G9: Spring/Autumn | H9: Summer | J9: =F9 -> Winter | K9: =G9 -> Spring/Autumn | L9: =H9 -> Summer
B10: 1 | C10: Wednesday | D10: 0 | E10: weekday | F10: ='DC Cooler Duty'!J8 -> 2.142 | G10: ='DC Cooler Duty'!L8 -> 2.346 | H10: ='DC Cooler Duty'!N8 -> 2.55 | J10: =F10+'DC Cooler Power '!E8 -> 2.5245 | K10: =G10+'DC Cooler Power '!F8 -> 2.71395 | L10: =H10+'DC Cooler Power '!G8 -> 2.910796
B11: 2 | C11: =C10 -> Wednesday | D11: 0.041666667 | E11: weekday | F11: ='DC Cooler Duty'!J9 -> 2.016 | G11: ='DC Cooler Duty'!L9 -> 2.208 | H11: ='DC Cooler Duty'!N9 -> 2.4 | J11: =F11+'DC Cooler Power '!E9 -> 2.376 | K11: =G11+'DC Cooler Power '!F9 -> 2.5543059 | L11: =H11+'DC Cooler Power '!G9 -> 2.7395727
B12: 3 | C12: =C11 -> Wednesday | D12: 0.083333333 | E12: weekday | F12: ='DC Cooler Duty'!J10 -> 2.142 | G12: ='DC Cooler Duty'!L10 -> 2.346 | H12: ='DC Cooler Duty'!N10 -> 2.55 | J12: =F12+'DC Cooler Power '!E10 -> 2.5245 | K12: =G12+'DC Cooler Power '!F10 -> 2.71395 | L12: =H12+'DC Cooler Power '!G10 -> 2.910796
B13: 4 | C13: =C12 -> Wednesday | D13: 0.125 | E13: weekday | F13: ='DC Cooler Duty'!J11 -> 2.268 | G13: ='DC Cooler Duty'!L11 -> 2.484 | H13: ='DC Cooler Duty'!N11 -> 2.7 | J13: =F13+'DC Cooler Power '!E11 -> 2.673 | K13: =G13+'DC Cooler Power '!F11 -> 2.8735941 | L13: =H13+'DC Cooler Power '!G11 -> 3.0820192
B14: 5 | C14: =C13 -> Wednesday | D14: 0.16666667 | E14: weekday | F14: ='DC Cooler Duty'!J12 -> 2.583 | G14: ='DC Cooler Duty'!L12 -> 2.829 | H14: ='DC Cooler Duty'!N12 -> 3.075 | J14: =F14+'DC Cooler Power '!E12 -> 3.04425 | K14: =G14+'DC Cooler Power '!F12 -> 3.2727044 | L14: =H14+'DC Cooler Power '!G12 -> 3.5100775
B15: 6 | C15: =C14 -> Wednesday | D15: 0.20833333 | E15: weekday | F15: ='DC Cooler Duty'!J13 -> 2.772 | G15: ='DC Cooler Duty'!L13 -> 3.036 | H15: ='DC Cooler Duty'!N13 -> 3.3 | J15: =F15+'DC Cooler Power '!E13 -> 3.267 | K15: =G15+'DC Cooler Power '!F13 -> 3.5121706 | L15: =H15+'DC Cooler Power '!G13 -> 3.7669124
B16: 7 | C16: =C15 -> Wednesday | D16: 0.25 | E16: weekday | F16: ='DC Cooler Duty'!J14 -> 2.961 | G16: ='DC Cooler Duty'!L14 -> 3.243 | H16: ='DC Cooler Duty'!N14 -> 3.525 | J16: =F16+'DC Cooler Power '!E14 -> 3.48975 | K16: =G16+'DC Cooler Power '!F14 -> 3.7516367 | L16: =H16+'DC Cooler Power '!G14 -> 4.0237474
B17: 8 | C17: =C16 -> Wednesday | D17: 0.29166667 | E17: weekday | F17: ='DC Cooler Duty'!J15 -> 3.15 | G17: ='DC Cooler Duty'!L15 -> 3.45 | H17: ='DC Cooler Duty'!N15 -> 3.75 | J17: =F17+'DC Cooler Power '!E15 -> 3.7125 | K17: =G17+'DC Cooler Power '!F15 -> 3.9911029 | L17: =H17+'DC Cooler Power '!G15 -> 4.2805823
B18: 9 | C18: =C17 -> Wednesday | D18: 0.33333333 | E18: weekday | F18: ='DC Cooler Duty'!J16 -> 3.339 | G18: ='DC Cooler Duty'!L16 -> 3.657 | H18: ='DC Cooler Duty'!N16 -> 3.975 | J18: =F18+'DC Cooler Power '!E16 -> 3.93525 | K18: =G18+'DC Cooler Power '!F16 -> 4.2305691 | L18: =H18+'DC Cooler Power '!G16 -> 4.5374172
B19: 10 | C19: =C18 -> Wednesday | D19: 0.375 | E19: weekday | F19: ='DC Cooler Duty'!J17 -> 3.528 | G19: ='DC Cooler Duty'!L17 -> 3.864 | H19: ='DC Cooler Duty'!N17 -> 4.2 | J19: =F19+'DC Cooler Power '!E17 -> 4.158 | K19: =G19+'DC Cooler Power '!F17 -> 4.4700353 | L19: =H19+'DC Cooler Power '!G17 -> 4.7942522
B20: 11 | C20: =C19 -> Wednesday | D20: 0.41666667 | E20: weekday | F20: ='DC Cooler Duty'!J18 -> 3.717 | G20: ='DC Cooler Duty'!L18 -> 4.071 | H20: ='DC Cooler Duty'!N18 -> 4.425 | J20: =F20+'DC Cooler Power '!E18 -> 4.38075 | K20: =G20+'DC Cooler Power '!F18 -> 4.7095014 | L20: =H20+'DC Cooler Power '!G18 -> 5.0510871
B21: 12 | C21: =C20 -> Wednesday | D21: 0.45833333 | E21: weekday | F21: ='DC Cooler Duty'!J19 -> 3.906 | G21: ='DC Cooler Duty'!L19 -> 4.278 | H21: ='DC Cooler Duty'!N19 -> 4.65 | J21: =F21+'DC Cooler Power '!E19 -> 4.6035 | K21: =G21+'DC Cooler Power '!F19 -> 4.9489676 | L21: =H21+'DC Cooler Power '!G19 -> 5.307922
B22: 13 | C22: =C21 -> Wednesday | D22: 0.5 | E22: weekday | F22: ='DC Cooler Duty'!J20 -> 4.095 | G22: ='DC Cooler Duty'!L20 -> 4.485 | H22: ='DC Cooler Duty'!N20 -> 4.875 | J22: =F22+'DC Cooler Power '!E20 -> 4.82625 | K22: =G22+'DC Cooler Power '!F20 -> 5.1884338 | L22: =H22+'DC Cooler Power '!G20 -> 5.564757
... B33: 24 | C33: =C32 -> Wednesday | D33: 0.95833333 | E33: weekday | F33: ='DC Cooler Duty'!J31 -> 3.276 | G33: ='DC Cooler Duty'!L31 -> 3.588 | H33: ='DC Cooler Duty'!N31 -> 3.9 | J33: =F33+'DC Cooler Power '!E31 -> 3.861 | K33: =G33+'DC Cooler Power '!F31 -> 4.150747 | L33: =H33+'DC Cooler Power '!G31 -> 4.4518056
B34: 25 | C34: Thursday | D34: 1 | E34: weekday | F34: ='DC Cooler Duty'!J32 -> 2.142 | G34: ='DC Cooler Duty'!L32 -> 2.346 | H34: ='DC Cooler Duty'!N32 -> 2.55 | J34: =F34+'DC Cooler Power '!E32 -> 2.5245 | K34: =G34+'DC Cooler Power '!F32 -> 2.71395 | L34: =H34+'DC Cooler Power '!G32 -> 2.910796
B35: 26 | C35: =C34 -> Thursday | D35: 1.0416667 | E35: weekday | F35: ='DC Cooler Duty'!J33 -> 2.016 | G35: ='DC Cooler Duty'!L33 -> 2.208 | H35: ='DC Cooler Duty'!N33 -> 2.4 | J35: =F35+'DC Cooler Power '!E33 -> 2.376 | K35: =G35+'DC Cooler Power '!F33 -> 2.5543059 | L35: =H35+'DC Cooler Power '!G33 -> 2.7395727
B36: 27 | C36: =C35 -> Thursday | D36: 1.0833333 | E36: weekday | F36: ='DC Cooler Duty'!J34 -> 2.1672 | G36: ='DC Cooler Duty'!L34 -> 2.3736 | H36: ='DC Cooler Duty'!N34 -> 2.58 | J36: =F36+'DC Cooler Power '!E34 -> 2.5542 | K36: =G36+'DC Cooler Power '!F34 -> 2.7458788 | L36: =H36+'DC Cooler Power '!G34 -> 2.9450406
B37: 28 | C37: =C36 -> Thursday | D37: 1.125 | E37: weekday | F37: ='DC Cooler Duty'!J35 -> 2.268 | G37: ='DC Cooler Duty'!L35 -> 2.484 | H37: ='DC Cooler Duty'!N35 -> 2.7 | J37: =F37+'DC Cooler Power '!E35 -> 2.673 | K37: =G37+'DC Cooler Power '!F35 -> 2.8735941 | L37: =H37+'DC Cooler Power '!G35 -> 3.0820192
B38: 29 | C38: =C37 -> Thursday | D38: 1.1666667 | E38: weekday | F38: ='DC Cooler Duty'!J36 -> 2.502 | G38: ='DC Cooler Duty'!L36 -> 2.7402857 | H38: ='DC Cooler Duty'!N36 -> 2.9785714 | J38: =F38+'DC Cooler Power '!E36 -> 2.9487857 | K38: =G38+'DC Cooler Power '!F36 -> 3.170076 | L38: =H38+'DC Cooler Power '!G36 -> 3.4000054
B39: 30 | C39: =C38 -> Thursday | D39: 1.2083333 | E39: weekday | F39: ='DC Cooler Duty'!J37 -> 2.664 | G39: ='DC Cooler Duty'!L37 -> 2.9177143 | H39: ='DC Cooler Duty'!N37 -> 3.1714286 | J39: =F39+'DC Cooler Power '!E37 -> 3.1397143 | K39: =G39+'DC Cooler Power '!F37 -> 3.3753327 | L39: =H39+'DC Cooler Power '!G37 -> 3.6201496
B40: 31 | C40: =C39 -> Thursday | D40: 1.25 | E40: weekday | F40: ='DC Cooler Duty'!J38 -> 2.826 | G40: ='DC Cooler Duty'!L38 -> 3.0951429 | H40: ='DC Cooler Duty'!N38 -> 3.3642857 | J40: =F40+'DC Cooler Power '!E38 -> 3.3306429 | K40: =G40+'DC Cooler Power '!F38 -> 3.5805895 | L40: =H40+'DC Cooler Power '!G38 -> 3.8402938
B41: 32 | C41: =C40 -> Thursday | D41: 1.2916667 | E41: weekday | F41: ='DC Cooler Duty'!J39 -> 2.988 | G41: ='DC Cooler Duty'!L39 -> 3.2725714 | H41: ='DC Cooler Duty'!N39 -> 3.5571429 | J41: =F41+'DC Cooler Power '!E39 -> 3.5215714 | K41: =G41+'DC Cooler Power '!F39 -> 3.7858462 | L41: =H41+'DC Cooler Power '!G39 -> 4.0604381
B42: 33 | C42: =C41 -> Thursday | D42: 1.3333333 | E42: weekday | F42: ='DC Cooler Duty'!J40 -> 3.15 | G42: ='DC Cooler Duty'!L40 -> 3.45 | H42: ='DC Cooler Duty'!N40 -> 3.75 | J42: =F42+'DC Cooler Power '!E40 -> 3.7125 | K42: =G42+'DC Cooler Power '!F40 -> 3.9911029 | L42: =H42+'DC Cooler Power '!G40 -> 4.2805823
B43: 34 | C43: =C42 -> Thursday | D43: 1.375 | E43: weekday | F43: ='DC Cooler Duty'!J41 -> 3.312 | G43: ='DC Cooler Duty'!L41 -> 3.6274286 | H43: ='DC Cooler Duty'!N41 -> 3.9428571 | J43: =F43+'DC Cooler Power '!E41 -> 3.9034286 | K43: =G43+'DC Cooler Power '!F41 -> 4.1963596 | L43: =H43+'DC Cooler Power '!G41 -> 4.5007265
B44: 35 | C44: =C43 -> Thursday | D44: 1.4166667 | E44: weekday | F44: ='DC Cooler Duty'!J42 -> 3.474 | G44: ='DC Cooler Duty'!L42 -> 3.8048571 | H44: ='DC Cooler Duty'!N42 -> 4.1357143 | J44: =F44+'DC Cooler Power '!E42 -> 4.0943571 | K44: =G44+'DC Cooler Power '!F42 -> 4.4016164 | L44: =H44+'DC Cooler Power '!G42 -> 4.7208708
B45: 36 | C45: =C44 -> Thursday | D45: 1.4583333 | E45: weekday | F45: ='DC Cooler Duty'!J43 -> 3.636 | G45: ='DC Cooler Duty'!L43 -> 3.9822857 | H45: ='DC Cooler Duty'!N43 -> 4.3285714 | J45: =F45+'DC Cooler Power '!E43 -> 4.2852857 | K45: =G45+'DC Cooler Power '!F43 -> 4.6068731 | L45: =H45+'DC Cooler Power '!G43 -> 4.941015
B46: 37 | C46: =C45 -> Thursday | D46: 1.5 | E46: weekday | F46: ='DC Cooler Duty'!J44 -> 3.798 | G46: ='DC Cooler Duty'!L44 -> 4.1597143 | H46: ='DC Cooler Duty'!N44 -> 4.5214286 | J46: =F46+'DC Cooler Power '!E44 -> 4.4762143 | K46: =G46+'DC Cooler Power '!F44 -> 4.8121298 | L46: =H46+'DC Cooler Power '!G44 -> 5.1611592
... B57: 48 | C57: =C56 -> Thursday | D57: 1.9583333 | E57: weekday | F57: ='DC Cooler Duty'!J55 -> 3.276 | G57: ='DC Cooler Duty'!L55 -> 3.588 | H57: ='DC Cooler Duty'!N55 -> 3.9 | J57: =F57+'DC Cooler Power '!E55 -> 3.861 | K57: =G57+'DC Cooler Power '!F55 -> 4.150747 | L57: =H57+'DC Cooler Power '!G55 -> 4.4518056
B58: 49 | C58: Friday | D58: 2 | E58: weekday | F58: ='DC Cooler Duty'!J56 -> 2.142 | G58: ='DC Cooler Duty'!L56 -> 2.346 | H58: ='DC Cooler Duty'!N56 -> 2.55 | J58: =F58+'DC Cooler Power '!E56 -> 2.5245 | K58: =G58+'DC Cooler Power '!F56 -> 2.71395 | L58: =H58+'DC Cooler Power '!G56 -> 2.910796
B59: 50 | C59: =C58 -> Friday | D59: 2.0416667 | E59: weekday | F59: ='DC Cooler Duty'!J57 -> 2.016 | G59: ='DC Cooler Duty'!L57 -> 2.208 | H59: ='DC Cooler Duty'!N57 -> 2.4 | J59: =F59+'DC Cooler Power '!E57 -> 2.376 | K59: =G59+'DC Cooler Power '!F57 -> 2.5543059 | L59: =H59+'DC Cooler Power '!G57 -> 2.7395727
B60: 51 | C60: =C59 -> Friday | D60: 2.0833333 | E60: weekday | F60: ='DC Cooler Duty'!J58 -> 2.142 | G60: ='DC Cooler Duty'!L58 -> 2.346 | H60: ='DC Cooler Duty'!N58 -> 2.55 | J60: =F60+'DC Cooler Power '!E58 -> 2.5245 | K60: =G60+'DC Cooler Power '!F58 -> 2.71395 | L60: =H60+'DC Cooler Power '!G58 -> 2.910796
B61: 52 | C61: =C60 -> Friday | D61: 2.125 | E61: weekday | F61: ='DC Cooler Duty'!J59 -> 2.268 | G61: ='DC Cooler Duty'!L59 -> 2.484 | H61: ='DC Cooler Duty'!N59 -> 2.7 | J61: =F61+'DC Cooler Power '!E59 -> 2.673 | K61: =G61+'DC Cooler Power '!F59 -> 2.8735941 | L61: =H61+'DC Cooler Power '!G59 -> 3.0820192
...

Sheet DC Cooler Power 
A1: Data Centre Refrigerator Compressor Electricity Consumption, P (MWh)
E2: P =Qh/(CoP+1)
E3: Winter | F3: Spring/Autumn | G3: Summer
D4: CoP (from Home Heat Demand) | E4: ='[1]Degree-days'!$C$30 -> 4.6 | F4: ='[1]Degree-days'!$D$30 -> 5.3758667 | G4: ='[1]Degree-days'!$E$29 -> 6.0677067
D5: Total (MWh per week) | E5: =SUM(E8:E175) -> 99.45154 | F5: =SUM(F8:F175) -> 95.668476 | G5: =SUM(G8:G175) -> 93.808402
D6: Max | E6: =MAX(E8:E175) -> 0.945 | F6: =MAX(F8:F175) -> 0.90905289 | G6: =MAX(G8:G175) -> 0.89137825
A7: Count | B7: ='DC Cooler Heat Released'!C9 -> Day | C7: ='DC Cooler Heat Released'!D9 -> Time | D7: ='DC Cooler Heat Released'!E9 -> WE/WD | E7: (MWh)
A8: 1 | B8: ='DC Cooler Heat Released'!C10 -> Wednesday | C8: ='DC Cooler Heat Released'!D10 -> 0 | D8: ='DC Cooler Heat Released'!E10 -> weekday | E8: ='DC Cooler Heat Released'!F10/('DC Cooler Power '!$E$4+1) -> 0.3825 | F8: ='DC Cooler Heat Released'!G10/('DC Cooler Power '!$F$4+1) -> 0.36794998 | G8: ='DC Cooler Heat Released'!H10/($G$4+1) -> 0.36079596
A9: 2 | B9: ='DC Cooler Heat Released'!C11 -> Wednesday | C9: ='DC Cooler Heat Released'!D11 -> 0.041666667 | D9: ='DC Cooler Heat Released'!E11 -> weekday | E9: ='DC Cooler Heat Released'!F11/('DC Cooler Power '!$E$4+1) -> 0.36 | F9: ='DC Cooler Heat Released'!G11/('DC Cooler Power '!$F$4+1) -> 0.34630586 | G9: ='DC Cooler Heat Released'!H11/($G$4+1) -> 0.33957267
A10: 3 | B10: ='DC Cooler Heat Released'!C12 -> Wednesday | C10: ='DC Cooler Heat Released'!D12 -> 0.083333333 | D10: ='DC Cooler Heat Released'!E12 -> weekday | E10: ='DC Cooler Heat Released'!F12/('DC Cooler Power '!$E$4+1) -> 0.3825 | F10: ='DC Cooler Heat Released'!G12/('DC Cooler Power '!$F$4+1) -> 0.36794998 | G10: ='DC Cooler Heat Released'!H12/($G$4+1) -> 0.36079596
A11: 4 | B11: ='DC Cooler Heat Released'!C13 -> Wednesday | C11: ='DC Cooler Heat Released'!D13 -> 0.125 | D11: ='DC Cooler Heat Released'!E13 -> weekday | E11: ='DC Cooler Heat Released'!F13/('DC Cooler Power '!$E$4+1) -> 0.405 | F11: ='DC Cooler Heat Released'!G13/('DC Cooler Power '!$F$4+1) -> 0.38959409 | G11: ='DC Cooler Heat Released'!H13/($G$4+1) -> 0.38201925
A12: 5 | B12: ='DC Cooler Heat Released'!C14 -> Wednesday | C12: ='DC Cooler Heat Released'!D14 -> 0.16666667 | D12: ='DC Cooler Heat Released'!E14 -> weekday | E12: ='DC Cooler Heat Released'!F14/('DC Cooler Power '!$E$4+1) -> 0.46125 | F12: ='DC Cooler Heat Released'!G14/('DC Cooler Power '!$F$4+1) -> 0.44370439 | G12: ='DC Cooler Heat Released'!H14/($G$4+1) -> 0.43507748
A13: 6 | B13: ='DC Cooler Heat Released'!C15 -> Wednesday | C13: ='DC Cooler Heat Released'!D15 -> 0.20833333 | D13: ='DC Cooler Heat Released'!E15 -> weekday | E13: ='DC Cooler Heat Released'!F15/('DC Cooler Power '!$E$4+1) -> 0.495 | F13: ='DC Cooler Heat Released'!G15/('DC Cooler Power '!$F$4+1) -> 0.47617056 | G13: ='DC Cooler Heat Released'!H15/($G$4+1) -> 0.46691242
A14: 7 | B14: ='DC Cooler Heat Released'!C16 -> Wednesday | C14: ='DC Cooler Heat Released'!D16 -> 0.25 | D14: ='DC Cooler Heat Released'!E16 -> weekday | E14: ='DC Cooler Heat Released'!F16/('DC Cooler Power '!$E$4+1) -> 0.52875 | F14: ='DC Cooler Heat Released'!G16/('DC Cooler Power '!$F$4+1) -> 0.50863673 | G14: ='DC Cooler Heat Released'!H16/($G$4+1) -> 0.49874735
A15: 8 | B15: ='DC Cooler Heat Released'!C17 -> Wednesday | C15: ='DC Cooler Heat Released'!D17 -> 0.29166667 | D15: ='DC Cooler Heat Released'!E17 -> weekday | E15: ='DC Cooler Heat Released'!F17/('DC Cooler Power '!$E$4+1) -> 0.5625 | F15: ='DC Cooler Heat Released'!G17/('DC Cooler Power '!$F$4+1) -> 0.54110291 | G15: ='DC Cooler Heat Released'!H17/($G$4+1) -> 0.53058229
A16: 9 | B16: ='DC Cooler Heat Released'!C18 -> Wednesday | C16: ='DC Cooler Heat Released'!D18 -> 0.33333333 | D16: ='DC Cooler Heat Released'!E18 -> weekday | E16: ='DC Cooler Heat Released'!F18/('DC Cooler Power '!$E$4+1) -> 0.59625 | F16: ='DC Cooler Heat Released'!G18/('DC Cooler Power '!$F$4+1) -> 0.57356908 | G16: ='DC Cooler Heat Released'!H18/($G$4+1) -> 0.56241723
A17: 10 | B17: ='DC Cooler Heat Released'!C19 -> Wednesday | C17: ='DC Cooler Heat Released'!D19 -> 0.375 | D17: ='DC Cooler Heat Released'!E19 -> weekday | E17: ='DC Cooler Heat Released'!F19/('DC Cooler Power '!$E$4+1) -> 0.63 | F17: ='DC Cooler Heat Released'!G19/('DC Cooler Power '!$F$4+1) -> 0.60603526 | G17: ='DC Cooler Heat Released'!H19/($G$4+1) -> 0.59425217
A18: 11 | B18: ='DC Cooler Heat Released'!C20 -> Wednesday | C18: ='DC Cooler Heat Released'!D20 -> 0.41666667 | D18: ='DC Cooler Heat Released'!E20 -> weekday | E18: ='DC Cooler Heat Released'!F20/('DC Cooler Power '!$E$4+1) -> 0.66375 | F18: ='DC Cooler Heat Released'!G20/('DC Cooler Power '!$F$4+1) -> 0.63850143 | G18: ='DC Cooler Heat Released'!H20/($G$4+1) -> 0.6260871
A19: 12 | B19: ='DC Cooler Heat Released'!C21 -> Wednesday | C19: ='DC Cooler Heat Released'!D21 -> 0.45833333 | D19: ='DC Cooler Heat Released'!E21 -> weekday | E19: ='DC Cooler Heat Released'!F21/('DC Cooler Power '!$E$4+1) -> 0.6975 | F19: ='DC Cooler Heat Released'!G21/('DC Cooler Power '!$F$4+1) -> 0.67096761 | G19: ='DC Cooler Heat Released'!H21/($G$4+1) -> 0.65792204
... A175: 168 | B175: ='DC Cooler Heat Released'!C177 -> Tueday | C175: ='DC Cooler Heat Released'!D177 -> 6.9583333 | D175: ='DC Cooler Heat Released'!E177 -> weekday | E175: ='DC Cooler Heat Released'!F177/('DC Cooler Power '!$E$4+1) -> 0.495 | F175: ='DC Cooler Heat Released'!G177/('DC Cooler Power '!$F$4+1) -> 0.47617056 | G175: ='DC Cooler Heat Released'!H177/($G$4+1) -> 0.46691242
D176: Total | E176: =SUM(E8:E175) -> 99.45154 | F176: =SUM(F8:F175) -> 95.668476 | G176: =SUM(G8:G175) -> 93.808402

Sheet Four-Weekly Cooler Duty & Power
A1: Simulink Work Space File | C1: DCHrW | D1: DCHrS_A | E1: DCHrS | F1: DC_CpW | G1: DC_CpS_A | H1: DC_CpS
C2: Four Weekly Demand (kWh per 672 hours)
C3: Cooler Duty (kWh) | F3: Chiller Compressor Power (kWh) | J3: Combined Duty and Compressor Power (kWh)
I4: Total | J4: =SUM(J6:J677) -> 2625520.7 | K4: =SUM(K6:K677) -> 2822551.7 | L4: =SUM(L6:L677) -> 3027274.7
B5: Hour | C5: =[2]HomeHeatDemand!I2 -> Winter | D5: =[2]HomeHeatDemand!J2 -> Spring/Autumn | E5: =[2]HomeHeatDemand!K2 -> Summer | F5: =C5 -> Winter | G5: =D5 -> Spring/Autumn | H5: =E5 -> Summer | J5: =C5 -> Winter | K5: =D5 -> Spring/Autumn | L5: =E5 -> Summer
A6: 1 | B6: {=_xlfn.SEQUENCE(672)} -> 1 | C6: ='DC Cooler Duty'!J8*1000 -> 2142 | D6: ='DC Cooler Duty'!L8*1000 -> 2346 | E6: ='DC Cooler Duty'!N8*1000 -> 2550 | F6: ='DC Cooler Power '!E8*1000 -> 382.5 | G6: ='DC Cooler Power '!F8*1000 -> 367.94998 | H6: ='DC Cooler Power '!G8*1000 -> 360.79596 | J6: =C6+F6 -> 2524.5 | K6: =D6+G6 -> 2713.95 | L6: =E6+H6 -> 2910.796
A7: 2 | B7: 2 | C7: ='DC Cooler Duty'!J9*1000 -> 2016 | D7: ='DC Cooler Duty'!L9*1000 -> 2208 | E7: ='DC Cooler Duty'!N9*1000 -> 2400 | F7: ='DC Cooler Power '!E9*1000 -> 360 | G7: ='DC Cooler Power '!F9*1000 -> 346.30586 | H7: ='DC Cooler Power '!G9*1000 -> 339.57267 | J7: =C7+F7 -> 2376 | K7: =D7+G7 -> 2554.3059 | L7: =E7+H7 -> 2739.5727
A8: 3 | B8: 3 | C8: ='DC Cooler Duty'!J10*1000 -> 2142 | D8: ='DC Cooler Duty'!L10*1000 -> 2346 | E8: ='DC Cooler Duty'!N10*1000 -> 2550 | F8: ='DC Cooler Power '!E10*1000 -> 382.5 | G8: ='DC Cooler Power '!F10*1000 -> 367.94998 | H8: ='DC Cooler Power '!G10*1000 -> 360.79596 | J8: =C8+F8 -> 2524.5 | K8: =D8+G8 -> 2713.95 | L8: =E8+H8 -> 2910.796
A9: 4 | B9: 4 | C9: ='DC Cooler Duty'!J11*1000 -> 2268 | D9: ='DC Cooler Duty'!L11*1000 -> 2484 | E9: ='DC Cooler Duty'!N11*1000 -> 2700 | F9: ='DC Cooler Power '!E11*1000 -> 405 | G9: ='DC Cooler Power '!F11*1000 -> 389.59409 | H9: ='DC Cooler Power '!G11*1000 -> 382.01925 | J9: =C9+F9 -> 2673 | K9: =D9+G9 -> 2873.5941 | L9: =E9+H9 -> 3082.0192
A10: 5 | B10: 5 | C10: ='DC Cooler Duty'!J12*1000 -> 2583 | D10: ='DC Cooler Duty'!L12*1000 -> 2829 | E10: ='DC Cooler Duty'!N12*1000 -> 3075 | F10: ='DC Cooler Power '!E12*1000 -> 461.25 | G10: ='DC Cooler Power '!F12*1000 -> 443.70439 | H10: ='DC Cooler Power '!G12*1000 -> 435.07748 | J10: =C10+F10 -> 3044.25 | K10: =D10+G10 -> 3272.7044 | L10: =E10+H10 -> 3510.0775
A11: 6 | B11: 6 | C11: ='DC Cooler Duty'!J13*1000 -> 2772 | D11: ='DC Cooler Duty'!L13*1000 -> 3036 | E11: ='DC Cooler Duty'!N13*1000 -> 3300 | F11: ='DC Cooler Power '!E13*1000 -> 495 | G11: ='DC Cooler Power '!F13*1000 -> 476.17056 | H11: ='DC Cooler Power '!G13*1000 -> 466.91242 | J11: =C11+F11 -> 3267 | K11: =D11+G11 -> 3512.1706 | L11: =E11+H11 -> 3766.9124
A12: 7 | B12: 7 | C12: ='DC Cooler Duty'!J14*1000 -> 2961 | D12: ='DC Cooler Duty'!L14*1000 -> 3243 | E12: ='DC Cooler Duty'!N14*1000 -> 3525 | F12: ='DC Cooler Power '!E14*1000 -> 528.75 | G12: ='DC Cooler Power '!F14*1000 -> 508.63673 | H12: ='DC Cooler Power '!G14*1000 -> 498.74735 | J12: =C12+F12 -> 3489.75 | K12: =D12+G12 -> 3751.6367 | L12: =E12+H12 -> 4023.7474
A13: 8 | B13: 8 | C13: ='DC Cooler Duty'!J15*1000 -> 3150 | D13: ='DC Cooler Duty'!L15*1000 -> 3450 | E13: ='DC Cooler Duty'!N15*1000 -> 3750 | F13: ='DC Cooler Power '!E15*1000 -> 562.5 | G13: ='DC Cooler Power '!F15*1000 -> 541.10291 | H13: ='DC Cooler Power '!G15*1000 -> 530.58229 | J13: =C13+F13 -> 3712.5 | K13: =D13+G13 -> 3991.1029 | L13: =E13+H13 -> 4280.5823
A14: 9 | B14: 9 | C14: ='DC Cooler Duty'!J16*1000 -> 3339 | D14: ='DC Cooler Duty'!L16*1000 -> 3657 | E14: ='DC Cooler Duty'!N16*1000 -> 3975 | F14: ='DC Cooler Power '!E16*1000 -> 596.25 | G14: ='DC Cooler Power '!F16*1000 -> 573.56908 | H14: ='DC Cooler Power '!G16*1000 -> 562.41723 | J14: =C14+F14 -> 3935.25 | K14: =D14+G14 -> 4230.5691 | L14: =E14+H14 -> 4537.4172
A15: 10 | B15: 10 | C15: ='DC Cooler Duty'!J17*1000 -> 3528 | D15: ='DC Cooler Duty'!L17*1000 -> 3864 | E15: ='DC Cooler Duty'!N17*1000 -> 4200 | F15: ='DC Cooler Power '!E17*1000 -> 630 | G15: ='DC Cooler Power '!F17*1000 -> 606.03526 | H15: ='DC Cooler Power '!G17*1000 -> 594.25217 | J15: =C15+F15 -> 4158 | K15: =D15+G15 -> 4470.0353 | L15: =E15+H15 -> 4794.2522
A16: 11 | B16: 11 | C16: ='DC Cooler Duty'!J18*1000 -> 3717 | D16: ='DC Cooler Duty'!L18*1000 -> 4071 | E16: ='DC Cooler Duty'!N18*1000 -> 4425 | F16: ='DC Cooler Power '!E18*1000 -> 663.75 | G16: ='DC Cooler Power '!F18*1000 -> 638.50143 | H16: ='DC Cooler Power '!G18*1000 -> 626.0871 | J16: =C16+F16 -> 4380.75 | K16: =D16+G16 -> 4709.5014 | L16: =E16+H16 -> 5051.0871
A17: 12 | B17: 12 | C17: ='DC Cooler Duty'!J19*1000 -> 3906 | D17: ='DC Cooler Duty'!L19*1000 -> 4278 | E17: ='DC Cooler Duty'!N19*1000 -> 4650 | F17: ='DC Cooler Power '!E19*1000 -> 697.5 | G17: ='DC Cooler Power '!F19*1000 -> 670.96761 | H17: ='DC Cooler Power '!G19*1000 -> 657.92204 | J17: =C17+F17 -> 4603.5 | K17: =D17+G17 -> 4948.9676 | L17: =E17+H17 -> 5307.922
A18: 13 | B18: 13 | C18: ='DC Cooler Duty'!J20*1000 -> 4095 | D18: ='DC Cooler Duty'!L20*1000 -> 4485 | E18: ='DC Cooler Duty'!N20*1000 -> 4875 | F18: ='DC Cooler Power '!E20*1000 -> 731.25 | G18: ='DC Cooler Power '!F20*1000 -> 703.43378 | H18: ='DC Cooler Power '!G20*1000 -> 689.75698 | J18: =C18+F18 -> 4826.25 | K18: =D18+G18 -> 5188.4338 | L18: =E18+H18 -> 5564.757
... A173: 168 | B173: 168 | C173: ='DC Cooler Duty'!J175*1000 -> 2772 | D173: ='DC Cooler Duty'!L175*1000 -> 3036 | E173: ='DC Cooler Duty'!N175*1000 -> 3300 | F173: ='DC Cooler Power '!E175*1000 -> 495 | G173: ='DC Cooler Power '!F175*1000 -> 476.17056 | H173: ='DC Cooler Power '!G175*1000 -> 466.91242 | J173: =C173+F173 -> 3267 | K173: =D173+G173 -> 3512.1706 | L173: =E173+H173 -> 3766.9124
A174: 1 | B174: 169 | C174: =C6 -> 2142 | D174: =D6 -> 2346 | E174: =E6 -> 2550 | F174: =F6 -> 382.5 | G174: =G6 -> 367.94998 | H174: =H6 -> 360.79596 | J174: =C174+F174 -> 2524.5 | K174: =D174+G174 -> 2713.95 | L174: =E174+H174 -> 2910.796
A175: 2 | B175: 170 | C175: =C7 -> 2016 | D175: =D7 -> 2208 | E175: =E7 -> 2400 | F175: =F7 -> 360 | G175: =G7 -> 346.30586 | H175: =H7 -> 339.57267 | J175: =C175+F175 -> 2376 | K175: =D175+G175 -> 2554.3059 | L175: =E175+H175 -> 2739.5727
A176: 3 | B176: 171 | C176: =C8 -> 2142 | D176: =D8 -> 2346 | E176: =E8 -> 2550 | F176: =F8 -> 382.5 | G176: =G8 -> 367.94998 | H176: =H8 -> 360.79596 | J176: =C176+F176 -> 2524.5 | K176: =D176+G176 -> 2713.95 | L176: =E176+H176 -> 2910.796
A177: 4 | B177: 172 | C177: =C9 -> 2268 | D177: =D9 -> 2484 | E177: =E9 -> 2700 | F177: =F9 -> 405 | G177: =G9 -> 389.59409 | H177: =H9 -> 382.01925 | J177: =C177+F177 -> 2673 | K177: =D177+G177 -> 2873.5941 | L177: =E177+H177 -> 3082.0192
A178: 5 | B178: 173 | C178: =C10 -> 2583 | D178: =D10 -> 2829 | E178: =E10 -> 3075 | F178: =F10 -> 461.25 | G178: =G10 -> 443.70439 | H178: =H10 -> 435.07748 | J178: =C178+F178 -> 3044.25 | K178: =D178+G178 -> 3272.7044 | L178: =E178+H178 -> 3510.0775
A179: 6 | B179: 174 | C179: =C11 -> 2772 | D179: =D11 -> 3036 | E179: =E11 -> 3300 | F179: =F11 -> 495 | G179: =G11 -> 476.17056 | H179: =H11 -> 466.91242 | J179: =C179+F179 -> 3267 | K179: =D179+G179 -> 3512.1706 | L179: =E179+H179 -> 3766.9124
A180: 7 | B180: 175 | C180: =C12 -> 2961 | D180: =D12 -> 3243 | E180: =E12 -> 3525 | F180: =F12 -> 528.75 | G180: =G12 -> 508.63673 | H180: =H12 -> 498.74735 | J180: =C180+F180 -> 3489.75 | K180: =D180+G180 -> 3751.6367 | L180: =E180+H180 -> 4023.7474
A181: 8 | B181: 176 | C181: =C13 -> 3150 | D181: =D13 -> 3450 | E181: =E13 -> 3750 | F181: =F13 -> 562.5 | G181: =G13 -> 541.10291 | H181: =H13 -> 530.58229 | J181: =C181+F181 -> 3712.5 | K181: =D181+G181 -> 3991.1029 | L181: =E181+H181 -> 4280.5823
A182: 9 | B182: 177 | C182: =C14 -> 3339 | D182: =D14 -> 3657 | E182: =E14 -> 3975 | F182: =F14 -> 596.25 | G182: =G14 -> 573.56908 | H182: =H14 -> 562.41723 | J182: =C182+F182 -> 3935.25 | K182: =D182+G182 -> 4230.5691 | L182: =E182+H182 -> 4537.4172
A183: 10 | B183: 178 | C183: =C15 -> 3528 | D183: =D15 -> 3864 | E183: =E15 -> 4200 | F183: =F15 -> 630 | G183: =G15 -> 606.03526 | H183: =H15 -> 594.25217 | J183: =C183+F183 -> 4158 | K183: =D183+G183 -> 4470.0353 | L183: =E183+H183 -> 4794.2522
A184: 11 | B184: 179 | C184: =C16 -> 3717 | D184: =D16 -> 4071 | E184: =E16 -> 4425 | F184: =F16 -> 663.75 | G184: =G16 -> 638.50143 | H184: =H16 -> 626.0871 | J184: =C184+F184 -> 4380.75 | K184: =D184+G184 -> 4709.5014 | L184: =E184+H184 -> 5051.0871
A185: 12 | B185: 180 | C185: =C17 -> 3906 | D185: =D17 -> 4278 | E185: =E17 -> 4650 | F185: =F17 -> 697.5 | G185: =G17 -> 670.96761 | H185: =H17 -> 657.92204 | J185: =C185+F185 -> 4603.5 | K185: =D185+G185 -> 4948.9676 | L185: =E185+H185 -> 5307.922
... A341: 168 | B341: 336 | C341: =C173 -> 2772 | D341: =D173 -> 3036 | E341: =E173 -> 3300 | F341: =F173 -> 495 | G341: =G173 -> 476.17056 | H341: =H173 -> 466.91242 | J341: =C341+F341 -> 3267 | K341: =D341+G341 -> 3512.1706 | L341: =E341+H341 -> 3766.9124
A342: 1 | B342: 337 | C342: =C6 -> 2142 | D342: =D6 -> 2346 | E342: =E6 -> 2550 | F342: =F6 -> 382.5 | G342: =G6 -> 367.94998 | H342: =H6 -> 360.79596 | J342: =C342+F342 -> 2524.5 | K342: =D342+G342 -> 2713.95 | L342: =E342+H342 -> 2910.796
A343: 2 | B343: 338 | C343: =C7 -> 2016 | D343: =D7 -> 2208 | E343: =E7 -> 2400 | F343: =F7 -> 360 | G343: =G7 -> 346.30586 | H343: =H7 -> 339.57267 | J343: =C343+F343 -> 2376 | K343: =D343+G343 -> 2554.3059 | L343: =E343+H343 -> 2739.5727
A344: 3 | B344: 339 | C344: =C8 -> 2142 | D344: =D8 -> 2346 | E344: =E8 -> 2550 | F344: =F8 -> 382.5 | G344: =G8 -> 367.94998 | H344: =H8 -> 360.79596 | J344: =C344+F344 -> 2524.5 | K344: =D344+G344 -> 2713.95 | L344: =E344+H344 -> 2910.796
A345: 4 | B345: 340 | C345: =C9 -> 2268 | D345: =D9 -> 2484 | E345: =E9 -> 2700 | F345: =F9 -> 405 | G345: =G9 -> 389.59409 | H345: =H9 -> 382.01925 | J345: =C345+F345 -> 2673 | K345: =D345+G345 -> 2873.5941 | L345: =E345+H345 -> 3082.0192
A346: 5 | B346: 341 | C346: =C10 -> 2583 | D346: =D10 -> 2829 | E346: =E10 -> 3075 | F346: =F10 -> 461.25 | G346: =G10 -> 443.70439 | H346: =H10 -> 435.07748 | J346: =C346+F346 -> 3044.25 | K346: =D346+G346 -> 3272.7044 | L346: =E346+H346 -> 3510.0775
A347: 6 | B347: 342 | C347: =C11 -> 2772 | D347: =D11 -> 3036 | E347: =E11 -> 3300 | F347: =F11 -> 495 | G347: =G11 -> 476.17056 | H347: =H11 -> 466.91242 | J347: =C347+F347 -> 3267 | K347: =D347+G347 -> 3512.1706 | L347: =E347+H347 -> 3766.9124
A348: 7 | B348: 343 | C348: =C12 -> 2961 | D348: =D12 -> 3243 | E348: =E12 -> 3525 | F348: =F12 -> 528.75 | G348: =G12 -> 508.63673 | H348: =H12 -> 498.74735 | J348: =C348+F348 -> 3489.75 | K348: =D348+G348 -> 3751.6367 | L348: =E348+H348 -> 4023.7474
A349: 8 | B349: 344 | C349: =C13 -> 3150 | D349: =D13 -> 3450 | E349: =E13 -> 3750 | F349: =F13 -> 562.5 | G349: =G13 -> 541.10291 | H349: =H13 -> 530.58229 | J349: =C349+F349 -> 3712.5 | K349: =D349+G349 -> 3991.1029 | L349: =E349+H349 -> 4280.5823
...

Sheet Split Condenser
B1: Condenser
B2: Total Heat Released | C2: Qactual | D2: kW | E2: 5900
B3: Total Mass Flow Rate | D3: kg/s | E3: 141.01
B4: Water Specific Heat | C4: cp, cwater | D4: kJ/kg·K | E4: 4.181
B5: Overall Heat Transfer Coefficient | C5: U | D5: kW/m2·K | E5: 1
B6: Primary Side Condenser Inlet Temperature | D6: °C | E6: 30
E8: First Stage | F8: Second Stage | G8: Initial Value
B9: Secondary Side Mass Flow Rate | D9: kg/s | E9: 94 | F9: 38.439429 | G9: =E3-E9 -> 47.01
B10: Secondary Side Stage Inlet Temperature | D10: °C | E10: 20 | F10: 10
B11: Heat Transfer Area | C11: A | D11: m2 | E11: 500 | F11: 500
B12: Minimum Heat Capacity Rate | C12: Cmin | D12: kJ/s·K | E12: =E9*$E$4 -> 393.014 | F12: =F9*E4 -> 160.71525
B13: Number of Transfer Units | C13: UA/Cmin | D13: NTU | E13: =E11*$E$5/E12 -> 1.2722193 | F13: =F11*$E$5/F12 -> 3.1110924
B14: Effectiveness | C14: Ɛ | E14: =1-EXP(-E13) -> 0.71979094 | F14: =1-EXP(-F13) -> 0.95544774
B15: ƐCmin | E15: =E14*E12 -> 282.88792 | F15: =F14*F12 -> 153.55502
B16: Qc actual | D16: kW | E16: =E14*E12*(E6-E10) -> 2828.8792 | F16: =F14*F12*(E6-F10) -> 3071.1005 | G16: =E2-E16 -> 3071.1208
E17: Check Sum | F17: =SUM(E16:F16) -> 5899.9796

Sheet Split Evaporator
B1: Evaporator | I1: Side Calculation
B2: Total Heat Released | C2: Qactual | D2: kW | E2: 7200 | I2: Heat Released | J2: 2733704 | K2: =IF(J2=(J3+J4), TRUE, FALSE) -> TRUE
B3: Total Mass Flow Rate | D3: kg/s | E3: 141.01 | I3: Heat to Hot Sink | J3: 2113975 | K3: =J3/J2 -> 0.77330062
B4: Water Specific Heat | C4: cp, cwater | D4: kJ/kg·K | E4: 4.181 | I4: Heat to Cold Sink | J4: 619729 | K4: =J4/J2 -> 0.22669938
B5: Overall Heat Transfer Coefficient | C5: U | D5: kW/m2·K | E5: 1
B6: Primary Side Evaporator Inlet Temperature | D6: °C | E6: 5 | I6: HP Heat Demand | J6: 2412546 | K6: =IF(J6=(J7+J8), TRUE, FALSE) -> TRUE
I7: HP Hot Sink Supply | J7: 380256 | K7: =J7/J6 -> 0.15761606
E8: First Stage | F8: Second Stage | G8: Initial Value | I8: HP Cold Sink Supply | J8: 2032290 | K8: =J8/J6 -> 0.84238394
B9: Secondary Side Mass Flow Rate | D9: kg/s | E9: 40 | F9: 369.00871 | G9: =E3-E9 -> 101.01
B10: Secondary Side Stage Inlet Temperature | D10: °C | E10: 10 | F10: 20
B11: Heat Transfer Area | C11: A | D11: m2 | E11: 500 | F11: 500
B12: Minimum Heat Capacity Rate | C12: Cmin | D12: kJ/s·K | E12: =E9*$E$4 -> 167.24 | F12: =F9*E4 -> 1542.8254
B13: Number of Transfer Units | C13: UA/Cmin | D13: NTU | E13: =E11*$E$5/E12 -> 2.9897154 | F13: =F11*$E$5/F12 -> 0.32408074
B14: Effectiveness | C14: Ɛ | E14: =1-EXP(-E13) -> 0.94969825 | F14: =1-EXP(-F13) -> 0.27680815
B15: ƐCmin | E15: =E14*E12 -> 158.82754 | F15: =F14*F12 -> 427.06665
B16: Qc actual | D16: kW | E16: =E14*E12*(E10-E6) -> 794.13768 | F16: =F14*F12*(F10-E6) -> 6405.9997 | G16: =E2-E16 -> 6405.8623
E17: Check Sum | F17: =SUM(E16:F16) -> 7200.1374

Sheet NTU Calcs
E3: Tc, in
E5: Condenser overall heat transfer coefficient | F5: U | G5: W/m2.k | H5: 1400
B6: (kJ/s°K) | E6: Heat exchanger heat transfer area | F6: A | G6: m2 | H6: 1500
E7: Secondary-side water mass flow rate | F7: ṁ | G7: kg/s | H7: 146.1
E8: Water specific heat capcity | F8: cp | G8: KJ/kg.K | H8: 4.181
E9: Hot network temperature rise | F9: K | G9: °K | H9: 10
E11: Calculations
E12: Water heat capacity rate | F12: Cmin | G12: KJ/s∙K | H12: =H7*H8 -> 610.8441
E13: NTU | F13: NTU | H13: =H5*H6/H12/1000 -> 3.4378657
E14: Effectiveness | F14: Ɛ | H14: =1-EXP(H13*-1) -> 0.96786681
E15: Heat transfer | F15: Qch actual | G15: MW | H15: =H14*H7*H8*H9/1000 -> 5.9121573
H16: =H7*H8*H9/1000 -> 6.108441

Sheet Calcs Cold Sink Secondary Sid
O1: =SUM(O6743) -> 138156.7 | P1: 138160 | Q1: 138160 | R1: 138156
O2: 0
D3: =D10 -> HP Evaporator Secondary Side Flow Rate (kg/s)
C4: Qc Qh | D4: 10 | F4: 20 | H4: 30 | J4: 40 | L4: 50 | O4: 7.2194789e-08
B5: =B12 -> Condenser Secondary Side Flow Rate (kg/s) | C5: 10 | D5: 0 | E5: 151941 | F5: 3202 | G5: 131849 | H5: 0 | I5: 138157 | J5: 2118 | K5: 116497 | L5: 81892 | M5: 94124 | O5: 4.3316872e-07
C6: 20 | D6: 0 | E6: 266189 | F6: 0 | G6: 248263 | H6: 0 | I6: 246159 | J6: 0 | K6: 187778 | L6: 0 | M6: 144666 | O6: 2.2380381e-06
C7: 30 | D7: 0 | E7: 351049 | F7: 0 | G7: 330097 | H7: 0 | I7: 298086 | J7: 0 | K7: 276411 | L7: 0 | M7: 320885 | O7: 1.1262377e-05
O8: 0.0014098844
O9: 0.0070464489
D10: HP Evaporator Secondary Side Flow Rate (kg/s) | O10: 0.035155749
C11: Qc Qh | D11: =D4 -> 10 | E11: =F4 -> 20 | F11: =H4 -> 30 | G11: =J4 -> 40 | H11: =L4 -> 50 | O11: 0.099222278
B12: Condenser Secondary Side Flow Rate (kg/s) | C12: =C5 -> 10 | D12: =SUM(D5:E5) -> 151941 | E12: =SUM(F5:G5) -> 135051 | F12: =SUM(H5:I5) -> 138157 | G12: =SUM(J5:K5) -> 118615 | H12: =SUM(L5:M5) -> 176016 | O12: 0.19683708
C13: =C6 -> 20 | D13: =SUM(D6:E6) -> 266189 | E13: =SUM(F6:G6) -> 248263 | F13: =SUM(H6:I6) -> 246159 | G13: =SUM(J6:K6) -> 187778 | H13: =SUM(L6:M6) -> 144666 | O13: 0.2927668
C14: =C7 -> 30 | D14: =SUM(D7:E7) -> 351049 | E14: =SUM(F7:G7) -> 330097 | F14: =SUM(H7:I7) -> 298086 | G14: =SUM(J7:K7) -> 276411 | H14: =SUM(L7:M7) -> 320885 | O14: 0.38693438
O15: 0.65810232
O16: 0.74446222
O17: 0.82868326
O18: 0.9106918
O19: 0.99041476
O20: 1.0677796
O21: 1.1427145
O22: 1.215148
O23: 1.2850093
O24: 1.3522282
O25: 1.416735
O26: 1.4784606
... O6743: 138156.7
